[2000-12-31T23:00:00.005] error: Unable to open pidfile `/var/run/slurmctld.pid': Read-only file system
[2000-12-31T23:00:00.005] Not running as root. Can't drop supplementary groups
[2000-12-31T23:00:00.005] error: Configured MailProg is invalid
[2000-12-31T23:00:00.006] slurmctld version 17.02.2 started on cluster beocat
[2000-12-31T23:00:00.448] layouts: no layout to initialize
[2000-12-31T23:00:00.460] layouts: loading entities/relations information
[2000-12-31T23:00:00.460] error: Could not open node state file /home/slurm/slurm_sim_ws/sim/micro/baseline/var/state/node_state: No such file or directory
[2000-12-31T23:00:00.460] error: NOTE: Trying backup state save file. Information may be lost!
[2000-12-31T23:00:00.460] No node state file (/home/slurm/slurm_sim_ws/sim/micro/baseline/var/state/node_state.old) to recover
[2000-12-31T23:00:00.460] error: Incomplete node data checkpoint file
[2000-12-31T23:00:00.460] Recovered state of 0 nodes
[2000-12-31T23:00:00.460] error: Could not open front_end state file /home/slurm/slurm_sim_ws/sim/micro/baseline/var/state/front_end_state: No such file or directory
[2000-12-31T23:00:00.460] error: NOTE: Trying backup front_end_state save file. Information may be lost!
[2000-12-31T23:00:00.460] No node state file (/home/slurm/slurm_sim_ws/sim/micro/baseline/var/state/front_end_state.old) to recover
[2000-12-31T23:00:00.460] error: Incomplete front_end node data checkpoint file
[2000-12-31T23:00:00.460] Recovered state of 0 front_end nodes
[2000-12-31T23:00:00.460] error: Could not open job state file /home/slurm/slurm_sim_ws/sim/micro/baseline/var/state/job_state: No such file or directory
[2000-12-31T23:00:00.460] error: NOTE: Trying backup state save file. Jobs may be lost!
[2000-12-31T23:00:00.460] No job state file (/home/slurm/slurm_sim_ws/sim/micro/baseline/var/state/job_state.old) to recover
[2000-12-31T23:00:00.460] cons_res: select_p_node_init
[2000-12-31T23:00:00.460] cons_res: preparing for 2 partitions
[2000-12-31T23:00:00.460] error: Could not open reservation state file /home/slurm/slurm_sim_ws/sim/micro/baseline/var/state/resv_state: No such file or directory
[2000-12-31T23:00:00.460] error: NOTE: Trying backup state save file. Reservations may be lost
[2000-12-31T23:00:00.460] No reservation state file (/home/slurm/slurm_sim_ws/sim/micro/baseline/var/state/resv_state.old) to recover
[2000-12-31T23:00:00.460] Recovered state of 0 reservations
[2000-12-31T23:00:00.460] error: Could not open trigger state file /home/slurm/slurm_sim_ws/sim/micro/baseline/var/state/trigger_state: No such file or directory
[2000-12-31T23:00:00.460] error: NOTE: Trying backup state save file. Triggers may be lost!
[2000-12-31T23:00:00.460] No trigger state file (/home/slurm/slurm_sim_ws/sim/micro/baseline/var/state/trigger_state.old) to recover
[2000-12-31T23:00:00.460] error: Incomplete trigger data checkpoint file
[2000-12-31T23:00:00.460] _preserve_plugins: backup_controller not specified
[2000-12-31T23:00:00.460] Reinitializing job accounting state
[2000-12-31T23:00:00.460] Ending any jobs in accounting that were running when controller went down on
[2000-12-31T23:00:00.460] cons_res: select_p_reconfigure
[2000-12-31T23:00:00.460] cons_res: select_p_node_init
[2000-12-31T23:00:00.460] cons_res: preparing for 2 partitions
[2000-12-31T23:00:00.460] Running as primary controller
[2000-12-31T23:00:00.460] Registering slurmctld at port 29002 with slurmdbd.
[2000-12-31T23:00:00.728] No parameter for mcs plugin, default values set
[2000-12-31T23:00:00.728] mcs: MCSParameters = (null). ondemand set.
[2000-12-31T23:00:00.728] JobsTraceFile=/home/slurm/slurm_sim_ws/sim/test.trace
[2000-12-31T23:00:00.728] sdiagFileOut=/home/slurm/slurm_sim_ws/sim/micro/baseline/log/sdiag.out
[2000-12-31T23:00:00.728] SimStats=/home/slurm/slurm_sim_ws/sim/micro/baseline/log/simstat.out
[2000-12-31T23:00:00.728] TimeStart=978325200
[2000-12-31T23:00:00.728] StartSecondsBeforeFirstJob=45
[2000-12-31T23:00:00.728] TimeStop=1
[2000-12-31T23:00:00.728] TimeStep=1000000 usec
[2000-12-31T23:00:00.728] AfterJobLaunchTimeIncreament=0
[2000-12-31T23:00:00.728] BFBetweenJobsChecksTimeIncreament=0
[2000-12-31T23:00:00.728] sdiagPeriod=60
[2000-12-31T23:00:00.728] sdiagFileOut=/home/slurm/slurm_sim_ws/sim/micro/baseline/log/sdiag.out
[2000-12-31T23:00:00.728] sprioPeriod=300
[2000-12-31T23:00:00.728] sprioFileOut=/home/slurm/slurm_sim_ws/sim/micro/baseline/log/sprio.out
[2000-12-31T23:00:00.728] sinfoPeriod=60
[2000-12-31T23:00:00.728] sinfoFileOut=/home/slurm/slurm_sim_ws/sim/micro/baseline/log/sinfo.out
[2000-12-31T23:00:00.728] squeuePeriod=300
[2000-12-31T23:00:00.728] squeueFileOut=/home/slurm/slurm_sim_ws/sim/micro/baseline/log/squeue.out
[2000-12-31T23:00:00.728] SharedMemoryName=/slurm_sim.shm
[2000-12-31T23:00:00.728] RunID=(null)
[2000-12-31T23:00:00.728] bf_model_real_prefactor=1.000000
[2000-12-31T23:00:00.728] bf_model_real_power=1.000000
[2000-12-31T23:00:00.728] bf_model_sim_prefactor=1.000000
[2000-12-31T23:00:00.728] bf_model_sim_power=1.000000
[2000-12-31T23:00:00.000] SIM: Trace initialization done. Total trace records: 501
[2017-01-01T00:00:41.000] CPUs=4 Boards=1 Sockets=1 Cores=2 Threads=2 Memory=8192 TmpDisk=8192 Uptime=300 CPUSpecList=(null)
[2017-01-01T00:00:41.000] No last decay (/home/slurm/slurm_sim_ws/sim/micro/baseline/var/state/priority_last_decay_ran) to recover
[2017-01-01T00:00:41.001] SchedulerParameters=default_queue_depth=100,max_rpc_cnt=0,max_sched_time=2,partition_job_depth=0,sched_max_job_start=0,sched_min_interval=0
[2017-01-01T00:01:26.001] Successfully submit job to queue (job_id: 1001)
[2017-01-01T00:01:26.001] sched: Allocate JobID=1001 NodeList=n1 #CPUs=12 Partition=normal
[2017-01-01T00:01:26.002] SIM: faking sending message type REQUEST_BATCH_JOB_LAUNCH to localhost

[2017-01-01T00:01:41.002] job_complete: JobID=1001 State=0x1 NodeCnt=1 WEXITSTATUS 0
[2017-01-01T00:01:41.002] job_complete: JobID=1001 State=0x8003 NodeCnt=1 done
[2017-01-01T00:02:15.002] Successfully submit job to queue (job_id: 1002)
[2017-01-01T00:02:15.002] sched: Allocate JobID=1002 NodeList=n1 #CPUs=1 Partition=normal
[2017-01-01T00:02:15.002] SIM: faking sending message type REQUEST_BATCH_JOB_LAUNCH to localhost

[2017-01-01T00:02:26.003] Successfully submit job to queue (job_id: 1003)
[2017-01-01T00:02:26.003] sched: Allocate JobID=1003 NodeList=b1 #CPUs=1 Partition=normal
[2017-01-01T00:02:26.003] SIM: faking sending message type REQUEST_BATCH_JOB_LAUNCH to localhost

[2017-01-01T00:05:01.003] job_complete: JobID=1003 State=0x1 NodeCnt=1 WEXITSTATUS 0
[2017-01-01T00:05:01.003] job_complete: JobID=1003 State=0x8003 NodeCnt=1 done
[2017-01-01T00:09:31.014] Successfully submit job to queue (job_id: 1004)
[2017-01-01T00:09:31.014] sched: Allocate JobID=1004 NodeList=n2 #CPUs=12 Partition=normal
[2017-01-01T00:09:31.014] SIM: faking sending message type REQUEST_BATCH_JOB_LAUNCH to localhost

[2017-01-01T00:11:05.024] Successfully submit job to queue (job_id: 1005)
[2017-01-01T00:11:05.024] sched: Allocate JobID=1005 NodeList=b1 #CPUs=12 Partition=normal
[2017-01-01T00:11:05.024] SIM: faking sending message type REQUEST_BATCH_JOB_LAUNCH to localhost

[2017-01-01T00:11:11.024] Successfully submit job to queue (job_id: 1006)
[2017-01-01T00:11:11.024] sched: Allocate JobID=1006 NodeList=n3 #CPUs=12 Partition=normal
[2017-01-01T00:11:11.024] SIM: faking sending message type REQUEST_BATCH_JOB_LAUNCH to localhost

[2017-01-01T00:11:20.024] Successfully submit job to queue (job_id: 1007)
[2017-01-01T00:11:20.025] sched: Allocate JobID=1007 NodeList=m[1-2] #CPUs=24 Partition=normal
[2017-01-01T00:11:20.025] SIM: faking sending message type REQUEST_BATCH_JOB_LAUNCH to localhost

[2017-01-01T00:12:14.025] job_complete: JobID=1005 State=0x1 NodeCnt=1 WEXITSTATUS 0
[2017-01-01T00:12:14.025] job_complete: JobID=1005 State=0x8003 NodeCnt=1 done
[2017-01-01T00:12:50.025] Successfully submit job to queue (job_id: 1008)
[2017-01-01T00:12:50.025] sched: Allocate JobID=1008 NodeList=m3 #CPUs=12 Partition=normal
[2017-01-01T00:12:50.025] SIM: faking sending message type REQUEST_BATCH_JOB_LAUNCH to localhost

[2017-01-01T00:12:51.025] job_complete: JobID=1008 State=0x1 NodeCnt=1 WEXITSTATUS 0
[2017-01-01T00:12:51.025] job_complete: JobID=1008 State=0x8003 NodeCnt=1 done
[2017-01-01T00:14:29.026] Successfully submit job to queue (job_id: 1009)
[2017-01-01T00:14:29.026] sched: Allocate JobID=1009 NodeList=b[1-8] #CPUs=96 Partition=normal
[2017-01-01T00:14:29.026] SIM: faking sending message type REQUEST_BATCH_JOB_LAUNCH to localhost

[2017-01-01T00:14:34.026] Successfully submit job to queue (job_id: 1010)
[2017-01-01T00:14:34.026] sched: Allocate JobID=1010 NodeList=n4 #CPUs=12 Partition=normal
[2017-01-01T00:14:34.026] SIM: faking sending message type REQUEST_BATCH_JOB_LAUNCH to localhost

[2017-01-01T00:14:35.026] job_complete: JobID=1010 State=0x1 NodeCnt=1 WEXITSTATUS 0
[2017-01-01T00:14:35.026] job_complete: JobID=1010 State=0x8003 NodeCnt=1 done
[2017-01-01T00:15:35.027] job_complete: JobID=1009 State=0x1 NodeCnt=8 WEXITSTATUS 0
[2017-01-01T00:15:35.027] job_complete: JobID=1009 State=0x8003 NodeCnt=8 done
[2017-01-01T00:15:42.027] job_complete: JobID=1006 State=0x1 NodeCnt=1 WEXITSTATUS 0
[2017-01-01T00:15:42.027] job_complete: JobID=1006 State=0x8003 NodeCnt=1 done
[2017-01-01T00:15:57.036] Successfully submit job to queue (job_id: 1011)
[2017-01-01T00:15:57.036] sched: Allocate JobID=1011 NodeList=g1 #CPUs=1 Partition=normal
[2017-01-01T00:15:57.036] SIM: faking sending message type REQUEST_BATCH_JOB_LAUNCH to localhost

[2017-01-01T00:15:58.036] job_complete: JobID=1011 State=0x1 NodeCnt=1 WEXITSTATUS 0
[2017-01-01T00:15:58.036] job_complete: JobID=1011 State=0x8003 NodeCnt=1 done
[2017-01-01T00:17:33.036] Successfully submit job to queue (job_id: 1012)
[2017-01-01T00:17:33.037] sched: Allocate JobID=1012 NodeList=m3 #CPUs=1 Partition=normal
[2017-01-01T00:17:33.037] SIM: faking sending message type REQUEST_BATCH_JOB_LAUNCH to localhost

[2017-01-01T00:19:46.037] Successfully submit job to queue (job_id: 1013)
[2017-01-01T00:19:46.037] sched: Allocate JobID=1013 NodeList=b1 #CPUs=1 Partition=normal
[2017-01-01T00:19:46.037] SIM: faking sending message type REQUEST_BATCH_JOB_LAUNCH to localhost

[2017-01-01T00:19:47.037] job_complete: JobID=1013 State=0x1 NodeCnt=1 WEXITSTATUS 0
[2017-01-01T00:19:47.038] job_complete: JobID=1013 State=0x8003 NodeCnt=1 done
[2017-01-01T00:19:52.038] Successfully submit job to queue (job_id: 1014)
[2017-01-01T00:19:52.038] sched: Allocate JobID=1014 NodeList=n3 #CPUs=12 Partition=normal
[2017-01-01T00:19:52.038] SIM: faking sending message type REQUEST_BATCH_JOB_LAUNCH to localhost

[2017-01-01T00:19:53.038] job_complete: JobID=1014 State=0x1 NodeCnt=1 WEXITSTATUS 0
[2017-01-01T00:19:53.038] job_complete: JobID=1014 State=0x8003 NodeCnt=1 done
[2017-01-01T00:20:10.038] job_complete: JobID=1004 State=0x1 NodeCnt=1 WEXITSTATUS 0
[2017-01-01T00:20:10.038] job_complete: JobID=1004 State=0x8003 NodeCnt=1 done
[2017-01-01T00:21:20.047] Successfully submit job to queue (job_id: 1015)
[2017-01-01T00:21:20.047] sched: Allocate JobID=1015 NodeList=m3 #CPUs=6 Partition=normal
[2017-01-01T00:21:20.047] SIM: faking sending message type REQUEST_BATCH_JOB_LAUNCH to localhost

[2017-01-01T00:21:33.047] Successfully submit job to queue (job_id: 1016)
[2017-01-01T00:21:33.047] sched: Allocate JobID=1016 NodeList=g1 #CPUs=2 Partition=normal
[2017-01-01T00:21:33.047] SIM: faking sending message type REQUEST_BATCH_JOB_LAUNCH to localhost

[2017-01-01T00:22:16.048] job_complete: JobID=1002 State=0x1 NodeCnt=1 WEXITSTATUS 0
[2017-01-01T00:22:16.048] job_complete: JobID=1002 State=0x8003 NodeCnt=1 done
[2017-01-01T00:22:38.048] Successfully submit job to queue (job_id: 1017)
[2017-01-01T00:22:38.048] sched: Allocate JobID=1017 NodeList=n1 #CPUs=12 Partition=normal
[2017-01-01T00:22:38.048] SIM: faking sending message type REQUEST_BATCH_JOB_LAUNCH to localhost

[2017-01-01T00:22:44.048] Successfully submit job to queue (job_id: 1018)
[2017-01-01T00:22:44.048] sched: Allocate JobID=1018 NodeList=m4 #CPUs=12 Partition=normal
[2017-01-01T00:22:44.048] SIM: faking sending message type REQUEST_BATCH_JOB_LAUNCH to localhost

[2017-01-01T00:23:06.048] job_complete: JobID=1018 State=0x1 NodeCnt=1 WEXITSTATUS 0
[2017-01-01T00:23:06.048] job_complete: JobID=1018 State=0x8003 NodeCnt=1 done
[2017-01-01T00:23:12.049] Successfully submit job to queue (job_id: 1019)
[2017-01-01T00:23:12.049] job_complete: JobID=1017 State=0x1 NodeCnt=1 WEXITSTATUS 0
[2017-01-01T00:23:12.049] job_complete: JobID=1017 State=0x8003 NodeCnt=1 done
[2017-01-01T00:23:21.049] Successfully submit job to queue (job_id: 1020)
[2017-01-01T00:25:17.049] Successfully submit job to queue (job_id: 1021)
[2017-01-01T00:28:03.059] Successfully submit job to queue (job_id: 1022)
[2017-01-01T00:28:03.059] sched: Allocate JobID=1022 NodeList=m3 #CPUs=1 Partition=normal
[2017-01-01T00:28:03.059] SIM: faking sending message type REQUEST_BATCH_JOB_LAUNCH to localhost

[2017-01-01T00:29:30.060] Successfully submit job to queue (job_id: 1023)
[2017-01-01T00:29:30.060] sched: Allocate JobID=1023 NodeList=n[1-2] #CPUs=24 Partition=normal
[2017-01-01T00:29:30.060] SIM: faking sending message type REQUEST_BATCH_JOB_LAUNCH to localhost

[2017-01-01T00:29:52.060] Successfully submit job to queue (job_id: 1024)
[2017-01-01T00:30:28.060] job_complete: JobID=1015 State=0x1 NodeCnt=1 WEXITSTATUS 0
[2017-01-01T00:30:28.060] job_complete: JobID=1015 State=0x8003 NodeCnt=1 done
[2017-01-01T00:32:19.070] Successfully submit job to queue (job_id: 1025)
[2017-01-01T00:32:35.070] Successfully submit job to queue (job_id: 1026)
[2017-01-01T00:33:28.070] Successfully submit job to queue (job_id: 1027)
[2017-01-01T00:33:28.070] sched: Allocate JobID=1027 NodeList=b[1-3] #CPUs=36 Partition=normal
[2017-01-01T00:33:28.071] SIM: faking sending message type REQUEST_BATCH_JOB_LAUNCH to localhost

[2017-01-01T00:33:30.071] job_complete: JobID=1023 State=0x1 NodeCnt=2 WEXITSTATUS 0
[2017-01-01T00:33:30.071] job_complete: JobID=1023 State=0x8003 NodeCnt=2 done
[2017-01-01T00:33:34.071] job_complete: JobID=1027 State=0x1 NodeCnt=3 WEXITSTATUS 0
[2017-01-01T00:33:34.071] job_complete: JobID=1027 State=0x8003 NodeCnt=3 done
[2017-01-01T00:34:26.071] job_complete: JobID=1016 State=0x1 NodeCnt=1 WEXITSTATUS 0
[2017-01-01T00:34:26.071] job_complete: JobID=1016 State=0x8003 NodeCnt=1 done
[2017-01-01T00:34:26.071] sched: Allocate JobID=1019 NodeList=g1 #CPUs=12 Partition=normal
[2017-01-01T00:34:26.071] SIM: faking sending message type REQUEST_BATCH_JOB_LAUNCH to localhost

[2017-01-01T00:34:26.072] sched: Allocate JobID=1025 NodeList=m3 #CPUs=6 Partition=normal
[2017-01-01T00:34:26.072] SIM: faking sending message type REQUEST_BATCH_JOB_LAUNCH to localhost

[2017-01-01T00:34:26.072] sched: Allocate JobID=1024 NodeList=b1 #CPUs=12 Partition=normal
[2017-01-01T00:34:26.072] SIM: faking sending message type REQUEST_BATCH_JOB_LAUNCH to localhost

[2017-01-01T00:34:26.072] sched: Allocate JobID=1020 NodeList=n1 #CPUs=1 Partition=normal
[2017-01-01T00:34:26.072] SIM: faking sending message type REQUEST_BATCH_JOB_LAUNCH to localhost

[2017-01-01T00:34:26.072] sched: Allocate JobID=1021 NodeList=m3 #CPUs=1 Partition=normal
[2017-01-01T00:34:26.072] SIM: faking sending message type REQUEST_BATCH_JOB_LAUNCH to localhost

[2017-01-01T00:34:26.072] sched: Allocate JobID=1026 NodeList=m3 #CPUs=1 Partition=normal
[2017-01-01T00:34:26.072] SIM: faking sending message type REQUEST_BATCH_JOB_LAUNCH to localhost

[2017-01-01T00:34:46.072] Successfully submit job to queue (job_id: 1028)
[2017-01-01T00:34:46.073] sched: Allocate JobID=1028 NodeList=b2 #CPUs=12 Partition=normal
[2017-01-01T00:34:46.073] SIM: faking sending message type REQUEST_BATCH_JOB_LAUNCH to localhost

[2017-01-01T00:34:47.073] job_complete: JobID=1028 State=0x1 NodeCnt=1 WEXITSTATUS 0
[2017-01-01T00:34:47.073] job_complete: JobID=1028 State=0x8003 NodeCnt=1 done
[2017-01-01T00:35:13.073] Successfully submit job to queue (job_id: 1029)
[2017-01-01T00:35:13.073] sched: Allocate JobID=1029 NodeList=m4 #CPUs=6 Partition=normal
[2017-01-01T00:35:13.073] SIM: faking sending message type REQUEST_BATCH_JOB_LAUNCH to localhost

[2017-01-01T00:35:56.082] Successfully submit job to queue (job_id: 1030)
[2017-01-01T00:35:56.082] sched: Allocate JobID=1030 NodeList=n2 #CPUs=12 Partition=normal
[2017-01-01T00:35:56.082] SIM: faking sending message type REQUEST_BATCH_JOB_LAUNCH to localhost

[2017-01-01T00:36:17.082] Successfully submit job to queue (job_id: 1031)
[2017-01-01T00:36:17.082] sched: Allocate JobID=1031 NodeList=m4 #CPUs=6 Partition=normal
[2017-01-01T00:36:17.082] SIM: faking sending message type REQUEST_BATCH_JOB_LAUNCH to localhost

[2017-01-01T00:36:20.082] job_complete: JobID=1007 State=0x1 NodeCnt=2 WEXITSTATUS 0
[2017-01-01T00:36:20.082] job_complete: JobID=1007 State=0x8003 NodeCnt=2 done
[2017-01-01T00:37:10.083] Successfully submit job to queue (job_id: 1032)
[2017-01-01T00:37:10.083] sched: Allocate JobID=1032 NodeList=m1 #CPUs=6 Partition=normal
[2017-01-01T00:37:10.083] SIM: faking sending message type REQUEST_BATCH_JOB_LAUNCH to localhost

[2017-01-01T00:37:42.083] Successfully submit job to queue (job_id: 1033)
[2017-01-01T00:37:44.083] sched: Allocate JobID=1033 NodeList=n1 #CPUs=1 Partition=normal
[2017-01-01T00:37:44.083] SIM: faking sending message type REQUEST_BATCH_JOB_LAUNCH to localhost

[2017-01-01T00:37:50.083] job_complete: JobID=1026 State=0x1 NodeCnt=1 WEXITSTATUS 0
[2017-01-01T00:37:50.083] job_complete: JobID=1026 State=0x8003 NodeCnt=1 done
[2017-01-01T00:38:59.084] job_complete: JobID=1012 State=0x1 NodeCnt=1 WEXITSTATUS 0
[2017-01-01T00:38:59.084] job_complete: JobID=1012 State=0x8003 NodeCnt=1 done
[2017-01-01T00:39:03.084] job_complete: JobID=1021 State=0x1 NodeCnt=1 WEXITSTATUS 0
[2017-01-01T00:39:03.084] job_complete: JobID=1021 State=0x8003 NodeCnt=1 done
[2017-01-01T00:40:43.084] Successfully submit job to queue (job_id: 1034)
[2017-01-01T00:40:44.085] sched: Allocate JobID=1034 NodeList=b[2-5] #CPUs=48 Partition=normal
[2017-01-01T00:40:44.085] SIM: faking sending message type REQUEST_BATCH_JOB_LAUNCH to localhost

[2017-01-01T00:40:45.085] job_complete: JobID=1034 State=0x1 NodeCnt=4 WEXITSTATUS 0
[2017-01-01T00:40:45.085] job_complete: JobID=1034 State=0x8003 NodeCnt=4 done
[2017-01-01T00:41:22.093] job_complete: JobID=1033 State=0x1 NodeCnt=1 WEXITSTATUS 0
[2017-01-01T00:41:22.093] job_complete: JobID=1033 State=0x8003 NodeCnt=1 done
[2017-01-01T00:41:28.093] job_complete: JobID=1020 State=0x1 NodeCnt=1 WEXITSTATUS 0
[2017-01-01T00:41:28.093] job_complete: JobID=1020 State=0x8003 NodeCnt=1 done
[2017-01-01T00:43:26.094] Successfully submit job to queue (job_id: 1035)
[2017-01-01T00:43:26.094] sched: Allocate JobID=1035 NodeList=n[1,3] #CPUs=24 Partition=normal
[2017-01-01T00:43:26.094] SIM: faking sending message type REQUEST_BATCH_JOB_LAUNCH to localhost

[2017-01-01T00:43:44.094] job_complete: JobID=1022 State=0x1 NodeCnt=1 WEXITSTATUS 0
[2017-01-01T00:43:44.094] job_complete: JobID=1022 State=0x8003 NodeCnt=1 done
[2017-01-01T00:43:46.094] Successfully submit job to queue (job_id: 1036)
[2017-01-01T00:43:47.094] sched: Allocate JobID=1036 NodeList=m2 #CPUs=12 Partition=normal
[2017-01-01T00:43:47.094] SIM: faking sending message type REQUEST_BATCH_JOB_LAUNCH to localhost

[2017-01-01T00:43:57.094] Successfully submit job to queue (job_id: 1037)
[2017-01-01T00:44:21.094] Successfully submit job to queue (job_id: 1038)
[2017-01-01T00:44:22.095] Successfully submit job to queue (job_id: 1039)
[2017-01-01T00:44:24.095] sched: Allocate JobID=1039 NodeList=b[2-9] #CPUs=96 Partition=normal
[2017-01-01T00:44:24.095] SIM: faking sending message type REQUEST_BATCH_JOB_LAUNCH to localhost

[2017-01-01T00:44:47.095] job_complete: JobID=1024 State=0x1 NodeCnt=1 WEXITSTATUS 0
[2017-01-01T00:44:47.095] job_complete: JobID=1024 State=0x8003 NodeCnt=1 done
[2017-01-01T00:45:26.095] job_complete: JobID=1035 State=0x1 NodeCnt=2 WEXITSTATUS 0
[2017-01-01T00:45:26.095] job_complete: JobID=1035 State=0x8003 NodeCnt=2 done
[2017-01-01T00:45:48.096] job_complete: JobID=1031 State=0x1 NodeCnt=1 WEXITSTATUS 0
[2017-01-01T00:45:48.096] job_complete: JobID=1031 State=0x8003 NodeCnt=1 done
[2017-01-01T00:48:15.104] Successfully submit job to queue (job_id: 1040)
[2017-01-01T00:48:28.104] job_complete: JobID=1025 State=0x1 NodeCnt=1 WEXITSTATUS 0
[2017-01-01T00:48:28.104] job_complete: JobID=1025 State=0x8003 NodeCnt=1 done
[2017-01-01T00:48:47.105] Successfully submit job to queue (job_id: 1041)
[2017-01-01T00:49:07.105] Successfully submit job to queue (job_id: 1042)
[2017-01-01T00:49:09.105] Successfully submit job to queue (job_id: 1043)
[2017-01-01T00:51:49.115] job_complete: JobID=1019 State=0x1 NodeCnt=1 WEXITSTATUS 0
[2017-01-01T00:51:49.115] job_complete: JobID=1019 State=0x8003 NodeCnt=1 done
[2017-01-01T00:52:16.115] Successfully submit job to queue (job_id: 1044)
[2017-01-01T00:52:49.115] job_complete: JobID=1036 State=0x1 NodeCnt=1 WEXITSTATUS 0
[2017-01-01T00:52:49.115] job_complete: JobID=1036 State=0x8003 NodeCnt=1 done
[2017-01-01T00:53:11.116] Successfully submit job to queue (job_id: 1045)
[2017-01-01T00:53:17.116] Successfully submit job to queue (job_id: 1046)
[2017-01-01T00:53:31.116] job_complete: JobID=1030 State=0x1 NodeCnt=1 WEXITSTATUS 0
[2017-01-01T00:53:31.116] job_complete: JobID=1030 State=0x8003 NodeCnt=1 done
[2017-01-01T00:53:44.116] Successfully submit job to queue (job_id: 1047)
[2017-01-01T00:53:52.116] Successfully submit job to queue (job_id: 1048)
[2017-01-01T00:53:52.116] sched: Allocate JobID=1048 NodeList=b[1,10],g1,m2,n[1-4] #CPUs=96 Partition=normal
[2017-01-01T00:53:52.116] SIM: faking sending message type REQUEST_BATCH_JOB_LAUNCH to localhost

[2017-01-01T00:54:01.116] Successfully submit job to queue (job_id: 1049)
[2017-01-01T00:54:22.117] job_complete: JobID=1039 State=0x1 NodeCnt=8 WEXITSTATUS 0
[2017-01-01T00:54:22.117] job_complete: JobID=1039 State=0x8003 NodeCnt=8 done
[2017-01-01T00:55:12.117] Successfully submit job to queue (job_id: 1050)
[2017-01-01T00:55:18.117] Successfully submit job to queue (job_id: 1051)
[2017-01-01T00:55:33.117] job_complete: JobID=1029 State=0x1 NodeCnt=1 WEXITSTATUS 0
[2017-01-01T00:55:33.117] job_complete: JobID=1029 State=0x8003 NodeCnt=1 done
[2017-01-01T00:57:29.125] job_complete: JobID=1048 State=0x1 NodeCnt=8 WEXITSTATUS 0
[2017-01-01T00:57:29.125] job_complete: JobID=1048 State=0x8003 NodeCnt=8 done
[2017-01-01T00:57:29.125] sched: Allocate JobID=1044 NodeList=n1 #CPUs=12 Partition=normal
[2017-01-01T00:57:29.125] SIM: faking sending message type REQUEST_BATCH_JOB_LAUNCH to localhost

[2017-01-01T00:57:29.125] sched: Allocate JobID=1047 NodeList=b1 #CPUs=12 Partition=normal
[2017-01-01T00:57:29.125] SIM: faking sending message type REQUEST_BATCH_JOB_LAUNCH to localhost

[2017-01-01T00:57:29.125] sched: Allocate JobID=1040 NodeList=n[2-3] #CPUs=24 Partition=normal
[2017-01-01T00:57:29.125] SIM: faking sending message type REQUEST_BATCH_JOB_LAUNCH to localhost

[2017-01-01T00:57:29.125] sched: Allocate JobID=1049 NodeList=g1 #CPUs=12 Partition=normal
[2017-01-01T00:57:29.126] SIM: faking sending message type REQUEST_BATCH_JOB_LAUNCH to localhost

[2017-01-01T00:57:29.126] sched: Allocate JobID=1037 NodeList=m[2-4] #CPUs=36 Partition=normal
[2017-01-01T00:57:29.126] SIM: faking sending message type REQUEST_BATCH_JOB_LAUNCH to localhost

[2017-01-01T00:57:30.126] job_complete: JobID=1049 State=0x1 NodeCnt=1 WEXITSTATUS 0
[2017-01-01T00:57:30.126] job_complete: JobID=1049 State=0x8003 NodeCnt=1 done
[2017-01-01T00:57:32.126] sched: Allocate JobID=1038 NodeList=g1 #CPUs=12 Partition=normal
[2017-01-01T00:57:32.126] SIM: faking sending message type REQUEST_BATCH_JOB_LAUNCH to localhost

[2017-01-01T00:57:32.126] sched: Allocate JobID=1043 NodeList=n4 #CPUs=1 Partition=normal
[2017-01-01T00:57:32.126] SIM: faking sending message type REQUEST_BATCH_JOB_LAUNCH to localhost

[2017-01-01T00:57:41.127] Successfully submit job to queue (job_id: 1052)
[2017-01-01T00:57:41.127] sched: Allocate JobID=1052 NodeList=b2 #CPUs=12 Partition=normal
[2017-01-01T00:57:41.127] SIM: faking sending message type REQUEST_BATCH_JOB_LAUNCH to localhost

[2017-01-01T00:58:00.127] Successfully submit job to queue (job_id: 1053)
[2017-01-01T00:58:00.127] sched: Allocate JobID=1053 NodeList=b3 #CPUs=12 Partition=normal
[2017-01-01T00:58:00.127] SIM: faking sending message type REQUEST_BATCH_JOB_LAUNCH to localhost

[2017-01-01T00:58:32.127] job_complete: JobID=1043 State=0x1 NodeCnt=1 WEXITSTATUS 0
[2017-01-01T00:58:32.127] job_complete: JobID=1043 State=0x8003 NodeCnt=1 done
[2017-01-01T00:58:55.128] Successfully submit job to queue (job_id: 1054)
[2017-01-01T00:58:55.128] sched: Allocate JobID=1054 NodeList=b[4-6] #CPUs=36 Partition=normal
[2017-01-01T00:58:55.128] SIM: faking sending message type REQUEST_BATCH_JOB_LAUNCH to localhost

[2017-01-01T00:58:56.128] job_complete: JobID=1054 State=0x1 NodeCnt=3 WEXITSTATUS 0
[2017-01-01T00:58:56.128] job_complete: JobID=1054 State=0x8003 NodeCnt=3 done
[2017-01-01T00:59:14.128] Successfully submit job to queue (job_id: 1055)
[2017-01-01T01:00:04.129] Successfully submit job to queue (job_id: 1056)
[2017-01-01T01:00:37.129] Successfully submit job to queue (job_id: 1057)
[2017-01-01T01:00:37.129] sched: Allocate JobID=1057 NodeList=n4 #CPUs=6 Partition=normal
[2017-01-01T01:00:37.129] SIM: faking sending message type REQUEST_BATCH_JOB_LAUNCH to localhost

[2017-01-01T01:00:41.129] backfill: Started JobId=1046 in normal on n4
[2017-01-01T01:00:41.129] SIM: faking sending message type REQUEST_BATCH_JOB_LAUNCH to localhost

[2017-01-01T01:00:41.130] backfill: Started JobId=1050 in normal on b4
[2017-01-01T01:00:41.130] SIM: faking sending message type REQUEST_BATCH_JOB_LAUNCH to localhost

[2017-01-01T01:00:41.130] backfill: Started JobId=1042 in normal on b5
[2017-01-01T01:00:41.130] SIM: faking sending message type REQUEST_BATCH_JOB_LAUNCH to localhost

[2017-01-01T01:00:41.130] backfill: Started JobId=1055 in normal on b6
[2017-01-01T01:00:41.130] SIM: faking sending message type REQUEST_BATCH_JOB_LAUNCH to localhost

[2017-01-01T01:00:41.130] backfill: Started JobId=1051 in normal on m1
[2017-01-01T01:00:41.130] SIM: faking sending message type REQUEST_BATCH_JOB_LAUNCH to localhost

[2017-01-01T01:00:59.134] Successfully submit job to queue (job_id: 1058)
[2017-01-01T01:01:10.134] job_complete: JobID=1032 State=0x1 NodeCnt=1 WEXITSTATUS 0
[2017-01-01T01:01:10.134] job_complete: JobID=1032 State=0x8003 NodeCnt=1 done
[2017-01-01T01:01:17.134] job_complete: JobID=1044 State=0x1 NodeCnt=1 WEXITSTATUS 0
[2017-01-01T01:01:17.135] job_complete: JobID=1044 State=0x8003 NodeCnt=1 done
[2017-01-01T01:01:18.135] Successfully submit job to queue (job_id: 1059)
[2017-01-01T01:01:22.135] job_complete: JobID=1038 State=0x1 NodeCnt=1 WEXITSTATUS 0
[2017-01-01T01:01:22.135] job_complete: JobID=1038 State=0x8003 NodeCnt=1 done
[2017-01-01T01:01:23.135] sched: Allocate JobID=1045 NodeList=g1 #CPUs=2 Partition=normal
[2017-01-01T01:01:23.135] SIM: faking sending message type REQUEST_BATCH_JOB_LAUNCH to localhost

[2017-01-01T01:01:23.135] sched: Allocate JobID=1056 NodeList=n1 #CPUs=1 Partition=normal
[2017-01-01T01:01:23.135] SIM: faking sending message type REQUEST_BATCH_JOB_LAUNCH to localhost

[2017-01-01T01:01:23.135] sched: Allocate JobID=1058 NodeList=b7 #CPUs=6 Partition=normal
[2017-01-01T01:01:23.135] SIM: faking sending message type REQUEST_BATCH_JOB_LAUNCH to localhost

[2017-01-01T01:01:23.135] sched: Allocate JobID=1059 NodeList=m1 #CPUs=6 Partition=normal
[2017-01-01T01:01:23.135] SIM: faking sending message type REQUEST_BATCH_JOB_LAUNCH to localhost

[2017-01-01T01:01:40.136] Successfully submit job to queue (job_id: 1060)
[2017-01-01T01:02:10.136] job_complete: JobID=1056 State=0x1 NodeCnt=1 WEXITSTATUS 0
[2017-01-01T01:02:10.136] job_complete: JobID=1056 State=0x8003 NodeCnt=1 done
[2017-01-01T01:02:30.136] job_complete: JobID=1037 State=0x1 NodeCnt=3 WEXITSTATUS 0
[2017-01-01T01:02:30.136] job_complete: JobID=1037 State=0x8003 NodeCnt=3 done
[2017-01-01T01:02:51.136] Successfully submit job to queue (job_id: 1061)
[2017-01-01T01:02:51.136] job_complete: JobID=1040 State=0x1 NodeCnt=2 WEXITSTATUS 0
[2017-01-01T01:02:51.136] job_complete: JobID=1040 State=0x8003 NodeCnt=2 done
[2017-01-01T01:02:51.136] sched: Allocate JobID=1061 NodeList=n[1-3] #CPUs=36 Partition=normal
[2017-01-01T01:02:51.137] SIM: faking sending message type REQUEST_BATCH_JOB_LAUNCH to localhost

[2017-01-01T01:03:20.137] Successfully submit job to queue (job_id: 1062)
[2017-01-01T01:03:20.137] sched: Allocate JobID=1062 NodeList=m1 #CPUs=1 Partition=normal
[2017-01-01T01:03:20.137] SIM: faking sending message type REQUEST_BATCH_JOB_LAUNCH to localhost

[2017-01-01T01:03:53.137] Successfully submit job to queue (job_id: 1063)
[2017-01-01T01:04:01.137] job_complete: JobID=1050 State=0x1 NodeCnt=1 WEXITSTATUS 0
[2017-01-01T01:04:01.137] job_complete: JobID=1050 State=0x8003 NodeCnt=1 done
[2017-01-01T01:04:02.137] Successfully submit job to queue (job_id: 1064)
[2017-01-01T01:04:03.137] job_complete: JobID=1059 State=0x1 NodeCnt=1 WEXITSTATUS 0
[2017-01-01T01:04:03.138] job_complete: JobID=1059 State=0x8003 NodeCnt=1 done
[2017-01-01T01:04:04.138] sched: Allocate JobID=1064 NodeList=m1 #CPUs=6 Partition=normal
[2017-01-01T01:04:04.138] SIM: faking sending message type REQUEST_BATCH_JOB_LAUNCH to localhost

[2017-01-01T01:04:53.138] Successfully submit job to queue (job_id: 1065)
[2017-01-01T01:05:03.138] Successfully submit job to queue (job_id: 1066)
[2017-01-01T01:05:30.138] job_complete: JobID=1047 State=0x1 NodeCnt=1 WEXITSTATUS 0
[2017-01-01T01:05:30.138] job_complete: JobID=1047 State=0x8003 NodeCnt=1 done
[2017-01-01T01:06:29.144] Successfully submit job to queue (job_id: 1067)
[2017-01-01T01:06:33.144] job_complete: JobID=1064 State=0x1 NodeCnt=1 WEXITSTATUS 0
[2017-01-01T01:06:33.144] job_complete: JobID=1064 State=0x8003 NodeCnt=1 done
[2017-01-01T01:06:56.145] job_complete: JobID=1042 State=0x1 NodeCnt=1 WEXITSTATUS 0
[2017-01-01T01:06:56.145] job_complete: JobID=1042 State=0x8003 NodeCnt=1 done
[2017-01-01T01:07:12.145] Successfully submit job to queue (job_id: 1068)
[2017-01-01T01:07:17.145] job_complete: JobID=1062 State=0x1 NodeCnt=1 WEXITSTATUS 0
[2017-01-01T01:07:17.145] job_complete: JobID=1062 State=0x8003 NodeCnt=1 done
[2017-01-01T01:07:21.145] Successfully submit job to queue (job_id: 1069)
[2017-01-01T01:07:39.145] job_complete: JobID=1052 State=0x1 NodeCnt=1 WEXITSTATUS 0
[2017-01-01T01:07:39.145] job_complete: JobID=1052 State=0x8003 NodeCnt=1 done
[2017-01-01T01:08:10.145] job_complete: JobID=1058 State=0x1 NodeCnt=1 WEXITSTATUS 0
[2017-01-01T01:08:10.145] job_complete: JobID=1058 State=0x8003 NodeCnt=1 done
[2017-01-01T01:08:34.146] Successfully submit job to queue (job_id: 1070)
[2017-01-01T01:08:43.146] job_complete: JobID=1053 State=0x1 NodeCnt=1 WEXITSTATUS 0
[2017-01-01T01:08:43.146] job_complete: JobID=1053 State=0x8003 NodeCnt=1 done
[2017-01-01T01:08:49.146] Successfully submit job to queue (job_id: 1071)
[2017-01-01T01:09:00.146] job_complete: JobID=1051 State=0x1 NodeCnt=1 WEXITSTATUS 0
[2017-01-01T01:09:00.146] job_complete: JobID=1051 State=0x8003 NodeCnt=1 done
[2017-01-01T01:10:22.147] Successfully submit job to queue (job_id: 1072)
[2017-01-01T01:10:44.147] Successfully submit job to queue (job_id: 1073)
[2017-01-01T01:11:05.156] Successfully submit job to queue (job_id: 1074)
[2017-01-01T01:11:10.156] Successfully submit job to queue (job_id: 1075)
[2017-01-01T01:11:54.157] Successfully submit job to queue (job_id: 1076)
[2017-01-01T01:12:09.157] Successfully submit job to queue (job_id: 1077)
[2017-01-01T01:12:16.157] Successfully submit job to queue (job_id: 1078)
[2017-01-01T01:13:23.157] Successfully submit job to queue (job_id: 1079)
[2017-01-01T01:14:18.158] Successfully submit job to queue (job_id: 1080)
[2017-01-01T01:14:31.158] job_complete: JobID=1055 State=0x1 NodeCnt=1 WEXITSTATUS 0
[2017-01-01T01:14:31.158] job_complete: JobID=1055 State=0x8003 NodeCnt=1 done
[2017-01-01T01:15:20.158] Successfully submit job to queue (job_id: 1081)
[2017-01-01T01:15:57.168] Successfully submit job to queue (job_id: 1082)
[2017-01-01T01:17:25.169] Successfully submit job to queue (job_id: 1083)
[2017-01-01T01:17:39.169] Successfully submit job to queue (job_id: 1084)
[2017-01-01T01:18:11.169] Successfully submit job to queue (job_id: 1085)
[2017-01-01T01:18:29.169] Successfully submit job to queue (job_id: 1086)
[2017-01-01T01:18:40.169] Successfully submit job to queue (job_id: 1087)
[2017-01-01T01:19:15.169] Successfully submit job to queue (job_id: 1088)
[2017-01-01T01:19:19.170] Successfully submit job to queue (job_id: 1089)
[2017-01-01T01:20:29.170] job_complete: JobID=1057 State=0x1 NodeCnt=1 WEXITSTATUS 0
[2017-01-01T01:20:29.171] job_complete: JobID=1057 State=0x8003 NodeCnt=1 done
[2017-01-01T01:20:41.171] backfill: Started JobId=1080 in normal on m[1-4]
[2017-01-01T01:20:41.171] SIM: faking sending message type REQUEST_BATCH_JOB_LAUNCH to localhost

[2017-01-01T01:20:41.171] backfill: Started JobId=1072 in normal on b[1-3]
[2017-01-01T01:20:41.172] SIM: faking sending message type REQUEST_BATCH_JOB_LAUNCH to localhost

[2017-01-01T01:20:41.172] backfill: Started JobId=1082 in normal on b4
[2017-01-01T01:20:41.172] SIM: faking sending message type REQUEST_BATCH_JOB_LAUNCH to localhost

[2017-01-01T01:20:41.172] backfill: Started JobId=1065 in normal on n4
[2017-01-01T01:20:41.172] SIM: faking sending message type REQUEST_BATCH_JOB_LAUNCH to localhost

[2017-01-01T01:20:41.172] backfill: Started JobId=1067 in normal on b5
[2017-01-01T01:20:41.173] SIM: faking sending message type REQUEST_BATCH_JOB_LAUNCH to localhost

[2017-01-01T01:20:41.173] backfill: Started JobId=1088 in normal on b[6-8]
[2017-01-01T01:20:41.173] SIM: faking sending message type REQUEST_BATCH_JOB_LAUNCH to localhost

[2017-01-01T01:20:41.173] backfill: Started JobId=1070 in normal on b9
[2017-01-01T01:20:41.173] SIM: faking sending message type REQUEST_BATCH_JOB_LAUNCH to localhost

[2017-01-01T01:20:41.173] backfill: Started JobId=1075 in normal on b10
[2017-01-01T01:20:41.174] SIM: faking sending message type REQUEST_BATCH_JOB_LAUNCH to localhost

[2017-01-01T01:20:41.174] backfill: Started JobId=1069 in normal on b5
[2017-01-01T01:20:41.174] SIM: faking sending message type REQUEST_BATCH_JOB_LAUNCH to localhost

[2017-01-01T01:20:42.174] job_complete: JobID=1069 State=0x1 NodeCnt=1 WEXITSTATUS 0
[2017-01-01T01:20:42.174] job_complete: JobID=1069 State=0x8003 NodeCnt=1 done
[2017-01-01T01:20:57.174] Successfully submit job to queue (job_id: 1090)
[2017-01-01T01:21:41.178] job_complete: JobID=1046 State=0x1 NodeCnt=1 WEXITSTATUS 0
[2017-01-01T01:21:41.178] job_complete: JobID=1046 State=0x8003 NodeCnt=1 done
[2017-01-01T01:21:46.178] job_complete: JobID=1065 State=0x1 NodeCnt=1 WEXITSTATUS 0
[2017-01-01T01:21:46.178] job_complete: JobID=1065 State=0x8003 NodeCnt=1 done
[2017-01-01T01:22:12.179] job_complete: JobID=1045 State=0x1 NodeCnt=1 WEXITSTATUS 0
[2017-01-01T01:22:12.179] job_complete: JobID=1045 State=0x8003 NodeCnt=1 done
[2017-01-01T01:23:09.179] Successfully submit job to queue (job_id: 1091)
[2017-01-01T01:23:17.179] Successfully submit job to queue (job_id: 1092)
[2017-01-01T01:24:04.179] Successfully submit job to queue (job_id: 1093)
[2017-01-01T01:24:11.179] Successfully submit job to queue (job_id: 1094)
[2017-01-01T01:24:37.180] job_complete: JobID=1070 State=0x1 NodeCnt=1 WEXITSTATUS 0
[2017-01-01T01:24:37.180] job_complete: JobID=1070 State=0x8003 NodeCnt=1 done
[2017-01-01T01:24:52.180] job_complete: JobID=1072 State=0x1 NodeCnt=3 WEXITSTATUS 0
[2017-01-01T01:24:52.180] job_complete: JobID=1072 State=0x8003 NodeCnt=3 done
[2017-01-01T01:25:06.180] job_complete: JobID=1067 State=0x1 NodeCnt=1 WEXITSTATUS 0
[2017-01-01T01:25:06.180] job_complete: JobID=1067 State=0x8003 NodeCnt=1 done
[2017-01-01T01:25:38.180] Successfully submit job to queue (job_id: 1095)
[2017-01-01T01:27:19.188] Successfully submit job to queue (job_id: 1096)
[2017-01-01T01:27:30.189] Successfully submit job to queue (job_id: 1097)
[2017-01-01T01:28:00.189] Successfully submit job to queue (job_id: 1098)
[2017-01-01T01:28:14.189] Successfully submit job to queue (job_id: 1099)
[2017-01-01T01:28:15.189] job_complete: JobID=1075 State=0x1 NodeCnt=1 WEXITSTATUS 0
[2017-01-01T01:28:15.189] job_complete: JobID=1075 State=0x8003 NodeCnt=1 done
[2017-01-01T01:29:14.189] Successfully submit job to queue (job_id: 1100)
[2017-01-01T01:29:52.190] Successfully submit job to queue (job_id: 1101)
[2017-01-01T01:29:52.190] sched: Allocate JobID=1101 NodeList=b[1-3,5,9-10],g1,n4 #CPUs=96 Partition=normal
[2017-01-01T01:29:52.190] SIM: faking sending message type REQUEST_BATCH_JOB_LAUNCH to localhost

[2017-01-01T01:29:54.190] Successfully submit job to queue (job_id: 1102)
[2017-01-01T01:30:36.190] Successfully submit job to queue (job_id: 1103)
[2017-01-01T01:30:51.191] job_complete: JobID=1061 State=0x1 NodeCnt=3 WEXITSTATUS 0
[2017-01-01T01:30:51.191] job_complete: JobID=1061 State=0x8003 NodeCnt=3 done
[2017-01-01T01:30:56.191] Successfully submit job to queue (job_id: 1104)
[2017-01-01T01:31:15.198] job_complete: JobID=1080 State=0x1 NodeCnt=4 WEXITSTATUS 0
[2017-01-01T01:31:15.198] job_complete: JobID=1080 State=0x8003 NodeCnt=4 done
[2017-01-01T01:32:54.199] Successfully submit job to queue (job_id: 1105)
[2017-01-01T01:33:19.199] Successfully submit job to queue (job_id: 1106)
[2017-01-01T01:33:28.199] job_complete: JobID=1101 State=0x1 NodeCnt=8 WEXITSTATUS 0
[2017-01-01T01:33:28.199] job_complete: JobID=1101 State=0x8003 NodeCnt=8 done
[2017-01-01T01:33:28.199] sched: Allocate JobID=1066 NodeList=n[1-4] #CPUs=48 Partition=normal
[2017-01-01T01:33:28.199] SIM: faking sending message type REQUEST_BATCH_JOB_LAUNCH to localhost

[2017-01-01T01:34:02.200] Successfully submit job to queue (job_id: 1107)
[2017-01-01T01:34:41.200] job_complete: JobID=1088 State=0x1 NodeCnt=3 WEXITSTATUS 0
[2017-01-01T01:34:41.200] job_complete: JobID=1088 State=0x8003 NodeCnt=3 done
[2017-01-01T01:34:55.200] Successfully submit job to queue (job_id: 1108)
[2017-01-01T01:36:51.208] Successfully submit job to queue (job_id: 1109)
[2017-01-01T01:36:52.208] Successfully submit job to queue (job_id: 1110)
[2017-01-01T01:37:38.208] Successfully submit job to queue (job_id: 1111)
[2017-01-01T01:38:15.209] Successfully submit job to queue (job_id: 1112)
[2017-01-01T01:39:50.209] Successfully submit job to queue (job_id: 1113)
[2017-01-01T01:40:18.210] job_complete: JobID=1082 State=0x1 NodeCnt=1 WEXITSTATUS 0
[2017-01-01T01:40:18.210] job_complete: JobID=1082 State=0x8003 NodeCnt=1 done
[2017-01-01T01:40:21.210] Successfully submit job to queue (job_id: 1114)
[2017-01-01T01:40:41.210] backfill: Started JobId=1076 in normal on m1
[2017-01-01T01:40:41.210] SIM: faking sending message type REQUEST_BATCH_JOB_LAUNCH to localhost

[2017-01-01T01:40:41.210] backfill: Started JobId=1085 in normal on g1
[2017-01-01T01:40:41.210] SIM: faking sending message type REQUEST_BATCH_JOB_LAUNCH to localhost

[2017-01-01T01:40:41.210] backfill: Started JobId=1084 in normal on m2
[2017-01-01T01:40:41.211] SIM: faking sending message type REQUEST_BATCH_JOB_LAUNCH to localhost

[2017-01-01T01:40:41.211] backfill: Started JobId=1092 in normal on m[3-4]
[2017-01-01T01:40:41.211] SIM: faking sending message type REQUEST_BATCH_JOB_LAUNCH to localhost

[2017-01-01T01:40:41.211] backfill: Started JobId=1094 in normal on m2
[2017-01-01T01:40:41.211] SIM: faking sending message type REQUEST_BATCH_JOB_LAUNCH to localhost

[2017-01-01T01:40:41.211] backfill: Started JobId=1090 in normal on m2
[2017-01-01T01:40:41.211] SIM: faking sending message type REQUEST_BATCH_JOB_LAUNCH to localhost

[2017-01-01T01:40:41.212] backfill: Started JobId=1097 in normal on b1
[2017-01-01T01:40:41.212] SIM: faking sending message type REQUEST_BATCH_JOB_LAUNCH to localhost

[2017-01-01T01:40:41.212] backfill: Started JobId=1071 in normal on m2
[2017-01-01T01:40:41.212] SIM: faking sending message type REQUEST_BATCH_JOB_LAUNCH to localhost

[2017-01-01T01:40:41.212] backfill: Started JobId=1087 in normal on m2
[2017-01-01T01:40:41.212] SIM: faking sending message type REQUEST_BATCH_JOB_LAUNCH to localhost

[2017-01-01T01:40:41.212] backfill: Started JobId=1098 in normal on b2
[2017-01-01T01:40:41.213] SIM: faking sending message type REQUEST_BATCH_JOB_LAUNCH to localhost

[2017-01-01T01:40:41.213] backfill: Started JobId=1100 in normal on b3
[2017-01-01T01:40:41.213] SIM: faking sending message type REQUEST_BATCH_JOB_LAUNCH to localhost

[2017-01-01T01:40:41.213] backfill: Started JobId=1107 in normal on b4
[2017-01-01T01:40:41.213] SIM: faking sending message type REQUEST_BATCH_JOB_LAUNCH to localhost

[2017-01-01T01:40:41.213] backfill: Started JobId=1111 in normal on m2
[2017-01-01T01:40:41.213] SIM: faking sending message type REQUEST_BATCH_JOB_LAUNCH to localhost

[2017-01-01T01:40:42.213] job_complete: JobID=1076 State=0x1 NodeCnt=1 WEXITSTATUS 0
[2017-01-01T01:40:42.214] job_complete: JobID=1076 State=0x8003 NodeCnt=1 done
[2017-01-01T01:40:42.214] job_complete: JobID=1111 State=0x1 NodeCnt=1 WEXITSTATUS 0
[2017-01-01T01:40:42.214] job_complete: JobID=1111 State=0x8003 NodeCnt=1 done
[2017-01-01T01:40:42.214] job_complete: JobID=1100 State=0x1 NodeCnt=1 WEXITSTATUS 0
[2017-01-01T01:40:42.214] job_complete: JobID=1100 State=0x8003 NodeCnt=1 done
[2017-01-01T01:40:42.214] job_complete: JobID=1087 State=0x1 NodeCnt=1 WEXITSTATUS 0
[2017-01-01T01:40:42.214] job_complete: JobID=1087 State=0x8003 NodeCnt=1 done
[2017-01-01T01:40:42.214] job_complete: JobID=1071 State=0x1 NodeCnt=1 WEXITSTATUS 0
[2017-01-01T01:40:42.214] job_complete: JobID=1071 State=0x8003 NodeCnt=1 done
[2017-01-01T01:40:42.214] job_complete: JobID=1085 State=0x1 NodeCnt=1 WEXITSTATUS 0
[2017-01-01T01:40:42.214] job_complete: JobID=1085 State=0x8003 NodeCnt=1 done
[2017-01-01T01:41:26.219] Successfully submit job to queue (job_id: 1115)
[2017-01-01T01:42:26.219] Successfully submit job to queue (job_id: 1116)
[2017-01-01T01:43:56.220] job_complete: JobID=1066 State=0x1 NodeCnt=4 WEXITSTATUS 0
[2017-01-01T01:43:56.220] job_complete: JobID=1066 State=0x8003 NodeCnt=4 done
[2017-01-01T01:43:56.220] sched: Allocate JobID=1083 NodeList=n[1-3] #CPUs=36 Partition=normal
[2017-01-01T01:43:56.220] SIM: faking sending message type REQUEST_BATCH_JOB_LAUNCH to localhost

[2017-01-01T01:44:05.220] Successfully submit job to queue (job_id: 1117)
[2017-01-01T01:44:37.220] Successfully submit job to queue (job_id: 1118)
[2017-01-01T01:44:46.221] Successfully submit job to queue (job_id: 1119)
[2017-01-01T01:45:06.221] job_complete: JobID=1092 State=0x1 NodeCnt=2 WEXITSTATUS 0
[2017-01-01T01:45:06.221] job_complete: JobID=1092 State=0x8003 NodeCnt=2 done
[2017-01-01T01:45:52.221] job_complete: JobID=1090 State=0x1 NodeCnt=1 WEXITSTATUS 0
[2017-01-01T01:45:52.221] job_complete: JobID=1090 State=0x8003 NodeCnt=1 done
[2017-01-01T01:48:56.231] Successfully submit job to queue (job_id: 1120)
[2017-01-01T01:50:24.231] Successfully submit job to queue (job_id: 1121)
[2017-01-01T01:50:54.231] Successfully submit job to queue (job_id: 1122)
[2017-01-01T01:52:41.239] job_complete: JobID=1107 State=0x1 NodeCnt=1 WEXITSTATUS 0
[2017-01-01T01:52:41.239] job_complete: JobID=1107 State=0x8003 NodeCnt=1 done
[2017-01-01T01:53:43.240] Successfully submit job to queue (job_id: 1123)
[2017-01-01T01:53:44.240] job_complete: JobID=1083 State=0x1 NodeCnt=3 WEXITSTATUS 0
[2017-01-01T01:53:44.240] job_complete: JobID=1083 State=0x8003 NodeCnt=3 done
[2017-01-01T01:53:44.240] sched: Allocate JobID=1086 NodeList=n[1-3] #CPUs=36 Partition=normal
[2017-01-01T01:53:44.240] SIM: faking sending message type REQUEST_BATCH_JOB_LAUNCH to localhost

[2017-01-01T01:53:45.240] job_complete: JobID=1086 State=0x1 NodeCnt=3 WEXITSTATUS 0
[2017-01-01T01:53:45.240] job_complete: JobID=1086 State=0x8003 NodeCnt=3 done
[2017-01-01T01:53:50.240] Successfully submit job to queue (job_id: 1124)
[2017-01-01T01:54:08.240] job_complete: JobID=1084 State=0x1 NodeCnt=1 WEXITSTATUS 0
[2017-01-01T01:54:08.241] job_complete: JobID=1084 State=0x8003 NodeCnt=1 done
[2017-01-01T01:54:41.241] job_complete: JobID=1097 State=0x1 NodeCnt=1 WEXITSTATUS 0
[2017-01-01T01:54:41.241] job_complete: JobID=1097 State=0x8003 NodeCnt=1 done
[2017-01-01T01:55:23.241] Successfully submit job to queue (job_id: 1125)
[2017-01-01T01:55:54.241] Successfully submit job to queue (job_id: 1126)
[2017-01-01T01:56:13.249] Successfully submit job to queue (job_id: 1127)
[2017-01-01T01:56:31.249] Successfully submit job to queue (job_id: 1128)
[2017-01-01T01:57:03.249] Successfully submit job to queue (job_id: 1129)
[2017-01-01T01:57:57.250] Successfully submit job to queue (job_id: 1130)
[2017-01-01T01:58:39.250] Successfully submit job to queue (job_id: 1131)
[2017-01-01T01:58:48.250] Successfully submit job to queue (job_id: 1132)
[2017-01-01T01:58:58.250] job_complete: JobID=1098 State=0x1 NodeCnt=1 WEXITSTATUS 0
[2017-01-01T01:58:58.250] job_complete: JobID=1098 State=0x8003 NodeCnt=1 done
[2017-01-01T02:00:41.251] backfill: Started JobId=1129 in normal on n[1-4]
[2017-01-01T02:00:41.251] SIM: faking sending message type REQUEST_BATCH_JOB_LAUNCH to localhost

[2017-01-01T02:00:41.251] backfill: Started JobId=1116 in normal on b1
[2017-01-01T02:00:41.252] SIM: faking sending message type REQUEST_BATCH_JOB_LAUNCH to localhost

[2017-01-01T02:00:41.252] backfill: Started JobId=1041 in normal on g1
[2017-01-01T02:00:41.252] SIM: faking sending message type REQUEST_BATCH_JOB_LAUNCH to localhost

[2017-01-01T02:00:41.252] backfill: Started JobId=1126 in normal on m[1,3]
[2017-01-01T02:00:41.252] SIM: faking sending message type REQUEST_BATCH_JOB_LAUNCH to localhost

[2017-01-01T02:00:41.252] backfill: Started JobId=1125 in normal on b2
[2017-01-01T02:00:41.252] SIM: faking sending message type REQUEST_BATCH_JOB_LAUNCH to localhost

[2017-01-01T02:00:41.252] backfill: Started JobId=1063 in normal on g1
[2017-01-01T02:00:41.253] SIM: faking sending message type REQUEST_BATCH_JOB_LAUNCH to localhost

[2017-01-01T02:00:41.253] backfill: Started JobId=1132 in normal on m2
[2017-01-01T02:00:41.253] SIM: faking sending message type REQUEST_BATCH_JOB_LAUNCH to localhost

[2017-01-01T02:00:41.253] backfill: Started JobId=1079 in normal on m4
[2017-01-01T02:00:41.253] SIM: faking sending message type REQUEST_BATCH_JOB_LAUNCH to localhost

[2017-01-01T02:00:41.253] backfill: Started JobId=1117 in normal on b3
[2017-01-01T02:00:41.253] SIM: faking sending message type REQUEST_BATCH_JOB_LAUNCH to localhost

[2017-01-01T02:00:41.253] backfill: Started JobId=1060 in normal on m2
[2017-01-01T02:00:41.254] SIM: faking sending message type REQUEST_BATCH_JOB_LAUNCH to localhost

[2017-01-01T02:00:41.254] backfill: Started JobId=1122 in normal on b2
[2017-01-01T02:00:41.254] SIM: faking sending message type REQUEST_BATCH_JOB_LAUNCH to localhost

[2017-01-01T02:00:41.254] backfill: Started JobId=1130 in normal on b4
[2017-01-01T02:00:41.254] SIM: faking sending message type REQUEST_BATCH_JOB_LAUNCH to localhost

[2017-01-01T02:00:41.254] backfill: Started JobId=1124 in normal on m2
[2017-01-01T02:00:41.255] SIM: faking sending message type REQUEST_BATCH_JOB_LAUNCH to localhost

[2017-01-01T02:00:42.255] job_complete: JobID=1125 State=0x1 NodeCnt=1 WEXITSTATUS 0
[2017-01-01T02:00:42.255] job_complete: JobID=1125 State=0x8003 NodeCnt=1 done
[2017-01-01T02:00:42.255] job_complete: JobID=1124 State=0x1 NodeCnt=1 WEXITSTATUS 0
[2017-01-01T02:00:42.255] job_complete: JobID=1124 State=0x8003 NodeCnt=1 done
[2017-01-01T02:00:42.255] job_complete: JobID=1079 State=0x1 NodeCnt=1 WEXITSTATUS 0
[2017-01-01T02:00:42.255] job_complete: JobID=1079 State=0x8003 NodeCnt=1 done
[2017-01-01T02:00:42.255] job_complete: JobID=1132 State=0x1 NodeCnt=1 WEXITSTATUS 0
[2017-01-01T02:00:42.255] job_complete: JobID=1132 State=0x8003 NodeCnt=1 done
[2017-01-01T02:01:03.255] Successfully submit job to queue (job_id: 1133)
[2017-01-01T02:01:08.260] Successfully submit job to queue (job_id: 1134)
[2017-01-01T02:01:15.260] job_complete: JobID=1130 State=0x1 NodeCnt=1 WEXITSTATUS 0
[2017-01-01T02:01:15.260] job_complete: JobID=1130 State=0x8003 NodeCnt=1 done
[2017-01-01T02:01:23.260] job_complete: JobID=1126 State=0x1 NodeCnt=2 WEXITSTATUS 0
[2017-01-01T02:01:23.260] job_complete: JobID=1126 State=0x8003 NodeCnt=2 done
[2017-01-01T02:01:36.260] Successfully submit job to queue (job_id: 1135)
[2017-01-01T02:02:11.260] Successfully submit job to queue (job_id: 1136)
[2017-01-01T02:02:23.260] Successfully submit job to queue (job_id: 1137)
[2017-01-01T02:03:02.261] Successfully submit job to queue (job_id: 1138)
[2017-01-01T02:04:03.261] Successfully submit job to queue (job_id: 1139)
[2017-01-01T02:04:18.261] Successfully submit job to queue (job_id: 1140)
[2017-01-01T02:05:04.262] job_complete: JobID=1063 State=0x1 NodeCnt=1 WEXITSTATUS 0
[2017-01-01T02:05:04.262] job_complete: JobID=1063 State=0x8003 NodeCnt=1 done
[2017-01-01T02:05:37.262] job_complete: JobID=1060 State=0x1 NodeCnt=1 WEXITSTATUS 0
[2017-01-01T02:05:37.262] job_complete: JobID=1060 State=0x8003 NodeCnt=1 done
[2017-01-01T02:06:23.271] Successfully submit job to queue (job_id: 1141)
[2017-01-01T02:06:26.271] job_complete: JobID=1041 State=0x1 NodeCnt=1 WEXITSTATUS 0
[2017-01-01T02:06:26.271] job_complete: JobID=1041 State=0x8003 NodeCnt=1 done
[2017-01-01T02:06:32.271] Successfully submit job to queue (job_id: 1142)
[2017-01-01T02:07:03.271] job_complete: JobID=1122 State=0x1 NodeCnt=1 WEXITSTATUS 0
[2017-01-01T02:07:03.271] job_complete: JobID=1122 State=0x8003 NodeCnt=1 done
[2017-01-01T02:08:06.272] Successfully submit job to queue (job_id: 1143)
[2017-01-01T02:08:56.272] Successfully submit job to queue (job_id: 1144)
[2017-01-01T02:09:41.272] job_complete: JobID=1094 State=0x1 NodeCnt=1 WEXITSTATUS 0
[2017-01-01T02:09:41.272] job_complete: JobID=1094 State=0x8003 NodeCnt=1 done
[2017-01-01T02:09:41.272] sched: Allocate JobID=1091 NodeList=m[1-4] #CPUs=48 Partition=normal
[2017-01-01T02:09:41.272] SIM: faking sending message type REQUEST_BATCH_JOB_LAUNCH to localhost

[2017-01-01T02:09:48.273] Successfully submit job to queue (job_id: 1145)
[2017-01-01T02:10:26.273] Successfully submit job to queue (job_id: 1146)
[2017-01-01T02:10:26.273] sched: Allocate JobID=1146 NodeList=b[2,4-10] #CPUs=96 Partition=normal
[2017-01-01T02:10:26.273] SIM: faking sending message type REQUEST_BATCH_JOB_LAUNCH to localhost

[2017-01-01T02:10:27.273] job_complete: JobID=1146 State=0x1 NodeCnt=8 WEXITSTATUS 0
[2017-01-01T02:10:27.273] job_complete: JobID=1146 State=0x8003 NodeCnt=8 done
[2017-01-01T02:10:38.274] Successfully submit job to queue (job_id: 1147)
[2017-01-01T02:10:39.274] Successfully submit job to queue (job_id: 1148)
[2017-01-01T02:11:38.283] Successfully submit job to queue (job_id: 1149)
[2017-01-01T02:13:43.284] job_complete: JobID=1116 State=0x1 NodeCnt=1 WEXITSTATUS 0
[2017-01-01T02:13:43.284] job_complete: JobID=1116 State=0x8003 NodeCnt=1 done
[2017-01-01T02:13:50.284] Successfully submit job to queue (job_id: 1150)
[2017-01-01T02:14:16.284] job_complete: JobID=1129 State=0x1 NodeCnt=4 WEXITSTATUS 0
[2017-01-01T02:14:16.284] job_complete: JobID=1129 State=0x8003 NodeCnt=4 done
[2017-01-01T02:14:16.284] sched: Allocate JobID=1068 NodeList=n1 #CPUs=1 Partition=normal
[2017-01-01T02:14:16.284] SIM: faking sending message type REQUEST_BATCH_JOB_LAUNCH to localhost

[2017-01-01T02:14:16.284] sched: Allocate JobID=1096 NodeList=n1 #CPUs=6 Partition=normal
[2017-01-01T02:14:16.284] SIM: faking sending message type REQUEST_BATCH_JOB_LAUNCH to localhost

[2017-01-01T02:14:16.284] sched: Allocate JobID=1120 NodeList=n2 #CPUs=12 Partition=normal
[2017-01-01T02:14:16.285] SIM: faking sending message type REQUEST_BATCH_JOB_LAUNCH to localhost

[2017-01-01T02:14:16.285] sched: Allocate JobID=1108 NodeList=n3 #CPUs=6 Partition=normal
[2017-01-01T02:14:16.285] SIM: faking sending message type REQUEST_BATCH_JOB_LAUNCH to localhost

[2017-01-01T02:15:00.285] Successfully submit job to queue (job_id: 1151)
[2017-01-01T02:15:10.286] Successfully submit job to queue (job_id: 1152)
[2017-01-01T02:16:42.293] Successfully submit job to queue (job_id: 1153)
[2017-01-01T02:16:47.293] Successfully submit job to queue (job_id: 1154)
[2017-01-01T02:16:54.293] Successfully submit job to queue (job_id: 1155)
[2017-01-01T02:17:09.293] Successfully submit job to queue (job_id: 1156)
[2017-01-01T02:17:09.293] Successfully submit job to queue (job_id: 1157)
[2017-01-01T02:17:09.293] sched: Allocate JobID=1156 NodeList=b[1-2,4-9] #CPUs=96 Partition=normal
[2017-01-01T02:17:09.294] SIM: faking sending message type REQUEST_BATCH_JOB_LAUNCH to localhost

[2017-01-01T02:17:52.294] Successfully submit job to queue (job_id: 1158)
[2017-01-01T02:18:45.294] Successfully submit job to queue (job_id: 1159)
[2017-01-01T02:19:05.294] job_complete: JobID=1068 State=0x1 NodeCnt=1 WEXITSTATUS 0
[2017-01-01T02:19:05.295] job_complete: JobID=1068 State=0x8003 NodeCnt=1 done
[2017-01-01T02:19:32.295] Successfully submit job to queue (job_id: 1160)
[2017-01-01T02:20:41.296] backfill: Started JobId=1102 in normal on n1
[2017-01-01T02:20:41.296] SIM: faking sending message type REQUEST_BATCH_JOB_LAUNCH to localhost

[2017-01-01T02:20:41.296] backfill: Started JobId=1140 in normal on g1
[2017-01-01T02:20:41.296] SIM: faking sending message type REQUEST_BATCH_JOB_LAUNCH to localhost

[2017-01-01T02:20:41.296] backfill: Started JobId=1113 in normal on n1
[2017-01-01T02:20:41.296] SIM: faking sending message type REQUEST_BATCH_JOB_LAUNCH to localhost

[2017-01-01T02:20:41.297] backfill: Started JobId=1123 in normal on n1
[2017-01-01T02:20:41.297] SIM: faking sending message type REQUEST_BATCH_JOB_LAUNCH to localhost

[2017-01-01T02:20:41.297] backfill: Started JobId=1153 in normal on b10,n4
[2017-01-01T02:20:41.297] SIM: faking sending message type REQUEST_BATCH_JOB_LAUNCH to localhost

[2017-01-01T02:20:41.298] backfill: Started JobId=1134 in normal on n3
[2017-01-01T02:20:41.298] SIM: faking sending message type REQUEST_BATCH_JOB_LAUNCH to localhost

[2017-01-01T02:20:51.300] job_complete: JobID=1156 State=0x1 NodeCnt=8 WEXITSTATUS 0
[2017-01-01T02:20:51.300] job_complete: JobID=1156 State=0x8003 NodeCnt=8 done
[2017-01-01T02:20:51.300] sched: Allocate JobID=1158 NodeList=b[1-2,4-9] #CPUs=96 Partition=normal
[2017-01-01T02:20:51.300] SIM: faking sending message type REQUEST_BATCH_JOB_LAUNCH to localhost

[2017-01-01T02:20:58.300] Successfully submit job to queue (job_id: 1161)
[2017-01-01T02:21:06.301] Successfully submit job to queue (job_id: 1162)
[2017-01-01T02:22:01.302] Successfully submit job to queue (job_id: 1163)
[2017-01-01T02:22:23.302] Successfully submit job to queue (job_id: 1164)
[2017-01-01T02:23:56.303] Successfully submit job to queue (job_id: 1165)
[2017-01-01T02:24:23.303] Successfully submit job to queue (job_id: 1166)
[2017-01-01T02:24:31.303] Successfully submit job to queue (job_id: 1167)
[2017-01-01T02:24:35.303] Successfully submit job to queue (job_id: 1168)
[2017-01-01T02:24:37.303] Successfully submit job to queue (job_id: 1169)
[2017-01-01T02:25:16.304] job_complete: JobID=1096 State=0x1 NodeCnt=1 WEXITSTATUS 0
[2017-01-01T02:25:16.304] job_complete: JobID=1096 State=0x8003 NodeCnt=1 done
[2017-01-01T02:25:23.304] job_complete: JobID=1134 State=0x1 NodeCnt=1 WEXITSTATUS 0
[2017-01-01T02:25:23.304] job_complete: JobID=1134 State=0x8003 NodeCnt=1 done
[2017-01-01T02:25:35.304] Successfully submit job to queue (job_id: 1170)
[2017-01-01T02:26:31.310] Successfully submit job to queue (job_id: 1171)
[2017-01-01T02:26:56.311] job_complete: JobID=1108 State=0x1 NodeCnt=1 WEXITSTATUS 0
[2017-01-01T02:26:56.311] job_complete: JobID=1108 State=0x8003 NodeCnt=1 done
[2017-01-01T02:27:11.311] job_complete: JobID=1158 State=0x1 NodeCnt=8 WEXITSTATUS 0
[2017-01-01T02:27:11.311] job_complete: JobID=1158 State=0x8003 NodeCnt=8 done
[2017-01-01T02:27:11.311] sched: Allocate JobID=1162 NodeList=b[1-2,4-9] #CPUs=96 Partition=normal
[2017-01-01T02:27:11.311] SIM: faking sending message type REQUEST_BATCH_JOB_LAUNCH to localhost

[2017-01-01T02:27:13.311] job_complete: JobID=1120 State=0x1 NodeCnt=1 WEXITSTATUS 0
[2017-01-01T02:27:13.311] job_complete: JobID=1120 State=0x8003 NodeCnt=1 done
[2017-01-01T02:27:24.312] job_complete: JobID=1113 State=0x1 NodeCnt=1 WEXITSTATUS 0
[2017-01-01T02:27:24.312] job_complete: JobID=1113 State=0x8003 NodeCnt=1 done
[2017-01-01T02:27:41.312] job_complete: JobID=1123 State=0x1 NodeCnt=1 WEXITSTATUS 0
[2017-01-01T02:27:41.312] job_complete: JobID=1123 State=0x8003 NodeCnt=1 done
[2017-01-01T02:27:57.312] Successfully submit job to queue (job_id: 1172)
[2017-01-01T02:29:18.312] Successfully submit job to queue (job_id: 1173)
[2017-01-01T02:30:05.313] job_complete: JobID=1162 State=0x1 NodeCnt=8 WEXITSTATUS 0
[2017-01-01T02:30:05.313] job_complete: JobID=1162 State=0x8003 NodeCnt=8 done
[2017-01-01T02:30:34.313] job_complete: JobID=1091 State=0x1 NodeCnt=4 WEXITSTATUS 0
[2017-01-01T02:30:34.313] job_complete: JobID=1091 State=0x8003 NodeCnt=4 done
[2017-01-01T02:30:34.313] sched: Allocate JobID=1118 NodeList=m[1-3] #CPUs=36 Partition=normal
[2017-01-01T02:30:34.313] SIM: faking sending message type REQUEST_BATCH_JOB_LAUNCH to localhost

[2017-01-01T02:30:37.314] job_complete: JobID=1117 State=0x1 NodeCnt=1 WEXITSTATUS 0
[2017-01-01T02:30:37.314] job_complete: JobID=1117 State=0x8003 NodeCnt=1 done
[2017-01-01T02:31:09.314] Successfully submit job to queue (job_id: 1174)
[2017-01-01T02:31:26.322] Successfully submit job to queue (job_id: 1175)
[2017-01-01T02:31:31.323] Successfully submit job to queue (job_id: 1176)
[2017-01-01T02:32:06.323] Successfully submit job to queue (job_id: 1177)
[2017-01-01T02:34:02.324] Successfully submit job to queue (job_id: 1178)
[2017-01-01T02:35:30.325] Successfully submit job to queue (job_id: 1179)
[2017-01-01T02:36:32.333] job_complete: JobID=1140 State=0x1 NodeCnt=1 WEXITSTATUS 0
[2017-01-01T02:36:32.333] job_complete: JobID=1140 State=0x8003 NodeCnt=1 done
[2017-01-01T02:36:56.334] Successfully submit job to queue (job_id: 1180)
[2017-01-01T02:37:27.334] Successfully submit job to queue (job_id: 1181)
[2017-01-01T02:37:54.334] Successfully submit job to queue (job_id: 1182)
[2017-01-01T02:37:56.334] Successfully submit job to queue (job_id: 1183)
[2017-01-01T02:38:50.335] job_complete: JobID=1102 State=0x1 NodeCnt=1 WEXITSTATUS 0
[2017-01-01T02:38:50.335] job_complete: JobID=1102 State=0x8003 NodeCnt=1 done
[2017-01-01T02:39:46.335] Successfully submit job to queue (job_id: 1184)
[2017-01-01T02:40:41.336] backfill: Started JobId=1081 in normal on g1
[2017-01-01T02:40:41.336] SIM: faking sending message type REQUEST_BATCH_JOB_LAUNCH to localhost

[2017-01-01T02:40:41.336] backfill: Started JobId=1104 in normal on n[1-2]
[2017-01-01T02:40:41.337] SIM: faking sending message type REQUEST_BATCH_JOB_LAUNCH to localhost

[2017-01-01T02:40:41.337] backfill: Started JobId=1074 in normal on m4
[2017-01-01T02:40:41.337] SIM: faking sending message type REQUEST_BATCH_JOB_LAUNCH to localhost

[2017-01-01T02:40:41.337] backfill: Started JobId=1127 in normal on m4
[2017-01-01T02:40:41.337] SIM: faking sending message type REQUEST_BATCH_JOB_LAUNCH to localhost

[2017-01-01T02:40:41.337] backfill: Started JobId=1183 in normal on b[1-3]
[2017-01-01T02:40:41.337] SIM: faking sending message type REQUEST_BATCH_JOB_LAUNCH to localhost

[2017-01-01T02:40:41.337] backfill: Started JobId=1138 in normal on b4
[2017-01-01T02:40:41.337] SIM: faking sending message type REQUEST_BATCH_JOB_LAUNCH to localhost

[2017-01-01T02:40:41.337] backfill: Started JobId=1182 in normal on b[5-6]
[2017-01-01T02:40:41.338] SIM: faking sending message type REQUEST_BATCH_JOB_LAUNCH to localhost

[2017-01-01T02:40:41.338] backfill: Started JobId=1179 in normal on b7
[2017-01-01T02:40:41.338] SIM: faking sending message type REQUEST_BATCH_JOB_LAUNCH to localhost

[2017-01-01T02:40:41.338] backfill: Started JobId=1171 in normal on b8
[2017-01-01T02:40:41.338] SIM: faking sending message type REQUEST_BATCH_JOB_LAUNCH to localhost

[2017-01-01T02:40:41.338] backfill: Started JobId=1151 in normal on m4
[2017-01-01T02:40:41.338] SIM: faking sending message type REQUEST_BATCH_JOB_LAUNCH to localhost

[2017-01-01T02:40:41.339] backfill: Started JobId=1073 in normal on g1
[2017-01-01T02:40:41.339] SIM: faking sending message type REQUEST_BATCH_JOB_LAUNCH to localhost

[2017-01-01T02:40:41.339] backfill: Started JobId=1110 in normal on m4
[2017-01-01T02:40:41.339] SIM: faking sending message type REQUEST_BATCH_JOB_LAUNCH to localhost

[2017-01-01T02:40:41.340] backfill: Started JobId=1184 in normal on m4
[2017-01-01T02:40:41.340] SIM: faking sending message type REQUEST_BATCH_JOB_LAUNCH to localhost

[2017-01-01T02:40:41.344] backfill: Started JobId=1174 in normal on m4
[2017-01-01T02:40:41.344] SIM: faking sending message type REQUEST_BATCH_JOB_LAUNCH to localhost

[2017-01-01T02:40:42.344] job_complete: JobID=1138 State=0x1 NodeCnt=1 WEXITSTATUS 0
[2017-01-01T02:40:42.344] job_complete: JobID=1138 State=0x8003 NodeCnt=1 done
[2017-01-01T02:41:11.344] Successfully submit job to queue (job_id: 1185)
[2017-01-01T02:41:31.346] Successfully submit job to queue (job_id: 1186)
[2017-01-01T02:41:36.346] job_complete: JobID=1153 State=0x1 NodeCnt=2 WEXITSTATUS 0
[2017-01-01T02:41:36.346] job_complete: JobID=1153 State=0x8003 NodeCnt=2 done
[2017-01-01T02:41:42.346] job_complete: JobID=1171 State=0x1 NodeCnt=1 WEXITSTATUS 0
[2017-01-01T02:41:42.346] job_complete: JobID=1171 State=0x8003 NodeCnt=1 done
[2017-01-01T02:42:52.347] Successfully submit job to queue (job_id: 1187)
[2017-01-01T02:42:58.347] Successfully submit job to queue (job_id: 1188)
[2017-01-01T02:43:04.347] job_complete: JobID=1151 State=0x1 NodeCnt=1 WEXITSTATUS 0
[2017-01-01T02:43:04.347] job_complete: JobID=1151 State=0x8003 NodeCnt=1 done
[2017-01-01T02:43:07.347] Successfully submit job to queue (job_id: 1189)
[2017-01-01T02:43:07.347] Successfully submit job to queue (job_id: 1190)
[2017-01-01T02:43:07.347] job_complete: JobID=1127 State=0x1 NodeCnt=1 WEXITSTATUS 0
[2017-01-01T02:43:07.347] job_complete: JobID=1127 State=0x8003 NodeCnt=1 done
[2017-01-01T02:43:16.347] job_complete: JobID=1118 State=0x1 NodeCnt=3 WEXITSTATUS 0
[2017-01-01T02:43:16.347] job_complete: JobID=1118 State=0x8003 NodeCnt=3 done
[2017-01-01T02:43:16.347] sched: Allocate JobID=1131 NodeList=m[1-2] #CPUs=24 Partition=normal
[2017-01-01T02:43:16.348] SIM: faking sending message type REQUEST_BATCH_JOB_LAUNCH to localhost

[2017-01-01T02:43:38.348] job_complete: JobID=1073 State=0x1 NodeCnt=1 WEXITSTATUS 0
[2017-01-01T02:43:38.348] job_complete: JobID=1073 State=0x8003 NodeCnt=1 done
[2017-01-01T02:44:57.348] Successfully submit job to queue (job_id: 1191)
[2017-01-01T02:44:57.348] sched: Allocate JobID=1191 NodeList=b[4,8-9] #CPUs=36 Partition=normal
[2017-01-01T02:44:57.349] SIM: faking sending message type REQUEST_BATCH_JOB_LAUNCH to localhost

[2017-01-01T02:45:21.349] job_complete: JobID=1174 State=0x1 NodeCnt=1 WEXITSTATUS 0
[2017-01-01T02:45:21.349] job_complete: JobID=1174 State=0x8003 NodeCnt=1 done
[2017-01-01T02:46:10.350] Successfully submit job to queue (job_id: 1192)
[2017-01-01T02:46:36.356] Successfully submit job to queue (job_id: 1193)
[2017-01-01T02:47:24.357] job_complete: JobID=1191 State=0x1 NodeCnt=3 WEXITSTATUS 0
[2017-01-01T02:47:24.357] job_complete: JobID=1191 State=0x8003 NodeCnt=3 done
[2017-01-01T02:47:50.357] Successfully submit job to queue (job_id: 1194)
[2017-01-01T02:47:58.357] Successfully submit job to queue (job_id: 1195)
[2017-01-01T02:49:14.358] Successfully submit job to queue (job_id: 1196)
[2017-01-01T02:49:35.358] Successfully submit job to queue (job_id: 1197)
[2017-01-01T02:50:07.359] Successfully submit job to queue (job_id: 1198)
[2017-01-01T02:50:09.359] job_complete: JobID=1081 State=0x1 NodeCnt=1 WEXITSTATUS 0
[2017-01-01T02:50:09.359] job_complete: JobID=1081 State=0x8003 NodeCnt=1 done
[2017-01-01T02:50:10.359] sched: Allocate JobID=1089 NodeList=g1 #CPUs=2 Partition=normal
[2017-01-01T02:50:10.359] SIM: faking sending message type REQUEST_BATCH_JOB_LAUNCH to localhost

[2017-01-01T02:50:10.359] sched: Allocate JobID=1173 NodeList=n[3-4] #CPUs=24 Partition=normal
[2017-01-01T02:50:10.359] SIM: faking sending message type REQUEST_BATCH_JOB_LAUNCH to localhost

[2017-01-01T02:50:11.359] job_complete: JobID=1173 State=0x1 NodeCnt=2 WEXITSTATUS 0
[2017-01-01T02:50:11.360] job_complete: JobID=1173 State=0x8003 NodeCnt=2 done
[2017-01-01T02:50:18.360] Successfully submit job to queue (job_id: 1199)
[2017-01-01T02:51:30.365] job_complete: JobID=1089 State=0x1 NodeCnt=1 WEXITSTATUS 0
[2017-01-01T02:51:30.366] job_complete: JobID=1089 State=0x8003 NodeCnt=1 done
[2017-01-01T02:51:47.366] Successfully submit job to queue (job_id: 1200)
[2017-01-01T02:52:44.366] Successfully submit job to queue (job_id: 1201)
[2017-01-01T02:53:07.366] Successfully submit job to queue (job_id: 1202)
[2017-01-01T02:53:10.366] job_complete: JobID=1179 State=0x1 NodeCnt=1 WEXITSTATUS 0
[2017-01-01T02:53:10.367] job_complete: JobID=1179 State=0x8003 NodeCnt=1 done
[2017-01-01T02:54:09.367] Successfully submit job to queue (job_id: 1203)
[2017-01-01T02:54:34.367] job_complete: JobID=1110 State=0x1 NodeCnt=1 WEXITSTATUS 0
[2017-01-01T02:54:34.367] job_complete: JobID=1110 State=0x8003 NodeCnt=1 done
[2017-01-01T02:54:44.367] Successfully submit job to queue (job_id: 1204)
[2017-01-01T02:54:51.367] Successfully submit job to queue (job_id: 1205)
[2017-01-01T02:55:03.368] Successfully submit job to queue (job_id: 1206)
[2017-01-01T02:55:07.368] job_complete: JobID=1182 State=0x1 NodeCnt=2 WEXITSTATUS 0
[2017-01-01T02:55:07.368] job_complete: JobID=1182 State=0x8003 NodeCnt=2 done
[2017-01-01T02:55:16.368] job_complete: JobID=1131 State=0x1 NodeCnt=2 WEXITSTATUS 0
[2017-01-01T02:55:16.368] job_complete: JobID=1131 State=0x8003 NodeCnt=2 done
[2017-01-01T02:55:32.369] Successfully submit job to queue (job_id: 1207)
[2017-01-01T02:55:45.369] Successfully submit job to queue (job_id: 1208)
[2017-01-01T02:56:04.369] job_complete: JobID=1074 State=0x1 NodeCnt=1 WEXITSTATUS 0
[2017-01-01T02:56:04.369] job_complete: JobID=1074 State=0x8003 NodeCnt=1 done
[2017-01-01T02:56:19.375] Successfully submit job to queue (job_id: 1209)
[2017-01-01T02:56:21.375] Successfully submit job to queue (job_id: 1210)
[2017-01-01T02:57:02.376] Successfully submit job to queue (job_id: 1211)
[2017-01-01T02:57:35.376] Successfully submit job to queue (job_id: 1212)
[2017-01-01T02:59:41.377] job_complete: JobID=1184 State=0x1 NodeCnt=1 WEXITSTATUS 0
[2017-01-01T02:59:41.377] job_complete: JobID=1184 State=0x8003 NodeCnt=1 done
[2017-01-01T03:00:07.378] job_complete: JobID=1104 State=0x1 NodeCnt=2 WEXITSTATUS 0
[2017-01-01T03:00:07.378] job_complete: JobID=1104 State=0x8003 NodeCnt=2 done
[2017-01-01T03:00:07.378] sched: Allocate JobID=1198 NodeList=n[1-4] #CPUs=48 Partition=normal
[2017-01-01T03:00:07.378] SIM: faking sending message type REQUEST_BATCH_JOB_LAUNCH to localhost

[2017-01-01T03:00:07.378] sched: Allocate JobID=1199 NodeList=m[1-4] #CPUs=48 Partition=normal
[2017-01-01T03:00:07.378] SIM: faking sending message type REQUEST_BATCH_JOB_LAUNCH to localhost

[2017-01-01T03:00:41.379] backfill: Started JobId=1148 in normal on b[4-5]
[2017-01-01T03:00:41.379] SIM: faking sending message type REQUEST_BATCH_JOB_LAUNCH to localhost

[2017-01-01T03:00:41.379] backfill: Started JobId=1190 in normal on b[6-7]
[2017-01-01T03:00:41.379] SIM: faking sending message type REQUEST_BATCH_JOB_LAUNCH to localhost

[2017-01-01T03:00:41.379] backfill: Started JobId=1157 in normal on g1
[2017-01-01T03:00:41.380] SIM: faking sending message type REQUEST_BATCH_JOB_LAUNCH to localhost

[2017-01-01T03:00:41.380] backfill: Started JobId=1175 in normal on b[8-9]
[2017-01-01T03:00:41.380] SIM: faking sending message type REQUEST_BATCH_JOB_LAUNCH to localhost

[2017-01-01T03:00:41.380] backfill: Started JobId=1136 in normal on b10
[2017-01-01T03:00:41.380] SIM: faking sending message type REQUEST_BATCH_JOB_LAUNCH to localhost

[2017-01-01T03:00:41.382] backfill: Started JobId=1181 in normal on g1
[2017-01-01T03:00:41.382] SIM: faking sending message type REQUEST_BATCH_JOB_LAUNCH to localhost

[2017-01-01T03:00:41.384] backfill: Started JobId=1196 in normal on g1
[2017-01-01T03:00:41.384] SIM: faking sending message type REQUEST_BATCH_JOB_LAUNCH to localhost

[2017-01-01T03:00:41.384] backfill: Started JobId=1167 in normal on g1
[2017-01-01T03:00:41.384] SIM: faking sending message type REQUEST_BATCH_JOB_LAUNCH to localhost

[2017-01-01T03:00:41.385] backfill: Started JobId=1207 in normal on g1
[2017-01-01T03:00:41.385] SIM: faking sending message type REQUEST_BATCH_JOB_LAUNCH to localhost

[2017-01-01T03:00:42.385] job_complete: JobID=1207 State=0x1 NodeCnt=1 WEXITSTATUS 0
[2017-01-01T03:00:42.385] job_complete: JobID=1207 State=0x8003 NodeCnt=1 done
[2017-01-01T03:01:12.386] Successfully submit job to queue (job_id: 1213)
[2017-01-01T03:01:14.386] Successfully submit job to queue (job_id: 1214)
[2017-01-01T03:01:54.387] Successfully submit job to queue (job_id: 1215)
[2017-01-01T03:02:33.387] Successfully submit job to queue (job_id: 1216)
[2017-01-01T03:03:02.388] Successfully submit job to queue (job_id: 1217)
[2017-01-01T03:03:11.388] job_complete: JobID=1148 State=0x1 NodeCnt=2 WEXITSTATUS 0
[2017-01-01T03:03:11.388] job_complete: JobID=1148 State=0x8003 NodeCnt=2 done
[2017-01-01T03:04:43.389] Successfully submit job to queue (job_id: 1218)
[2017-01-01T03:04:53.389] job_complete: JobID=1196 State=0x1 NodeCnt=1 WEXITSTATUS 0
[2017-01-01T03:04:53.389] job_complete: JobID=1196 State=0x8003 NodeCnt=1 done
[2017-01-01T03:06:40.399] Successfully submit job to queue (job_id: 1219)
[2017-01-01T03:06:49.400] job_complete: JobID=1199 State=0x1 NodeCnt=4 WEXITSTATUS 0
[2017-01-01T03:06:49.400] job_complete: JobID=1199 State=0x8003 NodeCnt=4 done
[2017-01-01T03:07:18.400] Successfully submit job to queue (job_id: 1220)
[2017-01-01T03:08:41.400] job_complete: JobID=1190 State=0x1 NodeCnt=2 WEXITSTATUS 0
[2017-01-01T03:08:41.400] job_complete: JobID=1190 State=0x8003 NodeCnt=2 done
[2017-01-01T03:09:41.401] job_complete: JobID=1183 State=0x1 NodeCnt=3 WEXITSTATUS 0
[2017-01-01T03:09:41.401] job_complete: JobID=1183 State=0x8003 NodeCnt=3 done
[2017-01-01T03:11:37.409] Successfully submit job to queue (job_id: 1221)
[2017-01-01T03:11:49.410] Successfully submit job to queue (job_id: 1222)
[2017-01-01T03:12:22.410] Successfully submit job to queue (job_id: 1223)
[2017-01-01T03:12:42.410] Successfully submit job to queue (job_id: 1224)
[2017-01-01T03:12:50.410] Successfully submit job to queue (job_id: 1225)
[2017-01-01T03:12:50.410] sched: Allocate JobID=1225 NodeList=b[1-7],m1 #CPUs=96 Partition=normal
[2017-01-01T03:12:50.411] SIM: faking sending message type REQUEST_BATCH_JOB_LAUNCH to localhost

[2017-01-01T03:12:51.411] job_complete: JobID=1225 State=0x1 NodeCnt=8 WEXITSTATUS 0
[2017-01-01T03:12:51.411] job_complete: JobID=1225 State=0x8003 NodeCnt=8 done
[2017-01-01T03:13:24.411] Successfully submit job to queue (job_id: 1226)
[2017-01-01T03:14:00.411] Successfully submit job to queue (job_id: 1227)
[2017-01-01T03:14:46.412] Successfully submit job to queue (job_id: 1228)
[2017-01-01T03:15:04.412] Successfully submit job to queue (job_id: 1229)
[2017-01-01T03:15:04.412] sched: Allocate JobID=1229 NodeList=b[1-7],m1 #CPUs=96 Partition=normal
[2017-01-01T03:15:04.413] SIM: faking sending message type REQUEST_BATCH_JOB_LAUNCH to localhost

[2017-01-01T03:15:59.413] Successfully submit job to queue (job_id: 1230)
[2017-01-01T03:16:25.419] Successfully submit job to queue (job_id: 1231)
[2017-01-01T03:16:26.419] Successfully submit job to queue (job_id: 1232)
[2017-01-01T03:16:26.419] Successfully submit job to queue (job_id: 1233)
[2017-01-01T03:16:52.420] Successfully submit job to queue (job_id: 1234)
[2017-01-01T03:18:56.420] Successfully submit job to queue (job_id: 1235)
[2017-01-01T03:19:14.421] job_complete: JobID=1181 State=0x1 NodeCnt=1 WEXITSTATUS 0
[2017-01-01T03:19:14.421] job_complete: JobID=1181 State=0x8003 NodeCnt=1 done
[2017-01-01T03:19:56.421] job_complete: JobID=1136 State=0x1 NodeCnt=1 WEXITSTATUS 0
[2017-01-01T03:19:56.421] job_complete: JobID=1136 State=0x8003 NodeCnt=1 done
[2017-01-01T03:20:34.422] Successfully submit job to queue (job_id: 1236)
[2017-01-01T03:20:41.422] backfill: Started JobId=1213 in normal on b10,m[2-4]
[2017-01-01T03:20:41.422] SIM: faking sending message type REQUEST_BATCH_JOB_LAUNCH to localhost

[2017-01-01T03:20:41.424] backfill: Started JobId=1228 in normal on g1
[2017-01-01T03:20:41.424] SIM: faking sending message type REQUEST_BATCH_JOB_LAUNCH to localhost

[2017-01-01T03:21:15.426] Successfully submit job to queue (job_id: 1237)
[2017-01-01T03:22:25.428] Successfully submit job to queue (job_id: 1238)
[2017-01-01T03:22:38.428] Successfully submit job to queue (job_id: 1239)
[2017-01-01T03:23:41.429] job_complete: JobID=1228 State=0x1 NodeCnt=1 WEXITSTATUS 0
[2017-01-01T03:23:41.429] job_complete: JobID=1228 State=0x8003 NodeCnt=1 done
[2017-01-01T03:23:48.429] Successfully submit job to queue (job_id: 1240)
[2017-01-01T03:24:11.429] Successfully submit job to queue (job_id: 1241)
[2017-01-01T03:26:43.438] Successfully submit job to queue (job_id: 1242)
[2017-01-01T03:27:41.439] job_complete: JobID=1175 State=0x1 NodeCnt=2 WEXITSTATUS 0
[2017-01-01T03:27:41.439] job_complete: JobID=1175 State=0x8003 NodeCnt=2 done
[2017-01-01T03:27:41.439] job_complete: JobID=1157 State=0x1 NodeCnt=1 WEXITSTATUS 0
[2017-01-01T03:27:41.439] job_complete: JobID=1157 State=0x8003 NodeCnt=1 done
[2017-01-01T03:27:42.439] Successfully submit job to queue (job_id: 1243)
[2017-01-01T03:28:06.439] Successfully submit job to queue (job_id: 1244)
[2017-01-01T03:28:14.439] Successfully submit job to queue (job_id: 1245)
[2017-01-01T03:28:41.439] job_complete: JobID=1167 State=0x1 NodeCnt=1 WEXITSTATUS 0
[2017-01-01T03:28:41.439] job_complete: JobID=1167 State=0x8003 NodeCnt=1 done
[2017-01-01T03:28:57.440] job_complete: JobID=1229 State=0x1 NodeCnt=8 WEXITSTATUS 0
[2017-01-01T03:28:57.440] job_complete: JobID=1229 State=0x8003 NodeCnt=8 done
[2017-01-01T03:29:07.440] job_complete: JobID=1198 State=0x1 NodeCnt=4 WEXITSTATUS 0
[2017-01-01T03:29:07.440] job_complete: JobID=1198 State=0x8003 NodeCnt=4 done
[2017-01-01T03:29:07.440] sched: Allocate JobID=1218 NodeList=n[1-3] #CPUs=36 Partition=normal
[2017-01-01T03:29:07.440] SIM: faking sending message type REQUEST_BATCH_JOB_LAUNCH to localhost

[2017-01-01T03:29:07.440] sched: Allocate JobID=1180 NodeList=n4 #CPUs=12 Partition=normal
[2017-01-01T03:29:07.440] SIM: faking sending message type REQUEST_BATCH_JOB_LAUNCH to localhost

[2017-01-01T03:29:07.440] sched: Allocate JobID=1177 NodeList=m1 #CPUs=6 Partition=normal
[2017-01-01T03:29:07.441] SIM: faking sending message type REQUEST_BATCH_JOB_LAUNCH to localhost

[2017-01-01T03:29:14.441] Successfully submit job to queue (job_id: 1246)
[2017-01-01T03:30:26.441] Successfully submit job to queue (job_id: 1247)
[2017-01-01T03:30:36.442] job_complete: JobID=1213 State=0x1 NodeCnt=4 WEXITSTATUS 0
[2017-01-01T03:30:36.442] job_complete: JobID=1213 State=0x8003 NodeCnt=4 done
[2017-01-01T03:31:32.449] Successfully submit job to queue (job_id: 1248)
[2017-01-01T03:31:38.449] Successfully submit job to queue (job_id: 1249)
[2017-01-01T03:32:01.449] job_complete: JobID=1180 State=0x1 NodeCnt=1 WEXITSTATUS 0
[2017-01-01T03:32:01.449] job_complete: JobID=1180 State=0x8003 NodeCnt=1 done
[2017-01-01T03:32:01.450] sched: Allocate JobID=1195 NodeList=n4 #CPUs=12 Partition=normal
[2017-01-01T03:32:01.450] SIM: faking sending message type REQUEST_BATCH_JOB_LAUNCH to localhost

[2017-01-01T03:32:01.450] sched: Allocate JobID=1164 NodeList=m1 #CPUs=6 Partition=normal
[2017-01-01T03:32:01.450] SIM: faking sending message type REQUEST_BATCH_JOB_LAUNCH to localhost

[2017-01-01T03:32:16.450] Successfully submit job to queue (job_id: 1250)
[2017-01-01T03:33:56.451] Successfully submit job to queue (job_id: 1251)
[2017-01-01T03:34:29.451] Successfully submit job to queue (job_id: 1252)
[2017-01-01T03:34:40.451] job_complete: JobID=1164 State=0x1 NodeCnt=1 WEXITSTATUS 0
[2017-01-01T03:34:40.451] job_complete: JobID=1164 State=0x8003 NodeCnt=1 done
[2017-01-01T03:34:49.452] Successfully submit job to queue (job_id: 1253)
[2017-01-01T03:35:37.452] job_complete: JobID=1177 State=0x1 NodeCnt=1 WEXITSTATUS 0
[2017-01-01T03:35:37.452] job_complete: JobID=1177 State=0x8003 NodeCnt=1 done
[2017-01-01T03:35:51.453] Successfully submit job to queue (job_id: 1254)
[2017-01-01T03:36:20.453] job_complete: JobID=1195 State=0x1 NodeCnt=1 WEXITSTATUS 0
[2017-01-01T03:36:20.453] job_complete: JobID=1195 State=0x8003 NodeCnt=1 done
[2017-01-01T03:36:20.453] sched: Allocate JobID=1077 NodeList=n4 #CPUs=6 Partition=normal
[2017-01-01T03:36:20.453] SIM: faking sending message type REQUEST_BATCH_JOB_LAUNCH to localhost

[2017-01-01T03:36:20.453] sched: Allocate JobID=1193 NodeList=m1 #CPUs=12 Partition=normal
[2017-01-01T03:36:20.453] SIM: faking sending message type REQUEST_BATCH_JOB_LAUNCH to localhost

[2017-01-01T03:36:20.453] sched: Allocate JobID=1119 NodeList=m2 #CPUs=12 Partition=normal
[2017-01-01T03:36:20.454] SIM: faking sending message type REQUEST_BATCH_JOB_LAUNCH to localhost

[2017-01-01T03:36:21.454] job_complete: JobID=1077 State=0x1 NodeCnt=1 WEXITSTATUS 0
[2017-01-01T03:36:21.454] job_complete: JobID=1077 State=0x8003 NodeCnt=1 done
[2017-01-01T03:36:23.454] sched: Allocate JobID=1210 NodeList=n4 #CPUs=12 Partition=normal
[2017-01-01T03:36:23.454] SIM: faking sending message type REQUEST_BATCH_JOB_LAUNCH to localhost

[2017-01-01T03:36:23.454] sched: Allocate JobID=1212 NodeList=m3 #CPUs=1 Partition=normal
[2017-01-01T03:36:23.454] SIM: faking sending message type REQUEST_BATCH_JOB_LAUNCH to localhost

[2017-01-01T03:36:23.454] sched: Allocate JobID=1247 NodeList=b[1-2] #CPUs=24 Partition=normal
[2017-01-01T03:36:23.454] SIM: faking sending message type REQUEST_BATCH_JOB_LAUNCH to localhost

[2017-01-01T03:36:23.454] sched: Allocate JobID=1243 NodeList=m4 #CPUs=12 Partition=normal
[2017-01-01T03:36:23.455] SIM: faking sending message type REQUEST_BATCH_JOB_LAUNCH to localhost

[2017-01-01T03:36:23.455] sched: Allocate JobID=1252 NodeList=b[3-4] #CPUs=24 Partition=normal
[2017-01-01T03:36:23.455] SIM: faking sending message type REQUEST_BATCH_JOB_LAUNCH to localhost

[2017-01-01T03:36:23.455] sched: Allocate JobID=1099 NodeList=m3 #CPUs=6 Partition=normal
[2017-01-01T03:36:23.455] SIM: faking sending message type REQUEST_BATCH_JOB_LAUNCH to localhost

[2017-01-01T03:36:24.455] job_complete: JobID=1099 State=0x1 NodeCnt=1 WEXITSTATUS 0
[2017-01-01T03:36:24.455] job_complete: JobID=1099 State=0x8003 NodeCnt=1 done
[2017-01-01T03:36:37.460] Successfully submit job to queue (job_id: 1255)
[2017-01-01T03:36:53.461] Successfully submit job to queue (job_id: 1256)
[2017-01-01T03:37:29.461] Successfully submit job to queue (job_id: 1257)
[2017-01-01T03:37:37.461] Successfully submit job to queue (job_id: 1258)
[2017-01-01T03:37:42.461] Successfully submit job to queue (job_id: 1259)
[2017-01-01T03:38:50.462] job_complete: JobID=1212 State=0x1 NodeCnt=1 WEXITSTATUS 0
[2017-01-01T03:38:50.462] job_complete: JobID=1212 State=0x8003 NodeCnt=1 done
[2017-01-01T03:40:40.463] Successfully submit job to queue (job_id: 1260)
[2017-01-01T03:40:41.464] backfill: Started JobId=1078 in normal on m3
[2017-01-01T03:40:41.464] SIM: faking sending message type REQUEST_BATCH_JOB_LAUNCH to localhost

[2017-01-01T03:40:41.464] backfill: Started JobId=1112 in normal on g1
[2017-01-01T03:40:41.464] SIM: faking sending message type REQUEST_BATCH_JOB_LAUNCH to localhost

[2017-01-01T03:40:41.464] backfill: Started JobId=1141 in normal on b5
[2017-01-01T03:40:41.464] SIM: faking sending message type REQUEST_BATCH_JOB_LAUNCH to localhost

[2017-01-01T03:40:41.464] backfill: Started JobId=1239 in normal on b6
[2017-01-01T03:40:41.464] SIM: faking sending message type REQUEST_BATCH_JOB_LAUNCH to localhost

[2017-01-01T03:40:41.465] backfill: Started JobId=1147 in normal on b7
[2017-01-01T03:40:41.465] SIM: faking sending message type REQUEST_BATCH_JOB_LAUNCH to localhost

[2017-01-01T03:40:41.465] backfill: Started JobId=1139 in normal on b8
[2017-01-01T03:40:41.465] SIM: faking sending message type REQUEST_BATCH_JOB_LAUNCH to localhost

[2017-01-01T03:40:41.465] backfill: Started JobId=1128 in normal on m3
[2017-01-01T03:40:41.465] SIM: faking sending message type REQUEST_BATCH_JOB_LAUNCH to localhost

[2017-01-01T03:40:41.466] backfill: Started JobId=1165 in normal on b9
[2017-01-01T03:40:41.466] SIM: faking sending message type REQUEST_BATCH_JOB_LAUNCH to localhost

[2017-01-01T03:40:41.466] backfill: Started JobId=1169 in normal on b10
[2017-01-01T03:40:41.467] SIM: faking sending message type REQUEST_BATCH_JOB_LAUNCH to localhost

[2017-01-01T03:40:41.467] backfill: Started JobId=1255 in normal on b6
[2017-01-01T03:40:41.467] SIM: faking sending message type REQUEST_BATCH_JOB_LAUNCH to localhost

[2017-01-01T03:40:41.468] backfill: Started JobId=1258 in normal on g1
[2017-01-01T03:40:41.468] SIM: faking sending message type REQUEST_BATCH_JOB_LAUNCH to localhost

[2017-01-01T03:40:41.469] backfill: Started JobId=1241 in normal on g1
[2017-01-01T03:40:41.469] SIM: faking sending message type REQUEST_BATCH_JOB_LAUNCH to localhost

[2017-01-01T03:40:41.473] backfill: Started JobId=1221 in normal on g1
[2017-01-01T03:40:41.473] SIM: faking sending message type REQUEST_BATCH_JOB_LAUNCH to localhost

[2017-01-01T03:40:42.473] job_complete: JobID=1128 State=0x1 NodeCnt=1 WEXITSTATUS 0
[2017-01-01T03:40:42.473] job_complete: JobID=1128 State=0x8003 NodeCnt=1 done
[2017-01-01T03:41:16.474] job_complete: JobID=1078 State=0x1 NodeCnt=1 WEXITSTATUS 0
[2017-01-01T03:41:16.474] job_complete: JobID=1078 State=0x8003 NodeCnt=1 done
[2017-01-01T03:42:28.475] job_complete: JobID=1258 State=0x1 NodeCnt=1 WEXITSTATUS 0
[2017-01-01T03:42:28.475] job_complete: JobID=1258 State=0x8003 NodeCnt=1 done
[2017-01-01T03:42:58.475] job_complete: JobID=1239 State=0x1 NodeCnt=1 WEXITSTATUS 0
[2017-01-01T03:42:58.475] job_complete: JobID=1239 State=0x8003 NodeCnt=1 done
[2017-01-01T03:43:13.476] job_complete: JobID=1255 State=0x1 NodeCnt=1 WEXITSTATUS 0
[2017-01-01T03:43:13.476] job_complete: JobID=1255 State=0x8003 NodeCnt=1 done
[2017-01-01T03:43:37.476] Successfully submit job to queue (job_id: 1261)
[2017-01-01T03:43:39.476] Successfully submit job to queue (job_id: 1262)
[2017-01-01T03:45:10.477] job_complete: JobID=1221 State=0x1 NodeCnt=1 WEXITSTATUS 0
[2017-01-01T03:45:10.477] job_complete: JobID=1221 State=0x8003 NodeCnt=1 done
[2017-01-01T03:45:17.477] job_complete: JobID=1210 State=0x1 NodeCnt=1 WEXITSTATUS 0
[2017-01-01T03:45:17.477] job_complete: JobID=1210 State=0x8003 NodeCnt=1 done
[2017-01-01T03:45:17.477] sched: Allocate JobID=1109 NodeList=n4 #CPUs=6 Partition=normal
[2017-01-01T03:45:17.477] SIM: faking sending message type REQUEST_BATCH_JOB_LAUNCH to localhost

[2017-01-01T03:45:17.477] sched: Allocate JobID=1114 NodeList=n4 #CPUs=6 Partition=normal
[2017-01-01T03:45:17.478] SIM: faking sending message type REQUEST_BATCH_JOB_LAUNCH to localhost

[2017-01-01T03:45:18.478] job_complete: JobID=1109 State=0x1 NodeCnt=1 WEXITSTATUS 0
[2017-01-01T03:45:18.478] job_complete: JobID=1109 State=0x8003 NodeCnt=1 done
[2017-01-01T03:45:20.478] sched: Allocate JobID=1115 NodeList=n4 #CPUs=6 Partition=normal
[2017-01-01T03:45:20.478] SIM: faking sending message type REQUEST_BATCH_JOB_LAUNCH to localhost

[2017-01-01T03:45:20.478] sched: Allocate JobID=1103 NodeList=m3 #CPUs=12 Partition=normal
[2017-01-01T03:45:20.478] SIM: faking sending message type REQUEST_BATCH_JOB_LAUNCH to localhost

[2017-01-01T03:45:21.478] job_complete: JobID=1115 State=0x1 NodeCnt=1 WEXITSTATUS 0
[2017-01-01T03:45:21.478] job_complete: JobID=1115 State=0x8003 NodeCnt=1 done
[2017-01-01T03:45:55.479] Successfully submit job to queue (job_id: 1263)
[2017-01-01T03:46:34.486] Successfully submit job to queue (job_id: 1264)
[2017-01-01T03:47:07.486] Successfully submit job to queue (job_id: 1265)
[2017-01-01T03:47:26.486] job_complete: JobID=1193 State=0x1 NodeCnt=1 WEXITSTATUS 0
[2017-01-01T03:47:26.487] job_complete: JobID=1193 State=0x8003 NodeCnt=1 done
[2017-01-01T03:48:03.487] Successfully submit job to queue (job_id: 1266)
[2017-01-01T03:48:22.487] Successfully submit job to queue (job_id: 1267)
[2017-01-01T03:49:07.487] job_complete: JobID=1241 State=0x1 NodeCnt=1 WEXITSTATUS 0
[2017-01-01T03:49:07.488] job_complete: JobID=1241 State=0x8003 NodeCnt=1 done
[2017-01-01T03:50:27.488] Successfully submit job to queue (job_id: 1268)
[2017-01-01T03:50:39.489] Successfully submit job to queue (job_id: 1269)
[2017-01-01T03:50:41.489] job_complete: JobID=1139 State=0x1 NodeCnt=1 WEXITSTATUS 0
[2017-01-01T03:50:41.489] job_complete: JobID=1139 State=0x8003 NodeCnt=1 done
[2017-01-01T03:51:11.489] job_complete: JobID=1114 State=0x1 NodeCnt=1 WEXITSTATUS 0
[2017-01-01T03:51:11.489] job_complete: JobID=1114 State=0x8003 NodeCnt=1 done
[2017-01-01T03:51:23.489] Successfully submit job to queue (job_id: 1270)
[2017-01-01T03:51:25.489] job_complete: JobID=1247 State=0x1 NodeCnt=2 WEXITSTATUS 0
[2017-01-01T03:51:25.489] job_complete: JobID=1247 State=0x8003 NodeCnt=2 done
[2017-01-01T03:51:36.497] Successfully submit job to queue (job_id: 1271)
[2017-01-01T03:52:10.497] Successfully submit job to queue (job_id: 1272)
[2017-01-01T03:52:38.497] Successfully submit job to queue (job_id: 1273)
[2017-01-01T03:52:43.498] job_complete: JobID=1119 State=0x1 NodeCnt=1 WEXITSTATUS 0
[2017-01-01T03:52:43.498] job_complete: JobID=1119 State=0x8003 NodeCnt=1 done
[2017-01-01T03:52:58.498] Successfully submit job to queue (job_id: 1274)
[2017-01-01T03:54:00.498] Successfully submit job to queue (job_id: 1275)
[2017-01-01T03:54:06.498] job_complete: JobID=1218 State=0x1 NodeCnt=3 WEXITSTATUS 0
[2017-01-01T03:54:06.499] job_complete: JobID=1218 State=0x8003 NodeCnt=3 done
[2017-01-01T03:54:06.499] sched: Allocate JobID=1266 NodeList=n[1-4] #CPUs=48 Partition=normal
[2017-01-01T03:54:06.499] SIM: faking sending message type REQUEST_BATCH_JOB_LAUNCH to localhost

[2017-01-01T03:54:06.499] sched: Allocate JobID=1273 NodeList=b[1-2,6] #CPUs=36 Partition=normal
[2017-01-01T03:54:06.499] SIM: faking sending message type REQUEST_BATCH_JOB_LAUNCH to localhost

[2017-01-01T03:54:49.499] Successfully submit job to queue (job_id: 1276)
[2017-01-01T03:55:22.500] Successfully submit job to queue (job_id: 1277)
[2017-01-01T03:55:24.500] job_complete: JobID=1252 State=0x1 NodeCnt=2 WEXITSTATUS 0
[2017-01-01T03:55:24.500] job_complete: JobID=1252 State=0x8003 NodeCnt=2 done
[2017-01-01T03:56:31.509] Successfully submit job to queue (job_id: 1278)
[2017-01-01T03:57:23.509] job_complete: JobID=1243 State=0x1 NodeCnt=1 WEXITSTATUS 0
[2017-01-01T03:57:23.509] job_complete: JobID=1243 State=0x8003 NodeCnt=1 done
[2017-01-01T03:57:47.510] Successfully submit job to queue (job_id: 1279)
[2017-01-01T03:58:24.510] Successfully submit job to queue (job_id: 1280)
[2017-01-01T03:58:31.510] Successfully submit job to queue (job_id: 1281)
[2017-01-01T03:58:52.510] Successfully submit job to queue (job_id: 1282)
[2017-01-01T03:59:01.511] Successfully submit job to queue (job_id: 1283)
[2017-01-01T03:59:03.511] Successfully submit job to queue (job_id: 1284)
[2017-01-01T03:59:22.511] Successfully submit job to queue (job_id: 1285)
[2017-01-01T03:59:45.511] Successfully submit job to queue (job_id: 1286)
[2017-01-01T04:00:41.513] backfill: Started JobId=1137 in normal on m1
[2017-01-01T04:00:41.513] SIM: faking sending message type REQUEST_BATCH_JOB_LAUNCH to localhost

[2017-01-01T04:00:41.513] backfill: Started JobId=1168 in normal on m[2,4]
[2017-01-01T04:00:41.513] SIM: faking sending message type REQUEST_BATCH_JOB_LAUNCH to localhost

[2017-01-01T04:00:41.513] backfill: Started JobId=1133 in normal on b3
[2017-01-01T04:00:41.514] SIM: faking sending message type REQUEST_BATCH_JOB_LAUNCH to localhost

[2017-01-01T04:00:41.514] backfill: Started JobId=1166 in normal on b4
[2017-01-01T04:00:41.514] SIM: faking sending message type REQUEST_BATCH_JOB_LAUNCH to localhost

[2017-01-01T04:01:25.520] job_complete: JobID=1166 State=0x1 NodeCnt=1 WEXITSTATUS 0
[2017-01-01T04:01:25.520] job_complete: JobID=1166 State=0x8003 NodeCnt=1 done
[2017-01-01T04:01:49.521] Successfully submit job to queue (job_id: 1287)
[2017-01-01T04:03:03.522] job_complete: JobID=1103 State=0x1 NodeCnt=1 WEXITSTATUS 0
[2017-01-01T04:03:03.522] job_complete: JobID=1103 State=0x8003 NodeCnt=1 done
[2017-01-01T04:03:18.522] job_complete: JobID=1165 State=0x1 NodeCnt=1 WEXITSTATUS 0
[2017-01-01T04:03:18.522] job_complete: JobID=1165 State=0x8003 NodeCnt=1 done
[2017-01-01T04:03:46.522] Successfully submit job to queue (job_id: 1288)
[2017-01-01T04:03:52.522] Successfully submit job to queue (job_id: 1289)
[2017-01-01T04:04:30.523] Successfully submit job to queue (job_id: 1290)
[2017-01-01T04:04:41.523] job_complete: JobID=1147 State=0x1 NodeCnt=1 WEXITSTATUS 0
[2017-01-01T04:04:41.523] job_complete: JobID=1147 State=0x8003 NodeCnt=1 done
[2017-01-01T04:05:56.524] job_complete: JobID=1133 State=0x1 NodeCnt=1 WEXITSTATUS 0
[2017-01-01T04:05:56.524] job_complete: JobID=1133 State=0x8003 NodeCnt=1 done
[2017-01-01T04:06:20.524] Successfully submit job to queue (job_id: 1291)
[2017-01-01T04:06:22.524] Successfully submit job to queue (job_id: 1292)
[2017-01-01T04:07:16.531] job_complete: JobID=1112 State=0x1 NodeCnt=1 WEXITSTATUS 0
[2017-01-01T04:07:16.531] job_complete: JobID=1112 State=0x8003 NodeCnt=1 done
[2017-01-01T04:07:30.531] Successfully submit job to queue (job_id: 1293)
[2017-01-01T04:07:41.531] job_complete: JobID=1169 State=0x1 NodeCnt=1 WEXITSTATUS 0
[2017-01-01T04:07:41.531] job_complete: JobID=1169 State=0x8003 NodeCnt=1 done
[2017-01-01T04:08:20.532] Successfully submit job to queue (job_id: 1294)
[2017-01-01T04:08:21.532] Successfully submit job to queue (job_id: 1295)
[2017-01-01T04:09:24.532] Successfully submit job to queue (job_id: 1296)
[2017-01-01T04:09:41.532] job_complete: JobID=1141 State=0x1 NodeCnt=1 WEXITSTATUS 0
[2017-01-01T04:09:41.532] job_complete: JobID=1141 State=0x8003 NodeCnt=1 done
[2017-01-01T04:10:17.533] Successfully submit job to queue (job_id: 1297)
[2017-01-01T04:10:38.533] Successfully submit job to queue (job_id: 1298)
[2017-01-01T04:11:20.534] job_complete: JobID=1168 State=0x1 NodeCnt=2 WEXITSTATUS 0
[2017-01-01T04:11:20.534] job_complete: JobID=1168 State=0x8003 NodeCnt=2 done
[2017-01-01T04:12:41.540] Successfully submit job to queue (job_id: 1299)
[2017-01-01T04:13:06.540] job_complete: JobID=1273 State=0x1 NodeCnt=3 WEXITSTATUS 0
[2017-01-01T04:13:06.540] job_complete: JobID=1273 State=0x8003 NodeCnt=3 done
[2017-01-01T04:13:44.541] Successfully submit job to queue (job_id: 1300)
[2017-01-01T04:13:53.541] Successfully submit job to queue (job_id: 1301)
[2017-01-01T04:14:00.541] Successfully submit job to queue (job_id: 1302)
[2017-01-01T04:15:23.542] Successfully submit job to queue (job_id: 1303)
[2017-01-01T04:16:26.543] Successfully submit job to queue (job_id: 1304)
[2017-01-01T04:16:42.548] Successfully submit job to queue (job_id: 1305)
[2017-01-01T04:17:35.549] Successfully submit job to queue (job_id: 1306)
[2017-01-01T04:17:36.549] Successfully submit job to queue (job_id: 1307)
[2017-01-01T04:17:39.549] Successfully submit job to queue (job_id: 1308)
[2017-01-01T04:17:43.549] Successfully submit job to queue (job_id: 1309)
[2017-01-01T04:18:21.550] job_complete: JobID=1266 State=0x1 NodeCnt=4 WEXITSTATUS 0
[2017-01-01T04:18:21.550] job_complete: JobID=1266 State=0x8003 NodeCnt=4 done
[2017-01-01T04:18:21.550] sched: Allocate JobID=1170 NodeList=n[1-2] #CPUs=24 Partition=normal
[2017-01-01T04:18:21.550] SIM: faking sending message type REQUEST_BATCH_JOB_LAUNCH to localhost

[2017-01-01T04:18:21.550] sched: Allocate JobID=1105 NodeList=g1 #CPUs=1 Partition=normal
[2017-01-01T04:18:21.550] SIM: faking sending message type REQUEST_BATCH_JOB_LAUNCH to localhost

[2017-01-01T04:18:21.550] sched: Allocate JobID=1106 NodeList=g1 #CPUs=1 Partition=normal
[2017-01-01T04:18:21.550] SIM: faking sending message type REQUEST_BATCH_JOB_LAUNCH to localhost

[2017-01-01T04:18:21.550] sched: Allocate JobID=1307 NodeList=b[1-4] #CPUs=48 Partition=normal
[2017-01-01T04:18:21.551] SIM: faking sending message type REQUEST_BATCH_JOB_LAUNCH to localhost

[2017-01-01T04:18:21.551] sched: Allocate JobID=1188 NodeList=n[3-4] #CPUs=24 Partition=normal
[2017-01-01T04:18:21.551] SIM: faking sending message type REQUEST_BATCH_JOB_LAUNCH to localhost

[2017-01-01T04:18:22.551] job_complete: JobID=1106 State=0x1 NodeCnt=1 WEXITSTATUS 0
[2017-01-01T04:18:22.551] job_complete: JobID=1106 State=0x8003 NodeCnt=1 done
[2017-01-01T04:18:27.551] Successfully submit job to queue (job_id: 1310)
[2017-01-01T04:19:03.552] job_complete: JobID=1307 State=0x1 NodeCnt=4 WEXITSTATUS 0
[2017-01-01T04:19:03.552] job_complete: JobID=1307 State=0x8003 NodeCnt=4 done
[2017-01-01T04:19:46.552] Successfully submit job to queue (job_id: 1311)
[2017-01-01T04:20:07.553] Successfully submit job to queue (job_id: 1312)
[2017-01-01T04:20:41.553] backfill: Started JobId=1155 in normal on m2
[2017-01-01T04:20:41.554] SIM: faking sending message type REQUEST_BATCH_JOB_LAUNCH to localhost

[2017-01-01T04:20:41.554] backfill: Started JobId=1209 in normal on m[3-4]
[2017-01-01T04:20:41.554] SIM: faking sending message type REQUEST_BATCH_JOB_LAUNCH to localhost

[2017-01-01T04:20:41.554] backfill: Started JobId=1145 in normal on b1
[2017-01-01T04:20:41.554] SIM: faking sending message type REQUEST_BATCH_JOB_LAUNCH to localhost

[2017-01-01T04:20:41.554] backfill: Started JobId=1194 in normal on b[2-3]
[2017-01-01T04:20:41.555] SIM: faking sending message type REQUEST_BATCH_JOB_LAUNCH to localhost

[2017-01-01T04:20:41.555] backfill: Started JobId=1154 in normal on b4
[2017-01-01T04:20:41.555] SIM: faking sending message type REQUEST_BATCH_JOB_LAUNCH to localhost

[2017-01-01T04:20:41.555] backfill: Started JobId=1135 in normal on b5
[2017-01-01T04:20:41.555] SIM: faking sending message type REQUEST_BATCH_JOB_LAUNCH to localhost

[2017-01-01T04:20:41.555] backfill: Started JobId=1159 in normal on b6
[2017-01-01T04:20:41.555] SIM: faking sending message type REQUEST_BATCH_JOB_LAUNCH to localhost

[2017-01-01T04:20:41.555] backfill: Started JobId=1197 in normal on g1
[2017-01-01T04:20:41.556] SIM: faking sending message type REQUEST_BATCH_JOB_LAUNCH to localhost

[2017-01-01T04:20:41.556] backfill: Started JobId=1267 in normal on b7
[2017-01-01T04:20:41.556] SIM: faking sending message type REQUEST_BATCH_JOB_LAUNCH to localhost

[2017-01-01T04:20:41.556] backfill: Started JobId=1211 in normal on b[8-9]
[2017-01-01T04:20:41.556] SIM: faking sending message type REQUEST_BATCH_JOB_LAUNCH to localhost

[2017-01-01T04:20:41.556] backfill: Started JobId=1176 in normal on b10
[2017-01-01T04:20:41.556] SIM: faking sending message type REQUEST_BATCH_JOB_LAUNCH to localhost

[2017-01-01T04:20:41.558] backfill: Started JobId=1161 in normal on b5
[2017-01-01T04:20:41.558] SIM: faking sending message type REQUEST_BATCH_JOB_LAUNCH to localhost

[2017-01-01T04:20:41.561] backfill: Started JobId=1236 in normal on b5
[2017-01-01T04:20:41.561] SIM: faking sending message type REQUEST_BATCH_JOB_LAUNCH to localhost

[2017-01-01T04:20:41.562] backfill: Started JobId=1288 in normal on b5
[2017-01-01T04:20:41.562] SIM: faking sending message type REQUEST_BATCH_JOB_LAUNCH to localhost

[2017-01-01T04:20:41.564] backfill: Started JobId=1279 in normal on b5
[2017-01-01T04:20:41.564] SIM: faking sending message type REQUEST_BATCH_JOB_LAUNCH to localhost

[2017-01-01T04:21:36.566] job_complete: JobID=1135 State=0x1 NodeCnt=1 WEXITSTATUS 0
[2017-01-01T04:21:36.566] job_complete: JobID=1135 State=0x8003 NodeCnt=1 done
[2017-01-01T04:21:37.567] job_complete: JobID=1137 State=0x1 NodeCnt=1 WEXITSTATUS 0
[2017-01-01T04:21:37.567] job_complete: JobID=1137 State=0x8003 NodeCnt=1 done
[2017-01-01T04:21:38.567] job_complete: JobID=1211 State=0x1 NodeCnt=2 WEXITSTATUS 0
[2017-01-01T04:21:38.567] job_complete: JobID=1211 State=0x8003 NodeCnt=2 done
[2017-01-01T04:22:04.567] job_complete: JobID=1176 State=0x1 NodeCnt=1 WEXITSTATUS 0
[2017-01-01T04:22:04.567] job_complete: JobID=1176 State=0x8003 NodeCnt=1 done
[2017-01-01T04:22:21.567] Successfully submit job to queue (job_id: 1313)
[2017-01-01T04:22:27.568] job_complete: JobID=1154 State=0x1 NodeCnt=1 WEXITSTATUS 0
[2017-01-01T04:22:27.568] job_complete: JobID=1154 State=0x8003 NodeCnt=1 done
[2017-01-01T04:22:34.568] job_complete: JobID=1159 State=0x1 NodeCnt=1 WEXITSTATUS 0
[2017-01-01T04:22:34.568] job_complete: JobID=1159 State=0x8003 NodeCnt=1 done
[2017-01-01T04:22:48.568] job_complete: JobID=1170 State=0x1 NodeCnt=2 WEXITSTATUS 0
[2017-01-01T04:22:48.568] job_complete: JobID=1170 State=0x8003 NodeCnt=2 done
[2017-01-01T04:23:08.569] Successfully submit job to queue (job_id: 1314)
[2017-01-01T04:23:08.569] sched: Allocate JobID=1314 NodeList=b[4,6,8-10],m1,n[1-2] #CPUs=96 Partition=normal
[2017-01-01T04:23:08.569] SIM: faking sending message type REQUEST_BATCH_JOB_LAUNCH to localhost

[2017-01-01T04:23:42.569] Successfully submit job to queue (job_id: 1315)
[2017-01-01T04:23:52.569] Successfully submit job to queue (job_id: 1316)
[2017-01-01T04:24:20.570] job_complete: JobID=1279 State=0x1 NodeCnt=1 WEXITSTATUS 0
[2017-01-01T04:24:20.570] job_complete: JobID=1279 State=0x8003 NodeCnt=1 done
[2017-01-01T04:24:33.570] Successfully submit job to queue (job_id: 1317)
[2017-01-01T04:24:39.570] job_complete: JobID=1197 State=0x1 NodeCnt=1 WEXITSTATUS 0
[2017-01-01T04:24:39.570] job_complete: JobID=1197 State=0x8003 NodeCnt=1 done
[2017-01-01T04:25:32.571] job_complete: JobID=1267 State=0x1 NodeCnt=1 WEXITSTATUS 0
[2017-01-01T04:25:32.571] job_complete: JobID=1267 State=0x8003 NodeCnt=1 done
[2017-01-01T04:25:52.572] Successfully submit job to queue (job_id: 1318)
[2017-01-01T04:26:48.576] job_complete: JobID=1188 State=0x1 NodeCnt=2 WEXITSTATUS 0
[2017-01-01T04:26:48.576] job_complete: JobID=1188 State=0x8003 NodeCnt=2 done
[2017-01-01T04:27:07.577] job_complete: JobID=1194 State=0x1 NodeCnt=2 WEXITSTATUS 0
[2017-01-01T04:27:07.577] job_complete: JobID=1194 State=0x8003 NodeCnt=2 done
[2017-01-01T04:27:36.577] job_complete: JobID=1209 State=0x1 NodeCnt=2 WEXITSTATUS 0
[2017-01-01T04:27:36.577] job_complete: JobID=1209 State=0x8003 NodeCnt=2 done
[2017-01-01T04:27:37.577] Successfully submit job to queue (job_id: 1319)
[2017-01-01T04:28:04.578] Successfully submit job to queue (job_id: 1320)
[2017-01-01T04:28:38.578] Successfully submit job to queue (job_id: 1321)
[2017-01-01T04:29:53.579] Successfully submit job to queue (job_id: 1322)
[2017-01-01T04:30:16.580] Successfully submit job to queue (job_id: 1323)
[2017-01-01T04:30:19.580] Successfully submit job to queue (job_id: 1324)
[2017-01-01T04:31:03.580] Successfully submit job to queue (job_id: 1325)
[2017-01-01T04:31:45.585] job_complete: JobID=1288 State=0x1 NodeCnt=1 WEXITSTATUS 0
[2017-01-01T04:31:45.585] job_complete: JobID=1288 State=0x8003 NodeCnt=1 done
[2017-01-01T04:32:19.585] Successfully submit job to queue (job_id: 1326)
[2017-01-01T04:33:04.586] job_complete: JobID=1145 State=0x1 NodeCnt=1 WEXITSTATUS 0
[2017-01-01T04:33:04.586] job_complete: JobID=1145 State=0x8003 NodeCnt=1 done
[2017-01-01T04:33:25.586] job_complete: JobID=1314 State=0x1 NodeCnt=8 WEXITSTATUS 0
[2017-01-01T04:33:25.586] job_complete: JobID=1314 State=0x8003 NodeCnt=8 done
[2017-01-01T04:33:57.587] job_complete: JobID=1155 State=0x1 NodeCnt=1 WEXITSTATUS 0
[2017-01-01T04:33:57.587] job_complete: JobID=1155 State=0x8003 NodeCnt=1 done
[2017-01-01T04:33:59.587] Successfully submit job to queue (job_id: 1327)
[2017-01-01T04:34:46.587] Successfully submit job to queue (job_id: 1328)
[2017-01-01T04:35:05.588] Successfully submit job to queue (job_id: 1329)
[2017-01-01T04:35:09.588] Successfully submit job to queue (job_id: 1330)
[2017-01-01T04:36:41.594] sched: Allocate JobID=1274 NodeList=n[1-2] #CPUs=24 Partition=normal
[2017-01-01T04:36:41.594] SIM: faking sending message type REQUEST_BATCH_JOB_LAUNCH to localhost

[2017-01-01T04:37:06.594] Successfully submit job to queue (job_id: 1331)
[2017-01-01T04:37:45.594] Successfully submit job to queue (job_id: 1332)
[2017-01-01T04:38:19.595] Successfully submit job to queue (job_id: 1333)
[2017-01-01T04:39:37.595] Successfully submit job to queue (job_id: 1334)
[2017-01-01T04:39:38.596] Successfully submit job to queue (job_id: 1335)
[2017-01-01T04:39:57.596] job_complete: JobID=1274 State=0x1 NodeCnt=2 WEXITSTATUS 0
[2017-01-01T04:39:57.596] job_complete: JobID=1274 State=0x8003 NodeCnt=2 done
[2017-01-01T04:39:58.596] job_complete: JobID=1105 State=0x1 NodeCnt=1 WEXITSTATUS 0
[2017-01-01T04:39:58.596] job_complete: JobID=1105 State=0x8003 NodeCnt=1 done
[2017-01-01T04:40:00.596] sched: Allocate JobID=1121 NodeList=g1 #CPUs=12 Partition=normal
[2017-01-01T04:40:00.597] SIM: faking sending message type REQUEST_BATCH_JOB_LAUNCH to localhost

[2017-01-01T04:40:00.597] sched: Allocate JobID=1093 NodeList=n1 #CPUs=1 Partition=normal
[2017-01-01T04:40:00.597] SIM: faking sending message type REQUEST_BATCH_JOB_LAUNCH to localhost

[2017-01-01T04:40:00.597] sched: Allocate JobID=1320 NodeList=n[2-4] #CPUs=36 Partition=normal
[2017-01-01T04:40:00.597] SIM: faking sending message type REQUEST_BATCH_JOB_LAUNCH to localhost

[2017-01-01T04:40:00.597] sched: Allocate JobID=1095 NodeList=n1 #CPUs=1 Partition=normal
[2017-01-01T04:40:00.597] SIM: faking sending message type REQUEST_BATCH_JOB_LAUNCH to localhost

[2017-01-01T04:40:41.598] backfill: Started JobId=1253 in normal on m[1-4]
[2017-01-01T04:40:41.598] SIM: faking sending message type REQUEST_BATCH_JOB_LAUNCH to localhost

[2017-01-01T04:40:41.598] backfill: Started JobId=1142 in normal on n1
[2017-01-01T04:40:41.598] SIM: faking sending message type REQUEST_BATCH_JOB_LAUNCH to localhost

[2017-01-01T04:40:41.599] backfill: Started JobId=1143 in normal on n1
[2017-01-01T04:40:41.599] SIM: faking sending message type REQUEST_BATCH_JOB_LAUNCH to localhost

[2017-01-01T04:40:41.599] backfill: Started JobId=1204 in normal on n1
[2017-01-01T04:40:41.599] SIM: faking sending message type REQUEST_BATCH_JOB_LAUNCH to localhost

[2017-01-01T04:40:41.599] backfill: Started JobId=1262 in normal on b1
[2017-01-01T04:40:41.599] SIM: faking sending message type REQUEST_BATCH_JOB_LAUNCH to localhost

[2017-01-01T04:40:41.600] backfill: Started JobId=1289 in normal on b2
[2017-01-01T04:40:41.600] SIM: faking sending message type REQUEST_BATCH_JOB_LAUNCH to localhost

[2017-01-01T04:40:41.600] backfill: Started JobId=1152 in normal on n1
[2017-01-01T04:40:41.600] SIM: faking sending message type REQUEST_BATCH_JOB_LAUNCH to localhost

[2017-01-01T04:40:41.600] backfill: Started JobId=1144 in normal on b3
[2017-01-01T04:40:41.600] SIM: faking sending message type REQUEST_BATCH_JOB_LAUNCH to localhost

[2017-01-01T04:40:41.600] backfill: Started JobId=1149 in normal on n1
[2017-01-01T04:40:41.601] SIM: faking sending message type REQUEST_BATCH_JOB_LAUNCH to localhost

[2017-01-01T04:40:41.601] backfill: Started JobId=1290 in normal on b[4,6-7]
[2017-01-01T04:40:41.601] SIM: faking sending message type REQUEST_BATCH_JOB_LAUNCH to localhost

[2017-01-01T04:40:41.601] backfill: Started JobId=1232 in normal on b[8-9]
[2017-01-01T04:40:41.601] SIM: faking sending message type REQUEST_BATCH_JOB_LAUNCH to localhost

[2017-01-01T04:40:41.601] backfill: Started JobId=1219 in normal on b10
[2017-01-01T04:40:41.601] SIM: faking sending message type REQUEST_BATCH_JOB_LAUNCH to localhost

[2017-01-01T04:40:41.604] backfill: Started JobId=1317 in normal on b5
[2017-01-01T04:40:41.604] SIM: faking sending message type REQUEST_BATCH_JOB_LAUNCH to localhost

[2017-01-01T04:40:41.608] backfill: Started JobId=1332 in normal on b1
[2017-01-01T04:40:41.608] SIM: faking sending message type REQUEST_BATCH_JOB_LAUNCH to localhost

[2017-01-01T04:40:42.608] job_complete: JobID=1142 State=0x1 NodeCnt=1 WEXITSTATUS 0
[2017-01-01T04:40:42.608] job_complete: JobID=1142 State=0x8003 NodeCnt=1 done
[2017-01-01T04:40:42.608] job_complete: JobID=1219 State=0x1 NodeCnt=1 WEXITSTATUS 0
[2017-01-01T04:40:42.609] job_complete: JobID=1219 State=0x8003 NodeCnt=1 done
[2017-01-01T04:40:42.609] job_complete: JobID=1204 State=0x1 NodeCnt=1 WEXITSTATUS 0
[2017-01-01T04:40:42.609] job_complete: JobID=1204 State=0x8003 NodeCnt=1 done
[2017-01-01T04:41:27.609] Successfully submit job to queue (job_id: 1336)
[2017-01-01T04:41:28.609] job_complete: JobID=1332 State=0x1 NodeCnt=1 WEXITSTATUS 0
[2017-01-01T04:41:28.609] job_complete: JobID=1332 State=0x8003 NodeCnt=1 done
[2017-01-01T04:43:21.611] job_complete: JobID=1232 State=0x1 NodeCnt=2 WEXITSTATUS 0
[2017-01-01T04:43:21.611] job_complete: JobID=1232 State=0x8003 NodeCnt=2 done
[2017-01-01T04:43:40.611] job_complete: JobID=1262 State=0x1 NodeCnt=1 WEXITSTATUS 0
[2017-01-01T04:43:40.611] job_complete: JobID=1262 State=0x8003 NodeCnt=1 done
[2017-01-01T04:43:47.612] job_complete: JobID=1095 State=0x1 NodeCnt=1 WEXITSTATUS 0
[2017-01-01T04:43:47.612] job_complete: JobID=1095 State=0x8003 NodeCnt=1 done
[2017-01-01T04:44:52.612] Successfully submit job to queue (job_id: 1337)
[2017-01-01T04:45:00.612] job_complete: JobID=1143 State=0x1 NodeCnt=1 WEXITSTATUS 0
[2017-01-01T04:45:00.612] job_complete: JobID=1143 State=0x8003 NodeCnt=1 done
[2017-01-01T04:45:40.613] Successfully submit job to queue (job_id: 1338)
[2017-01-01T04:46:20.614] job_complete: JobID=1161 State=0x1 NodeCnt=1 WEXITSTATUS 0
[2017-01-01T04:46:20.614] job_complete: JobID=1161 State=0x8003 NodeCnt=1 done
[2017-01-01T04:46:29.614] Successfully submit job to queue (job_id: 1339)
[2017-01-01T04:47:00.619] Successfully submit job to queue (job_id: 1340)
[2017-01-01T04:47:00.619] job_complete: JobID=1236 State=0x1 NodeCnt=1 WEXITSTATUS 0
[2017-01-01T04:47:00.620] job_complete: JobID=1236 State=0x8003 NodeCnt=1 done
[2017-01-01T04:47:20.620] job_complete: JobID=1317 State=0x1 NodeCnt=1 WEXITSTATUS 0
[2017-01-01T04:47:20.620] job_complete: JobID=1317 State=0x8003 NodeCnt=1 done
[2017-01-01T04:47:25.620] job_complete: JobID=1093 State=0x1 NodeCnt=1 WEXITSTATUS 0
[2017-01-01T04:47:25.620] job_complete: JobID=1093 State=0x8003 NodeCnt=1 done
[2017-01-01T04:47:42.620] Successfully submit job to queue (job_id: 1341)
[2017-01-01T04:48:14.621] Successfully submit job to queue (job_id: 1342)
[2017-01-01T04:49:05.621] job_complete: JobID=1152 State=0x1 NodeCnt=1 WEXITSTATUS 0
[2017-01-01T04:49:05.621] job_complete: JobID=1152 State=0x8003 NodeCnt=1 done
[2017-01-01T04:49:48.622] Successfully submit job to queue (job_id: 1343)
[2017-01-01T04:50:44.623] job_complete: JobID=1144 State=0x1 NodeCnt=1 WEXITSTATUS 0
[2017-01-01T04:50:44.623] job_complete: JobID=1144 State=0x8003 NodeCnt=1 done
[2017-01-01T04:51:47.628] Successfully submit job to queue (job_id: 1344)
[2017-01-01T04:52:23.629] Successfully submit job to queue (job_id: 1345)
[2017-01-01T04:52:41.629] job_complete: JobID=1149 State=0x1 NodeCnt=1 WEXITSTATUS 0
[2017-01-01T04:52:41.629] job_complete: JobID=1149 State=0x8003 NodeCnt=1 done
[2017-01-01T04:52:43.629] job_complete: JobID=1320 State=0x1 NodeCnt=3 WEXITSTATUS 0
[2017-01-01T04:52:43.629] job_complete: JobID=1320 State=0x8003 NodeCnt=3 done
[2017-01-01T04:53:18.629] Successfully submit job to queue (job_id: 1346)
[2017-01-01T04:53:28.630] Successfully submit job to queue (job_id: 1347)
[2017-01-01T04:55:01.630] Successfully submit job to queue (job_id: 1348)
[2017-01-01T04:55:19.631] Successfully submit job to queue (job_id: 1349)
[2017-01-01T04:55:40.631] Successfully submit job to queue (job_id: 1350)
[2017-01-01T04:55:46.632] Successfully submit job to queue (job_id: 1351)
[2017-01-01T04:58:32.638] Successfully submit job to queue (job_id: 1352)
[2017-01-01T04:58:32.638] sched: Allocate JobID=1352 NodeList=b[1,3,5,8-10],n[1-2] #CPUs=96 Partition=normal
[2017-01-01T04:58:32.638] SIM: faking sending message type REQUEST_BATCH_JOB_LAUNCH to localhost

[2017-01-01T04:58:39.638] Successfully submit job to queue (job_id: 1353)
[2017-01-01T04:58:49.639] Successfully submit job to queue (job_id: 1354)
[2017-01-01T04:59:06.639] Successfully submit job to queue (job_id: 1355)
[2017-01-01T04:59:07.639] job_complete: JobID=1290 State=0x1 NodeCnt=3 WEXITSTATUS 0
[2017-01-01T04:59:07.639] job_complete: JobID=1290 State=0x8003 NodeCnt=3 done
[2017-01-01T05:00:16.640] Successfully submit job to queue (job_id: 1356)
[2017-01-01T05:00:41.641] backfill: Started JobId=1186 in normal on n4
[2017-01-01T05:00:41.641] SIM: faking sending message type REQUEST_BATCH_JOB_LAUNCH to localhost

[2017-01-01T05:02:07.648] job_complete: JobID=1352 State=0x1 NodeCnt=8 WEXITSTATUS 0
[2017-01-01T05:02:07.648] job_complete: JobID=1352 State=0x8003 NodeCnt=8 done
[2017-01-01T05:02:07.648] sched: Allocate JobID=1355 NodeList=b[1,3-9] #CPUs=96 Partition=normal
[2017-01-01T05:02:07.648] SIM: faking sending message type REQUEST_BATCH_JOB_LAUNCH to localhost

[2017-01-01T05:02:33.648] Successfully submit job to queue (job_id: 1357)
[2017-01-01T05:02:52.648] Successfully submit job to queue (job_id: 1358)
[2017-01-01T05:02:59.649] Successfully submit job to queue (job_id: 1359)
[2017-01-01T05:03:09.649] Successfully submit job to queue (job_id: 1360)
[2017-01-01T05:03:27.649] Successfully submit job to queue (job_id: 1361)
[2017-01-01T05:03:41.649] job_complete: JobID=1289 State=0x1 NodeCnt=1 WEXITSTATUS 0
[2017-01-01T05:03:41.649] job_complete: JobID=1289 State=0x8003 NodeCnt=1 done
[2017-01-01T05:03:41.649] job_complete: JobID=1253 State=0x1 NodeCnt=4 WEXITSTATUS 0
[2017-01-01T05:03:41.649] job_complete: JobID=1253 State=0x8003 NodeCnt=4 done
[2017-01-01T05:04:11.650] Successfully submit job to queue (job_id: 1362)
[2017-01-01T05:04:21.650] Successfully submit job to queue (job_id: 1363)
[2017-01-01T05:08:16.657] Successfully submit job to queue (job_id: 1364)
[2017-01-01T05:08:53.657] Successfully submit job to queue (job_id: 1365)
[2017-01-01T05:09:00.658] job_complete: JobID=1121 State=0x1 NodeCnt=1 WEXITSTATUS 0
[2017-01-01T05:09:00.658] job_complete: JobID=1121 State=0x8003 NodeCnt=1 done
[2017-01-01T05:09:00.658] sched: Allocate JobID=1150 NodeList=g1 #CPUs=12 Partition=normal
[2017-01-01T05:09:00.658] SIM: faking sending message type REQUEST_BATCH_JOB_LAUNCH to localhost

[2017-01-01T05:09:00.658] sched: Allocate JobID=1215 NodeList=n[1-3] #CPUs=36 Partition=normal
[2017-01-01T05:09:00.658] SIM: faking sending message type REQUEST_BATCH_JOB_LAUNCH to localhost

[2017-01-01T05:09:00.658] sched: Allocate JobID=1187 NodeList=m[1-2] #CPUs=24 Partition=normal
[2017-01-01T05:09:00.658] SIM: faking sending message type REQUEST_BATCH_JOB_LAUNCH to localhost

[2017-01-01T05:09:32.659] Successfully submit job to queue (job_id: 1366)
[2017-01-01T05:09:37.659] Successfully submit job to queue (job_id: 1367)
[2017-01-01T05:11:22.660] Successfully submit job to queue (job_id: 1368)
[2017-01-01T05:11:30.660] Successfully submit job to queue (job_id: 1369)
[2017-01-01T05:11:36.660] Successfully submit job to queue (job_id: 1370)
[2017-01-01T05:12:17.665] job_complete: JobID=1150 State=0x1 NodeCnt=1 WEXITSTATUS 0
[2017-01-01T05:12:17.665] job_complete: JobID=1150 State=0x8003 NodeCnt=1 done
[2017-01-01T05:12:57.666] Successfully submit job to queue (job_id: 1371)
[2017-01-01T05:13:00.666] Successfully submit job to queue (job_id: 1372)
[2017-01-01T05:13:46.667] job_complete: JobID=1187 State=0x1 NodeCnt=2 WEXITSTATUS 0
[2017-01-01T05:13:46.667] job_complete: JobID=1187 State=0x8003 NodeCnt=2 done
[2017-01-01T05:13:52.667] Successfully submit job to queue (job_id: 1373)
[2017-01-01T05:14:15.667] Successfully submit job to queue (job_id: 1374)
[2017-01-01T05:14:57.668] Successfully submit job to queue (job_id: 1375)
[2017-01-01T05:15:55.669] Successfully submit job to queue (job_id: 1376)
[2017-01-01T05:16:10.669] Successfully submit job to queue (job_id: 1377)
[2017-01-01T05:16:57.674] Successfully submit job to queue (job_id: 1378)
[2017-01-01T05:16:57.674] sched: Allocate JobID=1327 NodeList=m[1-3] #CPUs=36 Partition=normal
[2017-01-01T05:16:57.674] SIM: faking sending message type REQUEST_BATCH_JOB_LAUNCH to localhost

[2017-01-01T05:16:57.675] sched: Allocate JobID=1245 NodeList=g1 #CPUs=2 Partition=normal
[2017-01-01T05:16:57.675] SIM: faking sending message type REQUEST_BATCH_JOB_LAUNCH to localhost

[2017-01-01T05:17:01.675] Successfully submit job to queue (job_id: 1379)
[2017-01-01T05:18:10.675] Successfully submit job to queue (job_id: 1380)
[2017-01-01T05:18:48.676] job_complete: JobID=1355 State=0x1 NodeCnt=8 WEXITSTATUS 0
[2017-01-01T05:18:48.676] job_complete: JobID=1355 State=0x8003 NodeCnt=8 done
[2017-01-01T05:19:24.676] Successfully submit job to queue (job_id: 1381)
[2017-01-01T05:19:49.677] Successfully submit job to queue (job_id: 1382)
[2017-01-01T05:19:56.677] job_complete: JobID=1245 State=0x1 NodeCnt=1 WEXITSTATUS 0
[2017-01-01T05:19:56.677] job_complete: JobID=1245 State=0x8003 NodeCnt=1 done
[2017-01-01T05:20:37.678] Successfully submit job to queue (job_id: 1383)
[2017-01-01T05:20:37.678] sched: Allocate JobID=1383 NodeList=b[1-8] #CPUs=96 Partition=normal
[2017-01-01T05:20:37.678] SIM: faking sending message type REQUEST_BATCH_JOB_LAUNCH to localhost

[2017-01-01T05:20:41.678] backfill: Started JobId=1185 in normal on m4
[2017-01-01T05:20:41.679] SIM: faking sending message type REQUEST_BATCH_JOB_LAUNCH to localhost

[2017-01-01T05:20:41.679] backfill: Started JobId=1163 in normal on g1
[2017-01-01T05:20:41.679] SIM: faking sending message type REQUEST_BATCH_JOB_LAUNCH to localhost

[2017-01-01T05:20:41.680] backfill: Started JobId=1287 in normal on b10
[2017-01-01T05:20:41.680] SIM: faking sending message type REQUEST_BATCH_JOB_LAUNCH to localhost

[2017-01-01T05:20:41.680] backfill: Started JobId=1315 in normal on b9
[2017-01-01T05:20:41.680] SIM: faking sending message type REQUEST_BATCH_JOB_LAUNCH to localhost

[2017-01-01T05:20:41.684] backfill: Started JobId=1331 in normal on g1
[2017-01-01T05:20:41.684] SIM: faking sending message type REQUEST_BATCH_JOB_LAUNCH to localhost

[2017-01-01T05:20:41.686] backfill: Started JobId=1356 in normal on g1
[2017-01-01T05:20:41.686] SIM: faking sending message type REQUEST_BATCH_JOB_LAUNCH to localhost

[2017-01-01T05:20:41.689] backfill: Started JobId=1358 in normal on g1
[2017-01-01T05:20:41.689] SIM: faking sending message type REQUEST_BATCH_JOB_LAUNCH to localhost

[2017-01-01T05:20:42.689] job_complete: JobID=1185 State=0x1 NodeCnt=1 WEXITSTATUS 0
[2017-01-01T05:20:42.689] job_complete: JobID=1185 State=0x8003 NodeCnt=1 done
[2017-01-01T05:20:42.689] job_complete: JobID=1163 State=0x1 NodeCnt=1 WEXITSTATUS 0
[2017-01-01T05:20:42.689] job_complete: JobID=1163 State=0x8003 NodeCnt=1 done
[2017-01-01T05:20:46.690] job_complete: JobID=1215 State=0x1 NodeCnt=3 WEXITSTATUS 0
[2017-01-01T05:20:46.690] job_complete: JobID=1215 State=0x8003 NodeCnt=3 done
[2017-01-01T05:20:47.690] sched: Allocate JobID=1254 NodeList=n[1-3] #CPUs=36 Partition=normal
[2017-01-01T05:20:47.690] SIM: faking sending message type REQUEST_BATCH_JOB_LAUNCH to localhost

[2017-01-01T05:21:47.691] job_complete: JobID=1356 State=0x1 NodeCnt=1 WEXITSTATUS 0
[2017-01-01T05:21:47.691] job_complete: JobID=1356 State=0x8003 NodeCnt=1 done
[2017-01-01T05:21:47.692] sched: Allocate JobID=1281 NodeList=m4 #CPUs=6 Partition=normal
[2017-01-01T05:21:47.692] SIM: faking sending message type REQUEST_BATCH_JOB_LAUNCH to localhost

[2017-01-01T05:21:48.692] job_complete: JobID=1281 State=0x1 NodeCnt=1 WEXITSTATUS 0
[2017-01-01T05:21:48.692] job_complete: JobID=1281 State=0x8003 NodeCnt=1 done
[2017-01-01T05:21:59.692] job_complete: JobID=1331 State=0x1 NodeCnt=1 WEXITSTATUS 0
[2017-01-01T05:21:59.692] job_complete: JobID=1331 State=0x8003 NodeCnt=1 done
[2017-01-01T05:22:41.692] job_complete: JobID=1186 State=0x1 NodeCnt=1 WEXITSTATUS 0
[2017-01-01T05:22:41.693] job_complete: JobID=1186 State=0x8003 NodeCnt=1 done
[2017-01-01T05:23:07.693] Successfully submit job to queue (job_id: 1384)
[2017-01-01T05:23:46.693] Successfully submit job to queue (job_id: 1385)
[2017-01-01T05:24:21.694] Successfully submit job to queue (job_id: 1386)
[2017-01-01T05:24:47.694] Successfully submit job to queue (job_id: 1387)
[2017-01-01T05:25:08.695] Successfully submit job to queue (job_id: 1388)
[2017-01-01T05:25:32.695] job_complete: JobID=1358 State=0x1 NodeCnt=1 WEXITSTATUS 0
[2017-01-01T05:25:32.695] job_complete: JobID=1358 State=0x8003 NodeCnt=1 done
[2017-01-01T05:25:32.695] sched: Allocate JobID=1277 NodeList=g1 #CPUs=12 Partition=normal
[2017-01-01T05:25:32.695] SIM: faking sending message type REQUEST_BATCH_JOB_LAUNCH to localhost

[2017-01-01T05:25:32.696] sched: Allocate JobID=1242 NodeList=n4 #CPUs=1 Partition=normal
[2017-01-01T05:25:32.696] SIM: faking sending message type REQUEST_BATCH_JOB_LAUNCH to localhost

[2017-01-01T05:25:41.696] job_complete: JobID=1315 State=0x1 NodeCnt=1 WEXITSTATUS 0
[2017-01-01T05:25:41.696] job_complete: JobID=1315 State=0x8003 NodeCnt=1 done
[2017-01-01T05:27:33.701] Successfully submit job to queue (job_id: 1389)
[2017-01-01T05:29:33.702] Successfully submit job to queue (job_id: 1390)
[2017-01-01T05:29:48.702] Successfully submit job to queue (job_id: 1391)
[2017-01-01T05:29:50.702] Successfully submit job to queue (job_id: 1392)
[2017-01-01T05:30:23.703] Successfully submit job to queue (job_id: 1393)
[2017-01-01T05:30:47.703] job_complete: JobID=1254 State=0x1 NodeCnt=3 WEXITSTATUS 0
[2017-01-01T05:30:47.703] job_complete: JobID=1254 State=0x8003 NodeCnt=3 done
[2017-01-01T05:31:55.709] Successfully submit job to queue (job_id: 1394)
[2017-01-01T05:32:10.710] Successfully submit job to queue (job_id: 1395)
[2017-01-01T05:33:42.711] Successfully submit job to queue (job_id: 1396)
[2017-01-01T05:34:02.711] Successfully submit job to queue (job_id: 1397)
[2017-01-01T05:34:23.711] Successfully submit job to queue (job_id: 1398)
[2017-01-01T05:34:30.711] Successfully submit job to queue (job_id: 1399)
[2017-01-01T05:35:50.713] Successfully submit job to queue (job_id: 1400)
[2017-01-01T05:36:00.713] Successfully submit job to queue (job_id: 1401)
[2017-01-01T05:36:37.713] Successfully submit job to queue (job_id: 1402)
[2017-01-01T05:37:38.718] Successfully submit job to queue (job_id: 1403)
[2017-01-01T05:37:50.719] Successfully submit job to queue (job_id: 1404)
[2017-01-01T05:38:04.719] Successfully submit job to queue (job_id: 1405)
[2017-01-01T05:38:34.719] Successfully submit job to queue (job_id: 1406)
[2017-01-01T05:38:48.720] Successfully submit job to queue (job_id: 1407)
[2017-01-01T05:39:40.720] Successfully submit job to queue (job_id: 1408)
[2017-01-01T05:40:40.721] Successfully submit job to queue (job_id: 1409)
[2017-01-01T05:40:41.723] backfill: Started JobId=1208 in normal on n4
[2017-01-01T05:40:41.723] SIM: faking sending message type REQUEST_BATCH_JOB_LAUNCH to localhost

[2017-01-01T05:40:41.723] backfill: Started JobId=1319 in normal on n4
[2017-01-01T05:40:41.723] SIM: faking sending message type REQUEST_BATCH_JOB_LAUNCH to localhost

[2017-01-01T05:40:41.724] backfill: Started JobId=1329 in normal on n4
[2017-01-01T05:40:41.724] SIM: faking sending message type REQUEST_BATCH_JOB_LAUNCH to localhost

[2017-01-01T05:40:41.724] backfill: Started JobId=1343 in normal on n4
[2017-01-01T05:40:41.725] SIM: faking sending message type REQUEST_BATCH_JOB_LAUNCH to localhost

[2017-01-01T05:40:41.725] backfill: Started JobId=1304 in normal on n4
[2017-01-01T05:40:41.725] SIM: faking sending message type REQUEST_BATCH_JOB_LAUNCH to localhost

[2017-01-01T05:40:41.726] backfill: Started JobId=1399 in normal on n4
[2017-01-01T05:40:41.726] SIM: faking sending message type REQUEST_BATCH_JOB_LAUNCH to localhost

[2017-01-01T05:40:42.726] job_complete: JobID=1399 State=0x1 NodeCnt=1 WEXITSTATUS 0
[2017-01-01T05:40:42.727] job_complete: JobID=1399 State=0x8003 NodeCnt=1 done
[2017-01-01T05:40:57.727] job_complete: JobID=1277 State=0x1 NodeCnt=1 WEXITSTATUS 0
[2017-01-01T05:40:57.727] job_complete: JobID=1277 State=0x8003 NodeCnt=1 done
[2017-01-01T05:41:11.727] job_complete: JobID=1383 State=0x1 NodeCnt=8 WEXITSTATUS 0
[2017-01-01T05:41:11.727] job_complete: JobID=1383 State=0x8003 NodeCnt=8 done
[2017-01-01T05:41:11.727] sched: Allocate JobID=1392 NodeList=b[1-8] #CPUs=96 Partition=normal
[2017-01-01T05:41:11.727] SIM: faking sending message type REQUEST_BATCH_JOB_LAUNCH to localhost

[2017-01-01T05:41:30.728] Successfully submit job to queue (job_id: 1410)
[2017-01-01T05:41:38.728] job_complete: JobID=1329 State=0x1 NodeCnt=1 WEXITSTATUS 0
[2017-01-01T05:41:38.728] job_complete: JobID=1329 State=0x8003 NodeCnt=1 done
[2017-01-01T05:41:41.728] job_complete: JobID=1287 State=0x1 NodeCnt=1 WEXITSTATUS 0
[2017-01-01T05:41:41.728] job_complete: JobID=1287 State=0x8003 NodeCnt=1 done
[2017-01-01T05:42:12.729] job_complete: JobID=1319 State=0x1 NodeCnt=1 WEXITSTATUS 0
[2017-01-01T05:42:12.729] job_complete: JobID=1319 State=0x8003 NodeCnt=1 done
[2017-01-01T05:42:13.730] Successfully submit job to queue (job_id: 1411)
[2017-01-01T05:42:57.730] job_complete: JobID=1327 State=0x1 NodeCnt=3 WEXITSTATUS 0
[2017-01-01T05:42:57.730] job_complete: JobID=1327 State=0x8003 NodeCnt=3 done
[2017-01-01T05:42:57.730] sched: Allocate JobID=1403 NodeList=b9,m[1-4],n[1-3] #CPUs=96 Partition=normal
[2017-01-01T05:42:57.730] SIM: faking sending message type REQUEST_BATCH_JOB_LAUNCH to localhost

[2017-01-01T05:43:26.731] Successfully submit job to queue (job_id: 1412)
[2017-01-01T05:43:44.731] job_complete: JobID=1343 State=0x1 NodeCnt=1 WEXITSTATUS 0
[2017-01-01T05:43:44.731] job_complete: JobID=1343 State=0x8003 NodeCnt=1 done
[2017-01-01T05:43:49.731] job_complete: JobID=1208 State=0x1 NodeCnt=1 WEXITSTATUS 0
[2017-01-01T05:43:49.731] job_complete: JobID=1208 State=0x8003 NodeCnt=1 done
[2017-01-01T05:43:53.732] Successfully submit job to queue (job_id: 1413)
[2017-01-01T05:44:11.732] job_complete: JobID=1304 State=0x1 NodeCnt=1 WEXITSTATUS 0
[2017-01-01T05:44:11.732] job_complete: JobID=1304 State=0x8003 NodeCnt=1 done
[2017-01-01T05:44:35.732] Successfully submit job to queue (job_id: 1414)
[2017-01-01T05:44:36.732] Successfully submit job to queue (job_id: 1415)
[2017-01-01T05:45:05.733] Successfully submit job to queue (job_id: 1416)
[2017-01-01T05:45:08.734] Successfully submit job to queue (job_id: 1417)
[2017-01-01T05:45:47.734] job_complete: JobID=1392 State=0x1 NodeCnt=8 WEXITSTATUS 0
[2017-01-01T05:45:47.734] job_complete: JobID=1392 State=0x8003 NodeCnt=8 done
[2017-01-01T05:45:47.734] sched: Allocate JobID=1413 NodeList=b[1-8] #CPUs=96 Partition=normal
[2017-01-01T05:45:47.735] SIM: faking sending message type REQUEST_BATCH_JOB_LAUNCH to localhost

[2017-01-01T05:45:55.735] Successfully submit job to queue (job_id: 1418)
[2017-01-01T05:46:04.735] Successfully submit job to queue (job_id: 1419)
[2017-01-01T05:47:11.738] Successfully submit job to queue (job_id: 1420)
[2017-01-01T05:47:18.738] job_complete: JobID=1413 State=0x1 NodeCnt=8 WEXITSTATUS 0
[2017-01-01T05:47:18.738] job_complete: JobID=1413 State=0x8003 NodeCnt=8 done
[2017-01-01T05:47:18.739] sched: Allocate JobID=1418 NodeList=b[1-8] #CPUs=96 Partition=normal
[2017-01-01T05:47:18.739] SIM: faking sending message type REQUEST_BATCH_JOB_LAUNCH to localhost

[2017-01-01T05:47:43.739] Successfully submit job to queue (job_id: 1421)
[2017-01-01T05:49:12.740] Successfully submit job to queue (job_id: 1422)
[2017-01-01T05:51:05.741] Successfully submit job to queue (job_id: 1423)
[2017-01-01T05:51:11.742] Successfully submit job to queue (job_id: 1424)
[2017-01-01T05:51:32.742] job_complete: JobID=1242 State=0x1 NodeCnt=1 WEXITSTATUS 0
[2017-01-01T05:51:32.742] job_complete: JobID=1242 State=0x8003 NodeCnt=1 done
[2017-01-01T05:51:48.742] Successfully submit job to queue (job_id: 1425)
[2017-01-01T05:51:59.747] Successfully submit job to queue (job_id: 1426)
[2017-01-01T05:52:01.747] job_complete: JobID=1418 State=0x1 NodeCnt=8 WEXITSTATUS 0
[2017-01-01T05:52:01.747] job_complete: JobID=1418 State=0x8003 NodeCnt=8 done
[2017-01-01T05:52:02.748] sched: Allocate JobID=1422 NodeList=b[1-8] #CPUs=96 Partition=normal
[2017-01-01T05:52:02.748] SIM: faking sending message type REQUEST_BATCH_JOB_LAUNCH to localhost

[2017-01-01T05:53:53.749] Successfully submit job to queue (job_id: 1427)
[2017-01-01T05:54:35.749] Successfully submit job to queue (job_id: 1428)
[2017-01-01T05:55:23.750] Successfully submit job to queue (job_id: 1429)
[2017-01-01T05:56:58.756] job_complete: JobID=1403 State=0x1 NodeCnt=8 WEXITSTATUS 0
[2017-01-01T05:56:58.756] job_complete: JobID=1403 State=0x8003 NodeCnt=8 done
[2017-01-01T05:56:58.756] sched: Allocate JobID=1226 NodeList=m[1-2] #CPUs=24 Partition=normal
[2017-01-01T05:56:58.756] SIM: faking sending message type REQUEST_BATCH_JOB_LAUNCH to localhost

[2017-01-01T05:56:58.756] sched: Allocate JobID=1227 NodeList=n[1-2] #CPUs=24 Partition=normal
[2017-01-01T05:56:58.757] SIM: faking sending message type REQUEST_BATCH_JOB_LAUNCH to localhost

[2017-01-01T05:56:58.757] sched: Allocate JobID=1192 NodeList=m3 #CPUs=12 Partition=normal
[2017-01-01T05:56:58.757] SIM: faking sending message type REQUEST_BATCH_JOB_LAUNCH to localhost

[2017-01-01T05:57:41.757] Successfully submit job to queue (job_id: 1430)
[2017-01-01T05:58:05.757] Successfully submit job to queue (job_id: 1431)
[2017-01-01T05:59:15.758] Successfully submit job to queue (job_id: 1432)
[2017-01-01T05:59:53.758] Successfully submit job to queue (job_id: 1433)
[2017-01-01T06:00:19.759] job_complete: JobID=1226 State=0x1 NodeCnt=2 WEXITSTATUS 0
[2017-01-01T06:00:19.759] job_complete: JobID=1226 State=0x8003 NodeCnt=2 done
[2017-01-01T06:00:21.760] Successfully submit job to queue (job_id: 1434)
[2017-01-01T06:00:41.760] backfill: Started JobId=1201 in normal on n3
[2017-01-01T06:00:41.760] SIM: faking sending message type REQUEST_BATCH_JOB_LAUNCH to localhost

[2017-01-01T06:00:41.760] backfill: Started JobId=1235 in normal on b[9-10]
[2017-01-01T06:00:41.761] SIM: faking sending message type REQUEST_BATCH_JOB_LAUNCH to localhost

[2017-01-01T06:00:41.761] backfill: Started JobId=1160 in normal on g1
[2017-01-01T06:00:41.761] SIM: faking sending message type REQUEST_BATCH_JOB_LAUNCH to localhost

[2017-01-01T06:00:41.761] backfill: Started JobId=1276 in normal on m[1-2,4]
[2017-01-01T06:00:41.761] SIM: faking sending message type REQUEST_BATCH_JOB_LAUNCH to localhost

[2017-01-01T06:00:41.761] backfill: Started JobId=1172 in normal on n4
[2017-01-01T06:00:41.761] SIM: faking sending message type REQUEST_BATCH_JOB_LAUNCH to localhost

[2017-01-01T06:00:41.761] backfill: Started JobId=1246 in normal on g1
[2017-01-01T06:00:41.762] SIM: faking sending message type REQUEST_BATCH_JOB_LAUNCH to localhost

[2017-01-01T06:00:41.762] backfill: Started JobId=1256 in normal on n4
[2017-01-01T06:00:41.762] SIM: faking sending message type REQUEST_BATCH_JOB_LAUNCH to localhost

[2017-01-01T06:00:41.763] backfill: Started JobId=1200 in normal on n4
[2017-01-01T06:00:41.763] SIM: faking sending message type REQUEST_BATCH_JOB_LAUNCH to localhost

[2017-01-01T06:00:41.764] backfill: Started JobId=1240 in normal on n4
[2017-01-01T06:00:41.765] SIM: faking sending message type REQUEST_BATCH_JOB_LAUNCH to localhost

[2017-01-01T06:00:41.769] backfill: Started JobId=1416 in normal on g1
[2017-01-01T06:00:41.769] SIM: faking sending message type REQUEST_BATCH_JOB_LAUNCH to localhost

[2017-01-01T06:00:42.772] job_complete: JobID=1172 State=0x1 NodeCnt=1 WEXITSTATUS 0
[2017-01-01T06:00:42.772] job_complete: JobID=1172 State=0x8003 NodeCnt=1 done
[2017-01-01T06:00:42.772] job_complete: JobID=1246 State=0x1 NodeCnt=1 WEXITSTATUS 0
[2017-01-01T06:00:42.772] job_complete: JobID=1246 State=0x8003 NodeCnt=1 done
[2017-01-01T06:01:00.772] job_complete: JobID=1227 State=0x1 NodeCnt=2 WEXITSTATUS 0
[2017-01-01T06:01:00.772] job_complete: JobID=1227 State=0x8003 NodeCnt=2 done
[2017-01-01T06:02:52.774] Successfully submit job to queue (job_id: 1435)
[2017-01-01T06:02:59.774] Successfully submit job to queue (job_id: 1436)
[2017-01-01T06:03:09.774] job_complete: JobID=1416 State=0x1 NodeCnt=1 WEXITSTATUS 0
[2017-01-01T06:03:09.774] job_complete: JobID=1416 State=0x8003 NodeCnt=1 done
[2017-01-01T06:03:10.775] Successfully submit job to queue (job_id: 1437)
[2017-01-01T06:04:26.775] Successfully submit job to queue (job_id: 1438)
[2017-01-01T06:05:25.776] Successfully submit job to queue (job_id: 1439)
[2017-01-01T06:05:41.777] job_complete: JobID=1200 State=0x1 NodeCnt=1 WEXITSTATUS 0
[2017-01-01T06:05:41.777] job_complete: JobID=1200 State=0x8003 NodeCnt=1 done
[2017-01-01T06:05:41.777] job_complete: JobID=1201 State=0x1 NodeCnt=1 WEXITSTATUS 0
[2017-01-01T06:05:41.777] job_complete: JobID=1201 State=0x8003 NodeCnt=1 done
[2017-01-01T06:06:13.777] job_complete: JobID=1240 State=0x1 NodeCnt=1 WEXITSTATUS 0
[2017-01-01T06:06:13.777] job_complete: JobID=1240 State=0x8003 NodeCnt=1 done
[2017-01-01T06:06:38.778] Successfully submit job to queue (job_id: 1440)
[2017-01-01T06:07:12.783] Successfully submit job to queue (job_id: 1441)
[2017-01-01T06:07:13.783] Successfully submit job to queue (job_id: 1442)
[2017-01-01T06:07:45.784] Successfully submit job to queue (job_id: 1443)
[2017-01-01T06:08:38.784] Successfully submit job to queue (job_id: 1444)
[2017-01-01T06:10:46.786] job_complete: JobID=1276 State=0x1 NodeCnt=3 WEXITSTATUS 0
[2017-01-01T06:10:46.786] job_complete: JobID=1276 State=0x8003 NodeCnt=3 done
[2017-01-01T06:11:02.787] Successfully submit job to queue (job_id: 1445)
[2017-01-01T06:13:20.792] Successfully submit job to queue (job_id: 1446)
[2017-01-01T06:13:23.792] Successfully submit job to queue (job_id: 1447)
[2017-01-01T06:13:30.793] Successfully submit job to queue (job_id: 1448)
[2017-01-01T06:13:32.793] Successfully submit job to queue (job_id: 1449)
[2017-01-01T06:14:12.793] job_complete: JobID=1422 State=0x1 NodeCnt=8 WEXITSTATUS 0
[2017-01-01T06:14:12.793] job_complete: JobID=1422 State=0x8003 NodeCnt=8 done
[2017-01-01T06:14:12.794] sched: Allocate JobID=1436 NodeList=b[1-8] #CPUs=96 Partition=normal
[2017-01-01T06:14:12.794] SIM: faking sending message type REQUEST_BATCH_JOB_LAUNCH to localhost

[2017-01-01T06:14:43.794] Successfully submit job to queue (job_id: 1450)
[2017-01-01T06:14:47.794] job_complete: JobID=1256 State=0x1 NodeCnt=1 WEXITSTATUS 0
[2017-01-01T06:14:47.794] job_complete: JobID=1256 State=0x8003 NodeCnt=1 done
[2017-01-01T06:15:40.795] job_complete: JobID=1192 State=0x1 NodeCnt=1 WEXITSTATUS 0
[2017-01-01T06:15:40.796] job_complete: JobID=1192 State=0x8003 NodeCnt=1 done
[2017-01-01T06:15:40.796] sched: Allocate JobID=1445 NodeList=m[1-4],n[1-4] #CPUs=96 Partition=normal
[2017-01-01T06:15:40.796] SIM: faking sending message type REQUEST_BATCH_JOB_LAUNCH to localhost

[2017-01-01T06:16:42.797] Successfully submit job to queue (job_id: 1451)
[2017-01-01T06:16:48.797] Successfully submit job to queue (job_id: 1452)
[2017-01-01T06:17:23.801] job_complete: JobID=1235 State=0x1 NodeCnt=2 WEXITSTATUS 0
[2017-01-01T06:17:23.801] job_complete: JobID=1235 State=0x8003 NodeCnt=2 done
[2017-01-01T06:17:36.801] Successfully submit job to queue (job_id: 1453)
[2017-01-01T06:19:26.802] Successfully submit job to queue (job_id: 1454)
[2017-01-01T06:20:00.803] Successfully submit job to queue (job_id: 1455)
[2017-01-01T06:20:32.804] Successfully submit job to queue (job_id: 1456)
[2017-01-01T06:20:41.804] backfill: Started JobId=1205 in normal on b9
[2017-01-01T06:20:41.804] SIM: faking sending message type REQUEST_BATCH_JOB_LAUNCH to localhost

[2017-01-01T06:20:41.805] backfill: Started JobId=1217 in normal on b10
[2017-01-01T06:20:41.805] SIM: faking sending message type REQUEST_BATCH_JOB_LAUNCH to localhost

[2017-01-01T06:20:41.807] backfill: Started JobId=1263 in normal on g1
[2017-01-01T06:20:41.807] SIM: faking sending message type REQUEST_BATCH_JOB_LAUNCH to localhost

[2017-01-01T06:20:41.808] backfill: Started JobId=1348 in normal on g1
[2017-01-01T06:20:41.808] SIM: faking sending message type REQUEST_BATCH_JOB_LAUNCH to localhost

[2017-01-01T06:20:42.813] job_complete: JobID=1348 State=0x1 NodeCnt=1 WEXITSTATUS 0
[2017-01-01T06:20:42.813] job_complete: JobID=1348 State=0x8003 NodeCnt=1 done
[2017-01-01T06:20:51.813] Successfully submit job to queue (job_id: 1457)
[2017-01-01T06:22:21.815] Successfully submit job to queue (job_id: 1458)
[2017-01-01T06:24:26.816] Successfully submit job to queue (job_id: 1459)
[2017-01-01T06:24:40.816] Successfully submit job to queue (job_id: 1460)
[2017-01-01T06:25:55.817] Successfully submit job to queue (job_id: 1461)
[2017-01-01T06:26:11.818] Successfully submit job to queue (job_id: 1462)
[2017-01-01T06:26:12.818] Successfully submit job to queue (job_id: 1463)
[2017-01-01T06:26:49.819] Successfully submit job to queue (job_id: 1464)
[2017-01-01T06:26:54.819] job_complete: JobID=1436 State=0x1 NodeCnt=8 WEXITSTATUS 0
[2017-01-01T06:26:54.819] job_complete: JobID=1436 State=0x8003 NodeCnt=8 done
[2017-01-01T06:26:54.819] sched: Allocate JobID=1456 NodeList=b[1-8] #CPUs=96 Partition=normal
[2017-01-01T06:26:54.819] SIM: faking sending message type REQUEST_BATCH_JOB_LAUNCH to localhost

[2017-01-01T06:27:08.823] Successfully submit job to queue (job_id: 1465)
[2017-01-01T06:28:14.824] Successfully submit job to queue (job_id: 1466)
[2017-01-01T06:28:14.824] job_complete: JobID=1263 State=0x1 NodeCnt=1 WEXITSTATUS 0
[2017-01-01T06:28:14.824] job_complete: JobID=1263 State=0x8003 NodeCnt=1 done
[2017-01-01T06:28:44.825] Successfully submit job to queue (job_id: 1467)
[2017-01-01T06:28:56.825] job_complete: JobID=1160 State=0x1 NodeCnt=1 WEXITSTATUS 0
[2017-01-01T06:28:56.825] job_complete: JobID=1160 State=0x8003 NodeCnt=1 done
[2017-01-01T06:30:39.826] Successfully submit job to queue (job_id: 1468)
[2017-01-01T06:32:57.833] Successfully submit job to queue (job_id: 1469)
[2017-01-01T06:33:17.833] Successfully submit job to queue (job_id: 1470)
[2017-01-01T06:33:53.834] Successfully submit job to queue (job_id: 1471)
[2017-01-01T06:34:03.834] Successfully submit job to queue (job_id: 1472)
[2017-01-01T06:34:17.834] Successfully submit job to queue (job_id: 1473)
[2017-01-01T06:34:33.835] Successfully submit job to queue (job_id: 1474)
[2017-01-01T06:35:04.836] job_complete: JobID=1456 State=0x1 NodeCnt=8 WEXITSTATUS 0
[2017-01-01T06:35:04.836] job_complete: JobID=1456 State=0x8003 NodeCnt=8 done
[2017-01-01T06:35:38.836] Successfully submit job to queue (job_id: 1475)
[2017-01-01T06:35:57.837] Successfully submit job to queue (job_id: 1476)
[2017-01-01T06:38:16.842] job_complete: JobID=1445 State=0x1 NodeCnt=8 WEXITSTATUS 0
[2017-01-01T06:38:16.842] job_complete: JobID=1445 State=0x8003 NodeCnt=8 done
[2017-01-01T06:38:16.842] sched: Allocate JobID=1301 NodeList=m[1-4] #CPUs=48 Partition=normal
[2017-01-01T06:38:16.842] SIM: faking sending message type REQUEST_BATCH_JOB_LAUNCH to localhost

[2017-01-01T06:38:41.843] job_complete: JobID=1205 State=0x1 NodeCnt=1 WEXITSTATUS 0
[2017-01-01T06:38:41.843] job_complete: JobID=1205 State=0x8003 NodeCnt=1 done
[2017-01-01T06:39:25.843] Successfully submit job to queue (job_id: 1477)
[2017-01-01T06:40:32.844] job_complete: JobID=1301 State=0x1 NodeCnt=4 WEXITSTATUS 0
[2017-01-01T06:40:32.845] job_complete: JobID=1301 State=0x8003 NodeCnt=4 done
[2017-01-01T06:40:32.845] sched: Allocate JobID=1237 NodeList=m[1-2] #CPUs=24 Partition=normal
[2017-01-01T06:40:32.845] SIM: faking sending message type REQUEST_BATCH_JOB_LAUNCH to localhost

[2017-01-01T06:40:32.845] sched: Allocate JobID=1275 NodeList=n[1-3] #CPUs=36 Partition=normal
[2017-01-01T06:40:32.845] SIM: faking sending message type REQUEST_BATCH_JOB_LAUNCH to localhost

[2017-01-01T06:40:32.845] sched: Allocate JobID=1178 NodeList=g1 #CPUs=1 Partition=normal
[2017-01-01T06:40:32.845] SIM: faking sending message type REQUEST_BATCH_JOB_LAUNCH to localhost

[2017-01-01T06:40:32.845] sched: Allocate JobID=1202 NodeList=m3 #CPUs=12 Partition=normal
[2017-01-01T06:40:32.845] SIM: faking sending message type REQUEST_BATCH_JOB_LAUNCH to localhost

[2017-01-01T06:40:33.846] job_complete: JobID=1237 State=0x1 NodeCnt=2 WEXITSTATUS 0
[2017-01-01T06:40:33.846] job_complete: JobID=1237 State=0x8003 NodeCnt=2 done
[2017-01-01T06:40:39.846] Successfully submit job to queue (job_id: 1478)
[2017-01-01T06:40:41.847] backfill: Started JobId=1189 in normal on m1
[2017-01-01T06:40:41.847] SIM: faking sending message type REQUEST_BATCH_JOB_LAUNCH to localhost

[2017-01-01T06:40:41.847] backfill: Started JobId=1328 in normal on b[1-4]
[2017-01-01T06:40:41.847] SIM: faking sending message type REQUEST_BATCH_JOB_LAUNCH to localhost

[2017-01-01T06:40:41.847] backfill: Started JobId=1234 in normal on n4
[2017-01-01T06:40:41.848] SIM: faking sending message type REQUEST_BATCH_JOB_LAUNCH to localhost

[2017-01-01T06:40:41.848] backfill: Started JobId=1222 in normal on m2
[2017-01-01T06:40:41.848] SIM: faking sending message type REQUEST_BATCH_JOB_LAUNCH to localhost

[2017-01-01T06:40:41.848] backfill: Started JobId=1224 in normal on m4
[2017-01-01T06:40:41.848] SIM: faking sending message type REQUEST_BATCH_JOB_LAUNCH to localhost

[2017-01-01T06:40:41.848] backfill: Started JobId=1233 in normal on b5
[2017-01-01T06:40:41.848] SIM: faking sending message type REQUEST_BATCH_JOB_LAUNCH to localhost

[2017-01-01T06:40:41.848] backfill: Started JobId=1350 in normal on b[6-9]
[2017-01-01T06:40:41.849] SIM: faking sending message type REQUEST_BATCH_JOB_LAUNCH to localhost

[2017-01-01T06:40:41.850] backfill: Started JobId=1257 in normal on g1
[2017-01-01T06:40:41.850] SIM: faking sending message type REQUEST_BATCH_JOB_LAUNCH to localhost

[2017-01-01T06:40:41.850] backfill: Started JobId=1248 in normal on g1
[2017-01-01T06:40:41.851] SIM: faking sending message type REQUEST_BATCH_JOB_LAUNCH to localhost

[2017-01-01T06:40:41.851] backfill: Started JobId=1264 in normal on m1
[2017-01-01T06:40:41.851] SIM: faking sending message type REQUEST_BATCH_JOB_LAUNCH to localhost

[2017-01-01T06:40:58.867] Successfully submit job to queue (job_id: 1479)
[2017-01-01T06:41:18.868] Successfully submit job to queue (job_id: 1480)
[2017-01-01T06:42:15.869] job_complete: JobID=1189 State=0x1 NodeCnt=1 WEXITSTATUS 0
[2017-01-01T06:42:15.870] job_complete: JobID=1189 State=0x8003 NodeCnt=1 done
[2017-01-01T06:42:18.870] Successfully submit job to queue (job_id: 1481)
[2017-01-01T06:42:42.870] Successfully submit job to queue (job_id: 1482)
[2017-01-01T06:43:12.871] job_complete: JobID=1264 State=0x1 NodeCnt=1 WEXITSTATUS 0
[2017-01-01T06:43:12.871] job_complete: JobID=1264 State=0x8003 NodeCnt=1 done
[2017-01-01T06:43:39.871] job_complete: JobID=1233 State=0x1 NodeCnt=1 WEXITSTATUS 0
[2017-01-01T06:43:39.871] job_complete: JobID=1233 State=0x8003 NodeCnt=1 done
[2017-01-01T06:43:41.871] job_complete: JobID=1217 State=0x1 NodeCnt=1 WEXITSTATUS 0
[2017-01-01T06:43:41.871] job_complete: JobID=1217 State=0x8003 NodeCnt=1 done
[2017-01-01T06:44:55.872] Successfully submit job to queue (job_id: 1483)
[2017-01-01T06:45:27.873] job_complete: JobID=1222 State=0x1 NodeCnt=1 WEXITSTATUS 0
[2017-01-01T06:45:27.873] job_complete: JobID=1222 State=0x8003 NodeCnt=1 done
[2017-01-01T06:45:41.873] job_complete: JobID=1328 State=0x1 NodeCnt=4 WEXITSTATUS 0
[2017-01-01T06:45:41.873] job_complete: JobID=1328 State=0x8003 NodeCnt=4 done
[2017-01-01T06:45:44.874] job_complete: JobID=1224 State=0x1 NodeCnt=1 WEXITSTATUS 0
[2017-01-01T06:45:44.874] job_complete: JobID=1224 State=0x8003 NodeCnt=1 done
[2017-01-01T06:45:56.874] Successfully submit job to queue (job_id: 1484)
[2017-01-01T06:46:29.874] Successfully submit job to queue (job_id: 1485)
[2017-01-01T06:46:41.874] job_complete: JobID=1234 State=0x1 NodeCnt=1 WEXITSTATUS 0
[2017-01-01T06:46:41.874] job_complete: JobID=1234 State=0x8003 NodeCnt=1 done
[2017-01-01T06:48:17.879] job_complete: JobID=1350 State=0x1 NodeCnt=4 WEXITSTATUS 0
[2017-01-01T06:48:17.879] job_complete: JobID=1350 State=0x8003 NodeCnt=4 done
[2017-01-01T06:48:42.879] job_complete: JobID=1202 State=0x1 NodeCnt=1 WEXITSTATUS 0
[2017-01-01T06:48:42.879] job_complete: JobID=1202 State=0x8003 NodeCnt=1 done
[2017-01-01T06:50:36.881] Successfully submit job to queue (job_id: 1486)
[2017-01-01T06:51:28.882] Successfully submit job to queue (job_id: 1487)
[2017-01-01T06:51:45.882] Successfully submit job to queue (job_id: 1488)
[2017-01-01T06:52:24.887] Successfully submit job to queue (job_id: 1489)
[2017-01-01T06:52:24.888] sched: Allocate JobID=1297 NodeList=m[1-3] #CPUs=36 Partition=normal
[2017-01-01T06:52:24.888] SIM: faking sending message type REQUEST_BATCH_JOB_LAUNCH to localhost

[2017-01-01T06:52:27.888] Successfully submit job to queue (job_id: 1490)
[2017-01-01T06:52:43.888] Successfully submit job to queue (job_id: 1491)
[2017-01-01T06:52:52.888] Successfully submit job to queue (job_id: 1492)
[2017-01-01T06:53:33.889] Successfully submit job to queue (job_id: 1493)
[2017-01-01T06:53:43.890] Successfully submit job to queue (job_id: 1494)
[2017-01-01T06:54:17.890] job_complete: JobID=1257 State=0x1 NodeCnt=1 WEXITSTATUS 0
[2017-01-01T06:54:17.890] job_complete: JobID=1257 State=0x8003 NodeCnt=1 done
[2017-01-01T06:55:18.892] Successfully submit job to queue (job_id: 1495)
[2017-01-01T06:56:29.892] Successfully submit job to queue (job_id: 1496)
[2017-01-01T06:57:41.897] sched: Allocate JobID=1214 NodeList=m4 #CPUs=12 Partition=normal
[2017-01-01T06:57:41.897] SIM: faking sending message type REQUEST_BATCH_JOB_LAUNCH to localhost

[2017-01-01T06:57:42.897] job_complete: JobID=1214 State=0x1 NodeCnt=1 WEXITSTATUS 0
[2017-01-01T06:57:42.897] job_complete: JobID=1214 State=0x8003 NodeCnt=1 done
[2017-01-01T06:58:32.898] Successfully submit job to queue (job_id: 1497)
[2017-01-01T06:58:41.898] job_complete: JobID=1248 State=0x1 NodeCnt=1 WEXITSTATUS 0
[2017-01-01T06:58:41.898] job_complete: JobID=1248 State=0x8003 NodeCnt=1 done
[2017-01-01T06:59:02.898] Successfully submit job to queue (job_id: 1498)
[2017-01-01T06:59:45.899] Successfully submit job to queue (job_id: 1499)
[2017-01-01T06:59:49.899] Successfully submit job to queue (job_id: 1500)
[2017-01-01T06:59:49.899] Error:SIM: unknown user for simulator: 
[2017-01-01T07:00:41.901] backfill: Started JobId=1230 in normal on m4
[2017-01-01T07:00:41.901] SIM: faking sending message type REQUEST_BATCH_JOB_LAUNCH to localhost

[2017-01-01T07:00:41.901] backfill: Started JobId=1250 in normal on n4
[2017-01-01T07:00:41.901] SIM: faking sending message type REQUEST_BATCH_JOB_LAUNCH to localhost

[2017-01-01T07:00:41.901] backfill: Started JobId=1244 in normal on b1
[2017-01-01T07:00:41.901] SIM: faking sending message type REQUEST_BATCH_JOB_LAUNCH to localhost

[2017-01-01T07:00:41.901] backfill: Started JobId=1206 in normal on b2
[2017-01-01T07:00:41.901] SIM: faking sending message type REQUEST_BATCH_JOB_LAUNCH to localhost

[2017-01-01T07:00:41.902] backfill: Started JobId=1404 in normal on b[3-6]
[2017-01-01T07:00:41.902] SIM: faking sending message type REQUEST_BATCH_JOB_LAUNCH to localhost

[2017-01-01T07:00:41.902] backfill: Started JobId=1269 in normal on b7
[2017-01-01T07:00:41.902] SIM: faking sending message type REQUEST_BATCH_JOB_LAUNCH to localhost

[2017-01-01T07:00:41.902] backfill: Started JobId=1342 in normal on b[8-10]
[2017-01-01T07:00:41.902] SIM: faking sending message type REQUEST_BATCH_JOB_LAUNCH to localhost

[2017-01-01T07:00:41.902] backfill: Started JobId=1251 in normal on b2
[2017-01-01T07:00:41.903] SIM: faking sending message type REQUEST_BATCH_JOB_LAUNCH to localhost

[2017-01-01T07:00:41.904] backfill: Started JobId=1303 in normal on g1
[2017-01-01T07:00:41.905] SIM: faking sending message type REQUEST_BATCH_JOB_LAUNCH to localhost

[2017-01-01T07:00:41.907] backfill: Started JobId=1347 in normal on b2
[2017-01-01T07:00:41.907] SIM: faking sending message type REQUEST_BATCH_JOB_LAUNCH to localhost

[2017-01-01T07:00:41.909] backfill: Started JobId=1400 in normal on b2
[2017-01-01T07:00:41.909] SIM: faking sending message type REQUEST_BATCH_JOB_LAUNCH to localhost

[2017-01-01T07:00:41.910] backfill: Started JobId=1479 in normal on b2
[2017-01-01T07:00:41.911] SIM: faking sending message type REQUEST_BATCH_JOB_LAUNCH to localhost

[2017-01-01T07:00:41.912] backfill: Started JobId=1499 in normal on b2
[2017-01-01T07:00:41.912] SIM: faking sending message type REQUEST_BATCH_JOB_LAUNCH to localhost

[2017-01-01T07:01:30.912] job_complete: JobID=1297 State=0x1 NodeCnt=3 WEXITSTATUS 0
[2017-01-01T07:01:30.912] job_complete: JobID=1297 State=0x8003 NodeCnt=3 done
[2017-01-01T07:02:14.914] job_complete: JobID=1479 State=0x1 NodeCnt=1 WEXITSTATUS 0
[2017-01-01T07:02:14.914] job_complete: JobID=1479 State=0x8003 NodeCnt=1 done
[2017-01-01T07:02:22.914] job_complete: JobID=1400 State=0x1 NodeCnt=1 WEXITSTATUS 0
[2017-01-01T07:02:22.914] job_complete: JobID=1400 State=0x8003 NodeCnt=1 done
[2017-01-01T07:02:43.915] job_complete: JobID=1404 State=0x1 NodeCnt=4 WEXITSTATUS 0
[2017-01-01T07:02:43.915] job_complete: JobID=1404 State=0x8003 NodeCnt=4 done
[2017-01-01T07:03:05.915] job_complete: JobID=1347 State=0x1 NodeCnt=1 WEXITSTATUS 0
[2017-01-01T07:03:05.915] job_complete: JobID=1347 State=0x8003 NodeCnt=1 done
[2017-01-01T07:03:49.916] job_complete: JobID=1275 State=0x1 NodeCnt=3 WEXITSTATUS 0
[2017-01-01T07:03:49.916] job_complete: JobID=1275 State=0x8003 NodeCnt=3 done
[2017-01-01T07:04:45.916] job_complete: JobID=1250 State=0x1 NodeCnt=1 WEXITSTATUS 0
[2017-01-01T07:04:45.916] job_complete: JobID=1250 State=0x8003 NodeCnt=1 done
[2017-01-01T07:05:12.917] job_complete: JobID=1244 State=0x1 NodeCnt=1 WEXITSTATUS 0
[2017-01-01T07:05:12.917] job_complete: JobID=1244 State=0x8003 NodeCnt=1 done
[2017-01-01T07:05:41.918] job_complete: JobID=1303 State=0x1 NodeCnt=1 WEXITSTATUS 0
[2017-01-01T07:05:41.918] job_complete: JobID=1303 State=0x8003 NodeCnt=1 done
[2017-01-01T07:06:58.919] job_complete: JobID=1499 State=0x1 NodeCnt=1 WEXITSTATUS 0
[2017-01-01T07:06:58.919] job_complete: JobID=1499 State=0x8003 NodeCnt=1 done
[2017-01-01T07:07:12.923] job_complete: JobID=1178 State=0x1 NodeCnt=1 WEXITSTATUS 0
[2017-01-01T07:07:12.923] job_complete: JobID=1178 State=0x8003 NodeCnt=1 done
[2017-01-01T07:07:12.923] sched: Allocate JobID=1203 NodeList=g1 #CPUs=12 Partition=normal
[2017-01-01T07:07:12.923] SIM: faking sending message type REQUEST_BATCH_JOB_LAUNCH to localhost

[2017-01-01T07:07:12.923] sched: Allocate JobID=1305 NodeList=m[1-3] #CPUs=36 Partition=normal
[2017-01-01T07:07:12.924] SIM: faking sending message type REQUEST_BATCH_JOB_LAUNCH to localhost

[2017-01-01T07:07:14.924] job_complete: JobID=1203 State=0x1 NodeCnt=1 WEXITSTATUS 0
[2017-01-01T07:07:14.924] job_complete: JobID=1203 State=0x8003 NodeCnt=1 done
[2017-01-01T07:07:15.924] sched: Allocate JobID=1220 NodeList=g1 #CPUs=12 Partition=normal
[2017-01-01T07:07:15.924] SIM: faking sending message type REQUEST_BATCH_JOB_LAUNCH to localhost

[2017-01-01T07:07:22.924] job_complete: JobID=1251 State=0x1 NodeCnt=1 WEXITSTATUS 0
[2017-01-01T07:07:22.924] job_complete: JobID=1251 State=0x8003 NodeCnt=1 done
[2017-01-01T07:10:25.927] job_complete: JobID=1305 State=0x1 NodeCnt=3 WEXITSTATUS 0
[2017-01-01T07:10:25.927] job_complete: JobID=1305 State=0x8003 NodeCnt=3 done
[2017-01-01T07:10:25.927] sched: Allocate JobID=1265 NodeList=m[1-2] #CPUs=24 Partition=normal
[2017-01-01T07:10:25.927] SIM: faking sending message type REQUEST_BATCH_JOB_LAUNCH to localhost

[2017-01-01T07:10:25.927] sched: Allocate JobID=1300 NodeList=n[1-3] #CPUs=36 Partition=normal
[2017-01-01T07:10:25.927] SIM: faking sending message type REQUEST_BATCH_JOB_LAUNCH to localhost

[2017-01-01T07:10:25.927] sched: Allocate JobID=1282 NodeList=m3 #CPUs=12 Partition=normal
[2017-01-01T07:10:25.927] SIM: faking sending message type REQUEST_BATCH_JOB_LAUNCH to localhost

[2017-01-01T07:11:53.928] job_complete: JobID=1342 State=0x1 NodeCnt=3 WEXITSTATUS 0
[2017-01-01T07:11:53.928] job_complete: JobID=1342 State=0x8003 NodeCnt=3 done
[2017-01-01T07:13:04.932] job_complete: JobID=1220 State=0x1 NodeCnt=1 WEXITSTATUS 0
[2017-01-01T07:13:04.932] job_complete: JobID=1220 State=0x8003 NodeCnt=1 done
[2017-01-01T07:14:38.933] job_complete: JobID=1282 State=0x1 NodeCnt=1 WEXITSTATUS 0
[2017-01-01T07:14:38.933] job_complete: JobID=1282 State=0x8003 NodeCnt=1 done
[2017-01-01T07:14:38.933] sched: Allocate JobID=1283 NodeList=m3 #CPUs=12 Partition=normal
[2017-01-01T07:14:38.933] SIM: faking sending message type REQUEST_BATCH_JOB_LAUNCH to localhost

[2017-01-01T07:16:02.935] job_complete: JobID=1265 State=0x1 NodeCnt=2 WEXITSTATUS 0
[2017-01-01T07:16:02.935] job_complete: JobID=1265 State=0x8003 NodeCnt=2 done
[2017-01-01T07:19:28.941] job_complete: JobID=1230 State=0x1 NodeCnt=1 WEXITSTATUS 0
[2017-01-01T07:19:28.941] job_complete: JobID=1230 State=0x8003 NodeCnt=1 done
[2017-01-01T07:20:41.943] backfill: Started JobId=1310 in normal on m1
[2017-01-01T07:20:41.943] SIM: faking sending message type REQUEST_BATCH_JOB_LAUNCH to localhost

[2017-01-01T07:20:41.943] backfill: Started JobId=1330 in normal on n4
[2017-01-01T07:20:41.943] SIM: faking sending message type REQUEST_BATCH_JOB_LAUNCH to localhost

[2017-01-01T07:20:41.944] backfill: Started JobId=1216 in normal on m1
[2017-01-01T07:20:41.944] SIM: faking sending message type REQUEST_BATCH_JOB_LAUNCH to localhost

[2017-01-01T07:20:41.944] backfill: Started JobId=1223 in normal on m1
[2017-01-01T07:20:41.944] SIM: faking sending message type REQUEST_BATCH_JOB_LAUNCH to localhost

[2017-01-01T07:20:41.944] backfill: Started JobId=1318 in normal on m2
[2017-01-01T07:20:41.944] SIM: faking sending message type REQUEST_BATCH_JOB_LAUNCH to localhost

[2017-01-01T07:20:41.944] backfill: Started JobId=1309 in normal on m4
[2017-01-01T07:20:41.944] SIM: faking sending message type REQUEST_BATCH_JOB_LAUNCH to localhost

[2017-01-01T07:20:41.944] backfill: Started JobId=1271 in normal on b1
[2017-01-01T07:20:41.945] SIM: faking sending message type REQUEST_BATCH_JOB_LAUNCH to localhost

[2017-01-01T07:20:41.945] backfill: Started JobId=1323 in normal on b3
[2017-01-01T07:20:41.945] SIM: faking sending message type REQUEST_BATCH_JOB_LAUNCH to localhost

[2017-01-01T07:20:41.945] backfill: Started JobId=1280 in normal on b4
[2017-01-01T07:20:41.945] SIM: faking sending message type REQUEST_BATCH_JOB_LAUNCH to localhost

[2017-01-01T07:20:41.945] backfill: Started JobId=1285 in normal on g1
[2017-01-01T07:20:41.946] SIM: faking sending message type REQUEST_BATCH_JOB_LAUNCH to localhost

[2017-01-01T07:20:41.946] backfill: Started JobId=1294 in normal on b5
[2017-01-01T07:20:41.946] SIM: faking sending message type REQUEST_BATCH_JOB_LAUNCH to localhost

[2017-01-01T07:20:41.946] backfill: Started JobId=1291 in normal on m1
[2017-01-01T07:20:41.946] SIM: faking sending message type REQUEST_BATCH_JOB_LAUNCH to localhost

[2017-01-01T07:20:41.946] backfill: Started JobId=1374 in normal on b[6,8-9]
[2017-01-01T07:20:41.946] SIM: faking sending message type REQUEST_BATCH_JOB_LAUNCH to localhost

[2017-01-01T07:20:41.947] backfill: Started JobId=1259 in normal on m1
[2017-01-01T07:20:41.947] SIM: faking sending message type REQUEST_BATCH_JOB_LAUNCH to localhost

[2017-01-01T07:20:41.947] backfill: Started JobId=1272 in normal on m1
[2017-01-01T07:20:41.947] SIM: faking sending message type REQUEST_BATCH_JOB_LAUNCH to localhost

[2017-01-01T07:20:41.949] backfill: Started JobId=1362 in normal on m1
[2017-01-01T07:20:41.949] SIM: faking sending message type REQUEST_BATCH_JOB_LAUNCH to localhost

[2017-01-01T07:20:41.954] backfill: Started JobId=1349 in normal on m2
[2017-01-01T07:20:41.954] SIM: faking sending message type REQUEST_BATCH_JOB_LAUNCH to localhost

[2017-01-01T07:20:41.956] backfill: Started JobId=1382 in normal on m2
[2017-01-01T07:20:41.956] SIM: faking sending message type REQUEST_BATCH_JOB_LAUNCH to localhost

[2017-01-01T07:20:41.956] backfill: Started JobId=1473 in normal on b2
[2017-01-01T07:20:41.957] SIM: faking sending message type REQUEST_BATCH_JOB_LAUNCH to localhost

[2017-01-01T07:20:41.957] backfill: Started JobId=1438 in normal on b10
[2017-01-01T07:20:41.957] SIM: faking sending message type REQUEST_BATCH_JOB_LAUNCH to localhost

[2017-01-01T07:20:41.960] backfill: Started JobId=1482 in normal on m2
[2017-01-01T07:20:41.960] SIM: faking sending message type REQUEST_BATCH_JOB_LAUNCH to localhost

[2017-01-01T07:20:42.961] job_complete: JobID=1349 State=0x1 NodeCnt=1 WEXITSTATUS 0
[2017-01-01T07:20:42.961] job_complete: JobID=1349 State=0x8003 NodeCnt=1 done
[2017-01-01T07:22:22.963] job_complete: JobID=1294 State=0x1 NodeCnt=1 WEXITSTATUS 0
[2017-01-01T07:22:22.963] job_complete: JobID=1294 State=0x8003 NodeCnt=1 done
[2017-01-01T07:23:41.963] job_complete: JobID=1269 State=0x1 NodeCnt=1 WEXITSTATUS 0
[2017-01-01T07:23:41.963] job_complete: JobID=1269 State=0x8003 NodeCnt=1 done
[2017-01-01T07:23:42.964] job_complete: JobID=1271 State=0x1 NodeCnt=1 WEXITSTATUS 0
[2017-01-01T07:23:42.964] job_complete: JobID=1271 State=0x8003 NodeCnt=1 done
[2017-01-01T07:24:28.964] job_complete: JobID=1438 State=0x1 NodeCnt=1 WEXITSTATUS 0
[2017-01-01T07:24:28.964] job_complete: JobID=1438 State=0x8003 NodeCnt=1 done
[2017-01-01T07:25:07.965] job_complete: JobID=1291 State=0x1 NodeCnt=1 WEXITSTATUS 0
[2017-01-01T07:25:07.965] job_complete: JobID=1291 State=0x8003 NodeCnt=1 done
[2017-01-01T07:25:11.965] job_complete: JobID=1280 State=0x1 NodeCnt=1 WEXITSTATUS 0
[2017-01-01T07:25:11.965] job_complete: JobID=1280 State=0x8003 NodeCnt=1 done
[2017-01-01T07:25:26.966] job_complete: JobID=1300 State=0x1 NodeCnt=3 WEXITSTATUS 0
[2017-01-01T07:25:26.966] job_complete: JobID=1300 State=0x8003 NodeCnt=3 done
[2017-01-01T07:25:26.966] sched: Allocate JobID=1322 NodeList=n[1-3] #CPUs=36 Partition=normal
[2017-01-01T07:25:26.966] SIM: faking sending message type REQUEST_BATCH_JOB_LAUNCH to localhost

[2017-01-01T07:25:43.966] job_complete: JobID=1272 State=0x1 NodeCnt=1 WEXITSTATUS 0
[2017-01-01T07:25:43.967] job_complete: JobID=1272 State=0x8003 NodeCnt=1 done
[2017-01-01T07:26:07.967] job_complete: JobID=1473 State=0x1 NodeCnt=1 WEXITSTATUS 0
[2017-01-01T07:26:07.967] job_complete: JobID=1473 State=0x8003 NodeCnt=1 done
[2017-01-01T07:26:23.967] job_complete: JobID=1330 State=0x1 NodeCnt=1 WEXITSTATUS 0
[2017-01-01T07:26:23.967] job_complete: JobID=1330 State=0x8003 NodeCnt=1 done
[2017-01-01T07:26:23.967] sched: Allocate JobID=1231 NodeList=n4 #CPUs=1 Partition=normal
[2017-01-01T07:26:23.967] SIM: faking sending message type REQUEST_BATCH_JOB_LAUNCH to localhost

[2017-01-01T07:26:23.968] sched: Allocate JobID=1238 NodeList=n4 #CPUs=6 Partition=normal
[2017-01-01T07:26:23.968] SIM: faking sending message type REQUEST_BATCH_JOB_LAUNCH to localhost

[2017-01-01T07:26:28.968] job_complete: JobID=1318 State=0x1 NodeCnt=1 WEXITSTATUS 0
[2017-01-01T07:26:28.968] job_complete: JobID=1318 State=0x8003 NodeCnt=1 done
[2017-01-01T07:26:41.968] job_complete: JobID=1382 State=0x1 NodeCnt=1 WEXITSTATUS 0
[2017-01-01T07:26:41.968] job_complete: JobID=1382 State=0x8003 NodeCnt=1 done
[2017-01-01T07:26:58.968] job_complete: JobID=1238 State=0x1 NodeCnt=1 WEXITSTATUS 0
[2017-01-01T07:26:58.968] job_complete: JobID=1238 State=0x8003 NodeCnt=1 done
[2017-01-01T07:27:41.972] job_complete: JobID=1482 State=0x1 NodeCnt=1 WEXITSTATUS 0
[2017-01-01T07:27:41.972] job_complete: JobID=1482 State=0x8003 NodeCnt=1 done
[2017-01-01T07:27:50.972] job_complete: JobID=1323 State=0x1 NodeCnt=1 WEXITSTATUS 0
[2017-01-01T07:27:50.972] job_complete: JobID=1323 State=0x8003 NodeCnt=1 done
[2017-01-01T07:30:08.974] job_complete: JobID=1322 State=0x1 NodeCnt=3 WEXITSTATUS 0
[2017-01-01T07:30:08.974] job_complete: JobID=1322 State=0x8003 NodeCnt=3 done
[2017-01-01T07:30:08.974] sched: Allocate JobID=1393 NodeList=n[1-3] #CPUs=36 Partition=normal
[2017-01-01T07:30:08.974] SIM: faking sending message type REQUEST_BATCH_JOB_LAUNCH to localhost

[2017-01-01T07:30:08.974] sched: Allocate JobID=1316 NodeList=n4 #CPUs=1 Partition=normal
[2017-01-01T07:30:08.974] SIM: faking sending message type REQUEST_BATCH_JOB_LAUNCH to localhost

[2017-01-01T07:30:14.974] job_complete: JobID=1206 State=0x1 NodeCnt=1 WEXITSTATUS 0
[2017-01-01T07:30:14.974] job_complete: JobID=1206 State=0x8003 NodeCnt=1 done
[2017-01-01T07:32:15.981] job_complete: JobID=1259 State=0x1 NodeCnt=1 WEXITSTATUS 0
[2017-01-01T07:32:15.981] job_complete: JobID=1259 State=0x8003 NodeCnt=1 done
[2017-01-01T07:32:21.981] job_complete: JobID=1216 State=0x1 NodeCnt=1 WEXITSTATUS 0
[2017-01-01T07:32:21.981] job_complete: JobID=1216 State=0x8003 NodeCnt=1 done
[2017-01-01T07:36:01.983] job_complete: JobID=1362 State=0x1 NodeCnt=1 WEXITSTATUS 0
[2017-01-01T07:36:01.983] job_complete: JobID=1362 State=0x8003 NodeCnt=1 done
[2017-01-01T07:36:15.983] job_complete: JobID=1310 State=0x1 NodeCnt=1 WEXITSTATUS 0
[2017-01-01T07:36:15.984] job_complete: JobID=1310 State=0x8003 NodeCnt=1 done
[2017-01-01T07:36:41.984] job_complete: JobID=1285 State=0x1 NodeCnt=1 WEXITSTATUS 0
[2017-01-01T07:36:41.984] job_complete: JobID=1285 State=0x8003 NodeCnt=1 done
[2017-01-01T07:37:02.984] job_complete: JobID=1309 State=0x1 NodeCnt=1 WEXITSTATUS 0
[2017-01-01T07:37:02.984] job_complete: JobID=1309 State=0x8003 NodeCnt=1 done
[2017-01-01T07:38:53.990] job_complete: JobID=1393 State=0x1 NodeCnt=3 WEXITSTATUS 0
[2017-01-01T07:38:53.990] job_complete: JobID=1393 State=0x8003 NodeCnt=3 done
[2017-01-01T07:38:53.991] sched: Allocate JobID=1261 NodeList=n1 #CPUs=12 Partition=normal
[2017-01-01T07:38:53.991] SIM: faking sending message type REQUEST_BATCH_JOB_LAUNCH to localhost

[2017-01-01T07:38:53.991] sched: Allocate JobID=1351 NodeList=m2 #CPUs=12 Partition=normal
[2017-01-01T07:38:53.991] SIM: faking sending message type REQUEST_BATCH_JOB_LAUNCH to localhost

[2017-01-01T07:38:53.991] sched: Allocate JobID=1249 NodeList=n2 #CPUs=6 Partition=normal
[2017-01-01T07:38:53.991] SIM: faking sending message type REQUEST_BATCH_JOB_LAUNCH to localhost

[2017-01-01T07:38:54.991] job_complete: JobID=1261 State=0x1 NodeCnt=1 WEXITSTATUS 0
[2017-01-01T07:38:54.991] job_complete: JobID=1261 State=0x8003 NodeCnt=1 done
[2017-01-01T07:40:41.993] backfill: Started JobId=1270 in normal on n1
[2017-01-01T07:40:41.993] SIM: faking sending message type REQUEST_BATCH_JOB_LAUNCH to localhost

[2017-01-01T07:40:41.993] backfill: Started JobId=1292 in normal on n3
[2017-01-01T07:40:41.993] SIM: faking sending message type REQUEST_BATCH_JOB_LAUNCH to localhost

[2017-01-01T07:40:41.993] backfill: Started JobId=1449 in normal on b[1-4]
[2017-01-01T07:40:41.993] SIM: faking sending message type REQUEST_BATCH_JOB_LAUNCH to localhost

[2017-01-01T07:40:41.994] backfill: Started JobId=1268 in normal on n2
[2017-01-01T07:40:41.994] SIM: faking sending message type REQUEST_BATCH_JOB_LAUNCH to localhost

[2017-01-01T07:40:41.994] backfill: Started JobId=1278 in normal on n4
[2017-01-01T07:40:41.994] SIM: faking sending message type REQUEST_BATCH_JOB_LAUNCH to localhost

[2017-01-01T07:40:41.994] backfill: Started JobId=1260 in normal on g1
[2017-01-01T07:40:41.994] SIM: faking sending message type REQUEST_BATCH_JOB_LAUNCH to localhost

[2017-01-01T07:40:41.994] backfill: Started JobId=1284 in normal on b5
[2017-01-01T07:40:41.994] SIM: faking sending message type REQUEST_BATCH_JOB_LAUNCH to localhost

[2017-01-01T07:40:41.995] backfill: Started JobId=1353 in normal on b7
[2017-01-01T07:40:41.995] SIM: faking sending message type REQUEST_BATCH_JOB_LAUNCH to localhost

[2017-01-01T07:40:41.995] backfill: Started JobId=1308 in normal on b10
[2017-01-01T07:40:41.995] SIM: faking sending message type REQUEST_BATCH_JOB_LAUNCH to localhost

[2017-01-01T07:40:41.996] backfill: Started JobId=1299 in normal on g1
[2017-01-01T07:40:41.996] SIM: faking sending message type REQUEST_BATCH_JOB_LAUNCH to localhost

[2017-01-01T07:40:41.999] backfill: Started JobId=1360 in normal on g1
[2017-01-01T07:40:41.999] SIM: faking sending message type REQUEST_BATCH_JOB_LAUNCH to localhost

[2017-01-01T07:40:41.999] backfill: Started JobId=1391 in normal on n4
[2017-01-01T07:40:41.999] SIM: faking sending message type REQUEST_BATCH_JOB_LAUNCH to localhost

[2017-01-01T07:40:41.999] backfill: Started JobId=1398 in normal on n4
[2017-01-01T07:40:41.999] SIM: faking sending message type REQUEST_BATCH_JOB_LAUNCH to localhost

[2017-01-01T07:40:42.003] backfill: Started JobId=1380 in normal on g1
[2017-01-01T07:40:42.003] SIM: faking sending message type REQUEST_BATCH_JOB_LAUNCH to localhost

[2017-01-01T07:40:42.005] backfill: Started JobId=1428 in normal on g1
[2017-01-01T07:40:42.005] SIM: faking sending message type REQUEST_BATCH_JOB_LAUNCH to localhost

[2017-01-01T07:40:42.005] backfill: Started JobId=1432 in normal on g1
[2017-01-01T07:40:42.005] SIM: faking sending message type REQUEST_BATCH_JOB_LAUNCH to localhost

[2017-01-01T07:40:43.008] job_complete: JobID=1398 State=0x1 NodeCnt=1 WEXITSTATUS 0
[2017-01-01T07:40:43.008] job_complete: JobID=1398 State=0x8003 NodeCnt=1 done
[2017-01-01T07:40:43.008] job_complete: JobID=1428 State=0x1 NodeCnt=1 WEXITSTATUS 0
[2017-01-01T07:40:43.008] job_complete: JobID=1428 State=0x8003 NodeCnt=1 done
[2017-01-01T07:41:36.009] job_complete: JobID=1270 State=0x1 NodeCnt=1 WEXITSTATUS 0
[2017-01-01T07:41:36.009] job_complete: JobID=1270 State=0x8003 NodeCnt=1 done
[2017-01-01T07:41:38.009] job_complete: JobID=1283 State=0x1 NodeCnt=1 WEXITSTATUS 0
[2017-01-01T07:41:38.009] job_complete: JobID=1283 State=0x8003 NodeCnt=1 done
[2017-01-01T07:41:41.009] job_complete: JobID=1223 State=0x1 NodeCnt=1 WEXITSTATUS 0
[2017-01-01T07:41:41.009] job_complete: JobID=1223 State=0x8003 NodeCnt=1 done
[2017-01-01T07:41:41.009] sched: Allocate JobID=1405 NodeList=m[1,3-4] #CPUs=36 Partition=normal
[2017-01-01T07:41:41.010] SIM: faking sending message type REQUEST_BATCH_JOB_LAUNCH to localhost

[2017-01-01T07:41:46.010] job_complete: JobID=1405 State=0x1 NodeCnt=3 WEXITSTATUS 0
[2017-01-01T07:41:46.010] job_complete: JobID=1405 State=0x8003 NodeCnt=3 done
[2017-01-01T07:41:49.010] job_complete: JobID=1299 State=0x1 NodeCnt=1 WEXITSTATUS 0
[2017-01-01T07:41:49.010] job_complete: JobID=1299 State=0x8003 NodeCnt=1 done
[2017-01-01T07:42:37.011] job_complete: JobID=1308 State=0x1 NodeCnt=1 WEXITSTATUS 0
[2017-01-01T07:42:37.011] job_complete: JobID=1308 State=0x8003 NodeCnt=1 done
[2017-01-01T07:42:41.012] job_complete: JobID=1374 State=0x1 NodeCnt=3 WEXITSTATUS 0
[2017-01-01T07:42:41.012] job_complete: JobID=1374 State=0x8003 NodeCnt=3 done
[2017-01-01T07:42:50.012] job_complete: JobID=1260 State=0x1 NodeCnt=1 WEXITSTATUS 0
[2017-01-01T07:42:50.012] job_complete: JobID=1260 State=0x8003 NodeCnt=1 done
[2017-01-01T07:43:52.012] job_complete: JobID=1353 State=0x1 NodeCnt=1 WEXITSTATUS 0
[2017-01-01T07:43:52.012] job_complete: JobID=1353 State=0x8003 NodeCnt=1 done
[2017-01-01T07:43:52.012] job_complete: JobID=1292 State=0x1 NodeCnt=1 WEXITSTATUS 0
[2017-01-01T07:43:52.013] job_complete: JobID=1292 State=0x8003 NodeCnt=1 done
[2017-01-01T07:44:43.013] job_complete: JobID=1316 State=0x1 NodeCnt=1 WEXITSTATUS 0
[2017-01-01T07:44:43.013] job_complete: JobID=1316 State=0x8003 NodeCnt=1 done
[2017-01-01T07:45:17.014] job_complete: JobID=1249 State=0x1 NodeCnt=1 WEXITSTATUS 0
[2017-01-01T07:45:17.014] job_complete: JobID=1249 State=0x8003 NodeCnt=1 done
[2017-01-01T07:46:09.015] job_complete: JobID=1449 State=0x1 NodeCnt=4 WEXITSTATUS 0
[2017-01-01T07:46:09.015] job_complete: JobID=1449 State=0x8003 NodeCnt=4 done
[2017-01-01T07:47:20.020] job_complete: JobID=1391 State=0x1 NodeCnt=1 WEXITSTATUS 0
[2017-01-01T07:47:20.020] job_complete: JobID=1391 State=0x8003 NodeCnt=1 done
[2017-01-01T07:48:43.021] job_complete: JobID=1360 State=0x1 NodeCnt=1 WEXITSTATUS 0
[2017-01-01T07:48:43.021] job_complete: JobID=1360 State=0x8003 NodeCnt=1 done
[2017-01-01T07:50:19.022] job_complete: JobID=1284 State=0x1 NodeCnt=1 WEXITSTATUS 0
[2017-01-01T07:50:19.023] job_complete: JobID=1284 State=0x8003 NodeCnt=1 done
[2017-01-01T07:50:41.023] job_complete: JobID=1268 State=0x1 NodeCnt=1 WEXITSTATUS 0
[2017-01-01T07:50:41.023] job_complete: JobID=1268 State=0x8003 NodeCnt=1 done
[2017-01-01T07:52:23.029] job_complete: JobID=1231 State=0x1 NodeCnt=1 WEXITSTATUS 0
[2017-01-01T07:52:23.029] job_complete: JobID=1231 State=0x8003 NodeCnt=1 done
[2017-01-01T07:56:37.032] job_complete: JobID=1432 State=0x1 NodeCnt=1 WEXITSTATUS 0
[2017-01-01T07:56:37.032] job_complete: JobID=1432 State=0x8003 NodeCnt=1 done
[2017-01-01T07:57:08.032] job_complete: JobID=1380 State=0x1 NodeCnt=1 WEXITSTATUS 0
[2017-01-01T07:57:08.032] job_complete: JobID=1380 State=0x8003 NodeCnt=1 done
[2017-01-01T07:58:53.039] job_complete: JobID=1351 State=0x1 NodeCnt=1 WEXITSTATUS 0
[2017-01-01T07:58:53.039] job_complete: JobID=1351 State=0x8003 NodeCnt=1 done
[2017-01-01T07:58:53.039] sched: Allocate JobID=1410 NodeList=m[1-4] #CPUs=48 Partition=normal
[2017-01-01T07:58:53.039] SIM: faking sending message type REQUEST_BATCH_JOB_LAUNCH to localhost

[2017-01-01T07:58:53.039] sched: Allocate JobID=1298 NodeList=n1 #CPUs=12 Partition=normal
[2017-01-01T07:58:53.039] SIM: faking sending message type REQUEST_BATCH_JOB_LAUNCH to localhost

[2017-01-01T08:00:42.041] backfill: Started JobId=1286 in normal on g1
[2017-01-01T08:00:42.041] SIM: faking sending message type REQUEST_BATCH_JOB_LAUNCH to localhost

[2017-01-01T08:00:42.041] backfill: Started JobId=1389 in normal on n2
[2017-01-01T08:00:42.042] SIM: faking sending message type REQUEST_BATCH_JOB_LAUNCH to localhost

[2017-01-01T08:00:42.042] backfill: Started JobId=1339 in normal on b1
[2017-01-01T08:00:42.042] SIM: faking sending message type REQUEST_BATCH_JOB_LAUNCH to localhost

[2017-01-01T08:00:42.042] backfill: Started JobId=1375 in normal on b1
[2017-01-01T08:00:42.042] SIM: faking sending message type REQUEST_BATCH_JOB_LAUNCH to localhost

[2017-01-01T08:00:42.042] backfill: Started JobId=1376 in normal on b2
[2017-01-01T08:00:42.042] SIM: faking sending message type REQUEST_BATCH_JOB_LAUNCH to localhost

[2017-01-01T08:00:42.042] backfill: Started JobId=1440 in normal on b[3-4]
[2017-01-01T08:00:42.042] SIM: faking sending message type REQUEST_BATCH_JOB_LAUNCH to localhost

[2017-01-01T08:00:42.043] backfill: Started JobId=1346 in normal on b2
[2017-01-01T08:00:42.043] SIM: faking sending message type REQUEST_BATCH_JOB_LAUNCH to localhost

[2017-01-01T08:00:42.043] backfill: Started JobId=1483 in normal on b[5-8]
[2017-01-01T08:00:42.043] SIM: faking sending message type REQUEST_BATCH_JOB_LAUNCH to localhost

[2017-01-01T08:00:42.043] backfill: Started JobId=1373 in normal on n3
[2017-01-01T08:00:42.043] SIM: faking sending message type REQUEST_BATCH_JOB_LAUNCH to localhost

[2017-01-01T08:00:42.043] backfill: Started JobId=1378 in normal on b[9-10]
[2017-01-01T08:00:42.043] SIM: faking sending message type REQUEST_BATCH_JOB_LAUNCH to localhost

[2017-01-01T08:00:42.044] backfill: Started JobId=1324 in normal on g1
[2017-01-01T08:00:42.044] SIM: faking sending message type REQUEST_BATCH_JOB_LAUNCH to localhost

[2017-01-01T08:00:42.046] backfill: Started JobId=1340 in normal on g1
[2017-01-01T08:00:42.046] SIM: faking sending message type REQUEST_BATCH_JOB_LAUNCH to localhost

[2017-01-01T08:00:42.050] backfill: Started JobId=1477 in normal on n4
[2017-01-01T08:00:42.050] SIM: faking sending message type REQUEST_BATCH_JOB_LAUNCH to localhost

[2017-01-01T08:00:43.052] job_complete: JobID=1389 State=0x1 NodeCnt=1 WEXITSTATUS 0
[2017-01-01T08:00:43.052] job_complete: JobID=1389 State=0x8003 NodeCnt=1 done
[2017-01-01T08:00:43.052] job_complete: JobID=1375 State=0x1 NodeCnt=1 WEXITSTATUS 0
[2017-01-01T08:00:43.052] job_complete: JobID=1375 State=0x8003 NodeCnt=1 done
[2017-01-01T08:04:02.054] job_complete: JobID=1477 State=0x1 NodeCnt=1 WEXITSTATUS 0
[2017-01-01T08:04:02.054] job_complete: JobID=1477 State=0x8003 NodeCnt=1 done
[2017-01-01T08:04:14.055] job_complete: JobID=1340 State=0x1 NodeCnt=1 WEXITSTATUS 0
[2017-01-01T08:04:14.055] job_complete: JobID=1340 State=0x8003 NodeCnt=1 done
[2017-01-01T08:04:14.055] job_complete: JobID=1324 State=0x1 NodeCnt=1 WEXITSTATUS 0
[2017-01-01T08:04:14.055] job_complete: JobID=1324 State=0x8003 NodeCnt=1 done
[2017-01-01T08:04:45.055] job_complete: JobID=1373 State=0x1 NodeCnt=1 WEXITSTATUS 0
[2017-01-01T08:04:45.055] job_complete: JobID=1373 State=0x8003 NodeCnt=1 done
[2017-01-01T08:05:14.056] job_complete: JobID=1376 State=0x1 NodeCnt=1 WEXITSTATUS 0
[2017-01-01T08:05:14.056] job_complete: JobID=1376 State=0x8003 NodeCnt=1 done
[2017-01-01T08:05:37.056] job_complete: JobID=1440 State=0x1 NodeCnt=2 WEXITSTATUS 0
[2017-01-01T08:05:37.056] job_complete: JobID=1440 State=0x8003 NodeCnt=2 done
[2017-01-01T08:06:15.057] job_complete: JobID=1410 State=0x1 NodeCnt=4 WEXITSTATUS 0
[2017-01-01T08:06:15.057] job_complete: JobID=1410 State=0x8003 NodeCnt=4 done
[2017-01-01T08:07:06.057] job_complete: JobID=1278 State=0x1 NodeCnt=1 WEXITSTATUS 0
[2017-01-01T08:07:06.057] job_complete: JobID=1278 State=0x8003 NodeCnt=1 done
[2017-01-01T08:08:57.063] job_complete: JobID=1346 State=0x1 NodeCnt=1 WEXITSTATUS 0
[2017-01-01T08:08:57.063] job_complete: JobID=1346 State=0x8003 NodeCnt=1 done
[2017-01-01T08:10:27.064] job_complete: JobID=1286 State=0x1 NodeCnt=1 WEXITSTATUS 0
[2017-01-01T08:10:27.064] job_complete: JobID=1286 State=0x8003 NodeCnt=1 done
[2017-01-01T08:10:53.065] job_complete: JobID=1298 State=0x1 NodeCnt=1 WEXITSTATUS 0
[2017-01-01T08:10:53.065] job_complete: JobID=1298 State=0x8003 NodeCnt=1 done
[2017-01-01T08:10:53.065] sched: Allocate JobID=1412 NodeList=n[1-4] #CPUs=48 Partition=normal
[2017-01-01T08:10:53.065] SIM: faking sending message type REQUEST_BATCH_JOB_LAUNCH to localhost

[2017-01-01T08:12:22.071] job_complete: JobID=1378 State=0x1 NodeCnt=2 WEXITSTATUS 0
[2017-01-01T08:12:22.071] job_complete: JobID=1378 State=0x8003 NodeCnt=2 done
[2017-01-01T08:18:06.080] job_complete: JobID=1339 State=0x1 NodeCnt=1 WEXITSTATUS 0
[2017-01-01T08:18:06.081] job_complete: JobID=1339 State=0x8003 NodeCnt=1 done
[2017-01-01T08:20:42.082] backfill: Started JobId=1302 in normal on m1
[2017-01-01T08:20:42.083] SIM: faking sending message type REQUEST_BATCH_JOB_LAUNCH to localhost

[2017-01-01T08:20:42.083] backfill: Started JobId=1293 in normal on m2
[2017-01-01T08:20:42.083] SIM: faking sending message type REQUEST_BATCH_JOB_LAUNCH to localhost

[2017-01-01T08:20:42.083] backfill: Started JobId=1325 in normal on g1
[2017-01-01T08:20:42.083] SIM: faking sending message type REQUEST_BATCH_JOB_LAUNCH to localhost

[2017-01-01T08:20:42.083] backfill: Started JobId=1326 in normal on m3
[2017-01-01T08:20:42.083] SIM: faking sending message type REQUEST_BATCH_JOB_LAUNCH to localhost

[2017-01-01T08:20:42.084] backfill: Started JobId=1313 in normal on m4
[2017-01-01T08:20:42.084] SIM: faking sending message type REQUEST_BATCH_JOB_LAUNCH to localhost

[2017-01-01T08:20:42.084] backfill: Started JobId=1486 in normal on b[1-4]
[2017-01-01T08:20:42.084] SIM: faking sending message type REQUEST_BATCH_JOB_LAUNCH to localhost

[2017-01-01T08:20:42.084] backfill: Started JobId=1321 in normal on b9
[2017-01-01T08:20:42.084] SIM: faking sending message type REQUEST_BATCH_JOB_LAUNCH to localhost

[2017-01-01T08:20:42.085] backfill: Started JobId=1337 in normal on b10
[2017-01-01T08:20:42.085] SIM: faking sending message type REQUEST_BATCH_JOB_LAUNCH to localhost

[2017-01-01T08:20:42.085] backfill: Started JobId=1335 in normal on m4
[2017-01-01T08:20:42.085] SIM: faking sending message type REQUEST_BATCH_JOB_LAUNCH to localhost

[2017-01-01T08:20:42.086] backfill: Started JobId=1408 in normal on b10
[2017-01-01T08:20:42.086] SIM: faking sending message type REQUEST_BATCH_JOB_LAUNCH to localhost

[2017-01-01T08:20:42.090] backfill: Started JobId=1430 in normal on b10
[2017-01-01T08:20:42.090] SIM: faking sending message type REQUEST_BATCH_JOB_LAUNCH to localhost

[2017-01-01T08:20:42.090] backfill: Started JobId=1468 in normal on b9
[2017-01-01T08:20:42.091] SIM: faking sending message type REQUEST_BATCH_JOB_LAUNCH to localhost

[2017-01-01T08:20:42.091] backfill: Started JobId=1488 in normal on b9
[2017-01-01T08:20:42.091] SIM: faking sending message type REQUEST_BATCH_JOB_LAUNCH to localhost

[2017-01-01T08:20:42.091] backfill: Started JobId=1497 in normal on b9
[2017-01-01T08:20:42.092] SIM: faking sending message type REQUEST_BATCH_JOB_LAUNCH to localhost

[2017-01-01T08:20:43.092] job_complete: JobID=1302 State=0x1 NodeCnt=1 WEXITSTATUS 0
[2017-01-01T08:20:43.092] job_complete: JobID=1302 State=0x8003 NodeCnt=1 done
[2017-01-01T08:22:53.094] job_complete: JobID=1412 State=0x1 NodeCnt=4 WEXITSTATUS 0
[2017-01-01T08:22:53.094] job_complete: JobID=1412 State=0x8003 NodeCnt=4 done
[2017-01-01T08:22:53.094] sched: Allocate JobID=1415 NodeList=n[1-4] #CPUs=48 Partition=normal
[2017-01-01T08:22:53.094] SIM: faking sending message type REQUEST_BATCH_JOB_LAUNCH to localhost

[2017-01-01T08:24:20.095] job_complete: JobID=1497 State=0x1 NodeCnt=1 WEXITSTATUS 0
[2017-01-01T08:24:20.095] job_complete: JobID=1497 State=0x8003 NodeCnt=1 done
[2017-01-01T08:24:58.095] job_complete: JobID=1325 State=0x1 NodeCnt=1 WEXITSTATUS 0
[2017-01-01T08:24:58.095] job_complete: JobID=1325 State=0x8003 NodeCnt=1 done
[2017-01-01T08:26:04.096] job_complete: JobID=1335 State=0x1 NodeCnt=1 WEXITSTATUS 0
[2017-01-01T08:26:04.096] job_complete: JobID=1335 State=0x8003 NodeCnt=1 done
[2017-01-01T08:29:03.103] job_complete: JobID=1321 State=0x1 NodeCnt=1 WEXITSTATUS 0
[2017-01-01T08:29:03.103] job_complete: JobID=1321 State=0x8003 NodeCnt=1 done
[2017-01-01T08:29:39.103] job_complete: JobID=1486 State=0x1 NodeCnt=4 WEXITSTATUS 0
[2017-01-01T08:29:39.103] job_complete: JobID=1486 State=0x8003 NodeCnt=4 done
[2017-01-01T08:30:20.104] job_complete: JobID=1468 State=0x1 NodeCnt=1 WEXITSTATUS 0
[2017-01-01T08:30:20.104] job_complete: JobID=1468 State=0x8003 NodeCnt=1 done
[2017-01-01T08:30:42.105] job_complete: JobID=1483 State=0x1 NodeCnt=4 WEXITSTATUS 0
[2017-01-01T08:30:42.105] job_complete: JobID=1483 State=0x8003 NodeCnt=4 done
[2017-01-01T08:31:37.105] job_complete: JobID=1337 State=0x1 NodeCnt=1 WEXITSTATUS 0
[2017-01-01T08:31:37.105] job_complete: JobID=1337 State=0x8003 NodeCnt=1 done
[2017-01-01T08:31:53.106] job_complete: JobID=1313 State=0x1 NodeCnt=1 WEXITSTATUS 0
[2017-01-01T08:31:53.106] job_complete: JobID=1313 State=0x8003 NodeCnt=1 done
[2017-01-01T08:36:26.113] job_complete: JobID=1326 State=0x1 NodeCnt=1 WEXITSTATUS 0
[2017-01-01T08:36:26.113] job_complete: JobID=1326 State=0x8003 NodeCnt=1 done
[2017-01-01T08:36:26.114] sched: Allocate JobID=1385 NodeList=m[1,3-4] #CPUs=36 Partition=normal
[2017-01-01T08:36:26.114] SIM: faking sending message type REQUEST_BATCH_JOB_LAUNCH to localhost

[2017-01-01T08:36:27.114] job_complete: JobID=1385 State=0x1 NodeCnt=3 WEXITSTATUS 0
[2017-01-01T08:36:27.114] job_complete: JobID=1385 State=0x8003 NodeCnt=3 done
[2017-01-01T08:36:29.114] sched: Allocate JobID=1295 NodeList=m1 #CPUs=6 Partition=normal
[2017-01-01T08:36:29.114] SIM: faking sending message type REQUEST_BATCH_JOB_LAUNCH to localhost

[2017-01-01T08:36:29.114] sched: Allocate JobID=1312 NodeList=m1 #CPUs=1 Partition=normal
[2017-01-01T08:36:29.114] SIM: faking sending message type REQUEST_BATCH_JOB_LAUNCH to localhost

[2017-01-01T08:37:54.120] job_complete: JobID=1408 State=0x1 NodeCnt=1 WEXITSTATUS 0
[2017-01-01T08:37:54.121] job_complete: JobID=1408 State=0x8003 NodeCnt=1 done
[2017-01-01T08:39:05.121] job_complete: JobID=1430 State=0x1 NodeCnt=1 WEXITSTATUS 0
[2017-01-01T08:39:05.121] job_complete: JobID=1430 State=0x8003 NodeCnt=1 done
[2017-01-01T08:39:16.121] job_complete: JobID=1312 State=0x1 NodeCnt=1 WEXITSTATUS 0
[2017-01-01T08:39:16.121] job_complete: JobID=1312 State=0x8003 NodeCnt=1 done
[2017-01-01T08:40:42.123] backfill: Started JobId=1296 in normal on g1
[2017-01-01T08:40:42.123] SIM: faking sending message type REQUEST_BATCH_JOB_LAUNCH to localhost

[2017-01-01T08:40:42.123] backfill: Started JobId=1371 in normal on m3
[2017-01-01T08:40:42.123] SIM: faking sending message type REQUEST_BATCH_JOB_LAUNCH to localhost

[2017-01-01T08:40:42.123] backfill: Started JobId=1452 in normal on b[1-4]
[2017-01-01T08:40:42.123] SIM: faking sending message type REQUEST_BATCH_JOB_LAUNCH to localhost

[2017-01-01T08:40:42.124] backfill: Started JobId=1500 in normal on b[5-7]
[2017-01-01T08:40:42.124] SIM: faking sending message type REQUEST_BATCH_JOB_LAUNCH to localhost

[2017-01-01T08:40:42.124] backfill: Started JobId=1357 in normal on m4
[2017-01-01T08:40:42.124] SIM: faking sending message type REQUEST_BATCH_JOB_LAUNCH to localhost

[2017-01-01T08:40:42.125] backfill: Started JobId=1363 in normal on m1
[2017-01-01T08:40:42.126] SIM: faking sending message type REQUEST_BATCH_JOB_LAUNCH to localhost

[2017-01-01T08:40:42.126] backfill: Started JobId=1443 in normal on m1
[2017-01-01T08:40:42.126] SIM: faking sending message type REQUEST_BATCH_JOB_LAUNCH to localhost

[2017-01-01T08:40:43.128] job_complete: JobID=1371 State=0x1 NodeCnt=1 WEXITSTATUS 0
[2017-01-01T08:40:43.128] job_complete: JobID=1371 State=0x8003 NodeCnt=1 done
[2017-01-01T08:41:03.128] job_complete: JobID=1488 State=0x1 NodeCnt=1 WEXITSTATUS 0
[2017-01-01T08:41:03.128] job_complete: JobID=1488 State=0x8003 NodeCnt=1 done
[2017-01-01T08:41:42.129] job_complete: JobID=1293 State=0x1 NodeCnt=1 WEXITSTATUS 0
[2017-01-01T08:41:42.129] job_complete: JobID=1293 State=0x8003 NodeCnt=1 done
[2017-01-01T08:42:14.129] job_complete: JobID=1500 State=0x1 NodeCnt=3 WEXITSTATUS 0
[2017-01-01T08:42:14.129] job_complete: JobID=1500 State=0x8003 NodeCnt=3 done
[2017-01-01T08:42:16.129] job_complete: JobID=1452 State=0x1 NodeCnt=4 WEXITSTATUS 0
[2017-01-01T08:42:16.129] job_complete: JobID=1452 State=0x8003 NodeCnt=4 done
[2017-01-01T08:43:34.131] job_complete: JobID=1357 State=0x1 NodeCnt=1 WEXITSTATUS 0
[2017-01-01T08:43:34.131] job_complete: JobID=1357 State=0x8003 NodeCnt=1 done
[2017-01-01T08:44:36.131] job_complete: JobID=1296 State=0x1 NodeCnt=1 WEXITSTATUS 0
[2017-01-01T08:44:36.131] job_complete: JobID=1296 State=0x8003 NodeCnt=1 done
[2017-01-01T08:46:50.133] job_complete: JobID=1363 State=0x1 NodeCnt=1 WEXITSTATUS 0
[2017-01-01T08:46:50.133] job_complete: JobID=1363 State=0x8003 NodeCnt=1 done
[2017-01-01T08:52:53.149] job_complete: JobID=1415 State=0x1 NodeCnt=4 WEXITSTATUS 0
[2017-01-01T08:52:53.149] job_complete: JobID=1415 State=0x8003 NodeCnt=4 done
[2017-01-01T08:52:53.149] sched: Allocate JobID=1464 NodeList=n[1-3] #CPUs=36 Partition=normal
[2017-01-01T08:52:53.150] SIM: faking sending message type REQUEST_BATCH_JOB_LAUNCH to localhost

[2017-01-01T08:52:53.150] sched: Allocate JobID=1369 NodeList=n4 #CPUs=6 Partition=normal
[2017-01-01T08:52:53.150] SIM: faking sending message type REQUEST_BATCH_JOB_LAUNCH to localhost

[2017-01-01T08:52:54.150] job_complete: JobID=1464 State=0x1 NodeCnt=3 WEXITSTATUS 0
[2017-01-01T08:52:54.150] job_complete: JobID=1464 State=0x8003 NodeCnt=3 done
[2017-01-01T08:54:16.151] job_complete: JobID=1443 State=0x1 NodeCnt=1 WEXITSTATUS 0
[2017-01-01T08:54:16.151] job_complete: JobID=1443 State=0x8003 NodeCnt=1 done
[2017-01-01T08:55:58.152] job_complete: JobID=1295 State=0x1 NodeCnt=1 WEXITSTATUS 0
[2017-01-01T08:55:58.152] job_complete: JobID=1295 State=0x8003 NodeCnt=1 done
[2017-01-01T08:55:58.152] sched: Allocate JobID=1435 NodeList=m[1-4] #CPUs=48 Partition=normal
[2017-01-01T08:55:58.152] SIM: faking sending message type REQUEST_BATCH_JOB_LAUNCH to localhost

[2017-01-01T08:56:59.152] job_complete: JobID=1435 State=0x1 NodeCnt=4 WEXITSTATUS 0
[2017-01-01T08:56:59.152] job_complete: JobID=1435 State=0x8003 NodeCnt=4 done
[2017-01-01T08:56:59.153] sched: Allocate JobID=1341 NodeList=m1 #CPUs=6 Partition=normal
[2017-01-01T08:56:59.153] SIM: faking sending message type REQUEST_BATCH_JOB_LAUNCH to localhost

[2017-01-01T08:56:59.153] sched: Allocate JobID=1333 NodeList=g1 #CPUs=2 Partition=normal
[2017-01-01T08:56:59.153] SIM: faking sending message type REQUEST_BATCH_JOB_LAUNCH to localhost

[2017-01-01T08:56:59.153] sched: Allocate JobID=1344 NodeList=n1 #CPUs=6 Partition=normal
[2017-01-01T08:56:59.153] SIM: faking sending message type REQUEST_BATCH_JOB_LAUNCH to localhost

[2017-01-01T08:56:59.153] sched: Allocate JobID=1370 NodeList=n1 #CPUs=1 Partition=normal
[2017-01-01T08:56:59.153] SIM: faking sending message type REQUEST_BATCH_JOB_LAUNCH to localhost

[2017-01-01T08:56:59.153] sched: Allocate JobID=1311 NodeList=m1 #CPUs=6 Partition=normal
[2017-01-01T08:56:59.153] SIM: faking sending message type REQUEST_BATCH_JOB_LAUNCH to localhost

[2017-01-01T08:56:59.153] sched: Allocate JobID=1377 NodeList=m2 #CPUs=12 Partition=normal
[2017-01-01T08:56:59.154] SIM: faking sending message type REQUEST_BATCH_JOB_LAUNCH to localhost

[2017-01-01T08:56:59.154] sched: Allocate JobID=1338 NodeList=n2 #CPUs=12 Partition=normal
[2017-01-01T08:56:59.154] SIM: faking sending message type REQUEST_BATCH_JOB_LAUNCH to localhost

[2017-01-01T08:56:59.154] sched: Allocate JobID=1336 NodeList=n3 #CPUs=12 Partition=normal
[2017-01-01T08:56:59.154] SIM: faking sending message type REQUEST_BATCH_JOB_LAUNCH to localhost

[2017-01-01T08:57:00.154] job_complete: JobID=1344 State=0x1 NodeCnt=1 WEXITSTATUS 0
[2017-01-01T08:57:00.154] job_complete: JobID=1344 State=0x8003 NodeCnt=1 done
[2017-01-01T08:57:00.154] job_complete: JobID=1336 State=0x1 NodeCnt=1 WEXITSTATUS 0
[2017-01-01T08:57:00.154] job_complete: JobID=1336 State=0x8003 NodeCnt=1 done
[2017-01-01T09:00:14.159] job_complete: JobID=1338 State=0x1 NodeCnt=1 WEXITSTATUS 0
[2017-01-01T09:00:14.159] job_complete: JobID=1338 State=0x8003 NodeCnt=1 done
[2017-01-01T09:00:42.160] backfill: Started JobId=1387 in normal on m3
[2017-01-01T09:00:42.160] SIM: faking sending message type REQUEST_BATCH_JOB_LAUNCH to localhost

[2017-01-01T09:00:42.160] backfill: Started JobId=1306 in normal on m3
[2017-01-01T09:00:42.160] SIM: faking sending message type REQUEST_BATCH_JOB_LAUNCH to localhost

[2017-01-01T09:00:42.160] backfill: Started JobId=1334 in normal on n4
[2017-01-01T09:00:42.160] SIM: faking sending message type REQUEST_BATCH_JOB_LAUNCH to localhost

[2017-01-01T09:00:42.161] backfill: Started JobId=1441 in normal on b[1-3]
[2017-01-01T09:00:42.161] SIM: faking sending message type REQUEST_BATCH_JOB_LAUNCH to localhost

[2017-01-01T09:00:42.161] backfill: Started JobId=1364 in normal on m4
[2017-01-01T09:00:42.161] SIM: faking sending message type REQUEST_BATCH_JOB_LAUNCH to localhost

[2017-01-01T09:00:42.161] backfill: Started JobId=1411 in normal on b4
[2017-01-01T09:00:42.161] SIM: faking sending message type REQUEST_BATCH_JOB_LAUNCH to localhost

[2017-01-01T09:00:42.161] backfill: Started JobId=1372 in normal on b5
[2017-01-01T09:00:42.162] SIM: faking sending message type REQUEST_BATCH_JOB_LAUNCH to localhost

[2017-01-01T09:00:42.162] backfill: Started JobId=1361 in normal on n2
[2017-01-01T09:00:42.162] SIM: faking sending message type REQUEST_BATCH_JOB_LAUNCH to localhost

[2017-01-01T09:00:42.162] backfill: Started JobId=1421 in normal on m3
[2017-01-01T09:00:42.162] SIM: faking sending message type REQUEST_BATCH_JOB_LAUNCH to localhost

[2017-01-01T09:00:42.162] backfill: Started JobId=1451 in normal on b6
[2017-01-01T09:00:42.162] SIM: faking sending message type REQUEST_BATCH_JOB_LAUNCH to localhost

[2017-01-01T09:00:42.162] backfill: Started JobId=1439 in normal on b7
[2017-01-01T09:00:42.163] SIM: faking sending message type REQUEST_BATCH_JOB_LAUNCH to localhost

[2017-01-01T09:00:42.163] backfill: Started JobId=1384 in normal on b8
[2017-01-01T09:00:42.163] SIM: faking sending message type REQUEST_BATCH_JOB_LAUNCH to localhost

[2017-01-01T09:00:42.163] backfill: Started JobId=1463 in normal on n3
[2017-01-01T09:00:42.163] SIM: faking sending message type REQUEST_BATCH_JOB_LAUNCH to localhost

[2017-01-01T09:00:42.163] backfill: Started JobId=1409 in normal on m3
[2017-01-01T09:00:42.163] SIM: faking sending message type REQUEST_BATCH_JOB_LAUNCH to localhost

[2017-01-01T09:00:42.163] backfill: Started JobId=1417 in normal on b9
[2017-01-01T09:00:42.163] SIM: faking sending message type REQUEST_BATCH_JOB_LAUNCH to localhost

[2017-01-01T09:00:42.164] backfill: Started JobId=1395 in normal on b10
[2017-01-01T09:00:42.164] SIM: faking sending message type REQUEST_BATCH_JOB_LAUNCH to localhost

[2017-01-01T09:00:42.165] backfill: Started JobId=1453 in normal on m3
[2017-01-01T09:00:42.165] SIM: faking sending message type REQUEST_BATCH_JOB_LAUNCH to localhost

[2017-01-01T09:00:42.165] backfill: Started JobId=1365 in normal on m3
[2017-01-01T09:00:42.165] SIM: faking sending message type REQUEST_BATCH_JOB_LAUNCH to localhost

[2017-01-01T09:00:42.166] backfill: Started JobId=1390 in normal on b7
[2017-01-01T09:00:42.166] SIM: faking sending message type REQUEST_BATCH_JOB_LAUNCH to localhost

[2017-01-01T09:00:42.166] backfill: Started JobId=1388 in normal on b7
[2017-01-01T09:00:42.166] SIM: faking sending message type REQUEST_BATCH_JOB_LAUNCH to localhost

[2017-01-01T09:00:42.168] backfill: Started JobId=1494 in normal on n1
[2017-01-01T09:00:42.169] SIM: faking sending message type REQUEST_BATCH_JOB_LAUNCH to localhost

[2017-01-01T09:00:42.169] backfill: Started JobId=1489 in normal on n1
[2017-01-01T09:00:42.169] SIM: faking sending message type REQUEST_BATCH_JOB_LAUNCH to localhost

[2017-01-01T09:00:43.170] job_complete: JobID=1411 State=0x1 NodeCnt=1 WEXITSTATUS 0
[2017-01-01T09:00:43.170] job_complete: JobID=1411 State=0x8003 NodeCnt=1 done
[2017-01-01T09:00:43.170] job_complete: JobID=1463 State=0x1 NodeCnt=1 WEXITSTATUS 0
[2017-01-01T09:00:43.170] job_complete: JobID=1463 State=0x8003 NodeCnt=1 done
[2017-01-01T09:00:52.170] job_complete: JobID=1384 State=0x1 NodeCnt=1 WEXITSTATUS 0
[2017-01-01T09:00:52.170] job_complete: JobID=1384 State=0x8003 NodeCnt=1 done
[2017-01-01T09:00:55.170] job_complete: JobID=1361 State=0x1 NodeCnt=1 WEXITSTATUS 0
[2017-01-01T09:00:55.170] job_complete: JobID=1361 State=0x8003 NodeCnt=1 done
[2017-01-01T09:02:59.172] job_complete: JobID=1365 State=0x1 NodeCnt=1 WEXITSTATUS 0
[2017-01-01T09:02:59.172] job_complete: JobID=1365 State=0x8003 NodeCnt=1 done
[2017-01-01T09:03:15.172] job_complete: JobID=1390 State=0x1 NodeCnt=1 WEXITSTATUS 0
[2017-01-01T09:03:15.172] job_complete: JobID=1390 State=0x8003 NodeCnt=1 done
[2017-01-01T09:03:22.172] job_complete: JobID=1334 State=0x1 NodeCnt=1 WEXITSTATUS 0
[2017-01-01T09:03:22.172] job_complete: JobID=1334 State=0x8003 NodeCnt=1 done
[2017-01-01T09:03:25.173] job_complete: JobID=1417 State=0x1 NodeCnt=1 WEXITSTATUS 0
[2017-01-01T09:03:25.173] job_complete: JobID=1417 State=0x8003 NodeCnt=1 done
[2017-01-01T09:03:29.173] job_complete: JobID=1372 State=0x1 NodeCnt=1 WEXITSTATUS 0
[2017-01-01T09:03:29.173] job_complete: JobID=1372 State=0x8003 NodeCnt=1 done
[2017-01-01T09:05:27.174] job_complete: JobID=1489 State=0x1 NodeCnt=1 WEXITSTATUS 0
[2017-01-01T09:05:27.174] job_complete: JobID=1489 State=0x8003 NodeCnt=1 done
[2017-01-01T09:06:11.174] job_complete: JobID=1409 State=0x1 NodeCnt=1 WEXITSTATUS 0
[2017-01-01T09:06:11.174] job_complete: JobID=1409 State=0x8003 NodeCnt=1 done
[2017-01-01T09:06:59.175] job_complete: JobID=1494 State=0x1 NodeCnt=1 WEXITSTATUS 0
[2017-01-01T09:06:59.175] job_complete: JobID=1494 State=0x8003 NodeCnt=1 done
[2017-01-01T09:07:58.181] job_complete: JobID=1421 State=0x1 NodeCnt=1 WEXITSTATUS 0
[2017-01-01T09:07:58.181] job_complete: JobID=1421 State=0x8003 NodeCnt=1 done
[2017-01-01T09:08:07.181] job_complete: JobID=1439 State=0x1 NodeCnt=1 WEXITSTATUS 0
[2017-01-01T09:08:07.181] job_complete: JobID=1439 State=0x8003 NodeCnt=1 done
[2017-01-01T09:09:04.182] job_complete: JobID=1369 State=0x1 NodeCnt=1 WEXITSTATUS 0
[2017-01-01T09:09:04.182] job_complete: JobID=1369 State=0x8003 NodeCnt=1 done
[2017-01-01T09:09:04.182] sched: Allocate JobID=1426 NodeList=n[2-4] #CPUs=36 Partition=normal
[2017-01-01T09:09:04.182] SIM: faking sending message type REQUEST_BATCH_JOB_LAUNCH to localhost

[2017-01-01T09:09:14.182] job_complete: JobID=1306 State=0x1 NodeCnt=1 WEXITSTATUS 0
[2017-01-01T09:09:14.182] job_complete: JobID=1306 State=0x8003 NodeCnt=1 done
[2017-01-01T09:13:18.190] job_complete: JobID=1311 State=0x1 NodeCnt=1 WEXITSTATUS 0
[2017-01-01T09:13:18.190] job_complete: JobID=1311 State=0x8003 NodeCnt=1 done
[2017-01-01T09:14:14.191] job_complete: JobID=1333 State=0x1 NodeCnt=1 WEXITSTATUS 0
[2017-01-01T09:14:14.191] job_complete: JobID=1333 State=0x8003 NodeCnt=1 done
[2017-01-01T09:14:16.191] job_complete: JobID=1441 State=0x1 NodeCnt=3 WEXITSTATUS 0
[2017-01-01T09:14:16.191] job_complete: JobID=1441 State=0x8003 NodeCnt=3 done
[2017-01-01T09:15:12.192] job_complete: JobID=1377 State=0x1 NodeCnt=1 WEXITSTATUS 0
[2017-01-01T09:15:12.192] job_complete: JobID=1377 State=0x8003 NodeCnt=1 done
[2017-01-01T09:16:42.193] job_complete: JobID=1395 State=0x1 NodeCnt=1 WEXITSTATUS 0
[2017-01-01T09:16:42.193] job_complete: JobID=1395 State=0x8003 NodeCnt=1 done
[2017-01-01T09:18:59.199] job_complete: JobID=1370 State=0x1 NodeCnt=1 WEXITSTATUS 0
[2017-01-01T09:18:59.199] job_complete: JobID=1370 State=0x8003 NodeCnt=1 done
[2017-01-01T09:18:59.199] job_complete: JobID=1341 State=0x1 NodeCnt=1 WEXITSTATUS 0
[2017-01-01T09:18:59.199] job_complete: JobID=1341 State=0x8003 NodeCnt=1 done
[2017-01-01T09:20:42.200] job_complete: JobID=1364 State=0x1 NodeCnt=1 WEXITSTATUS 0
[2017-01-01T09:20:42.200] job_complete: JobID=1364 State=0x8003 NodeCnt=1 done
[2017-01-01T09:20:42.200] backfill: Started JobId=1431 in normal on m[1-2,4]
[2017-01-01T09:20:42.200] SIM: faking sending message type REQUEST_BATCH_JOB_LAUNCH to localhost

[2017-01-01T09:20:42.201] backfill: Started JobId=1407 in normal on g1
[2017-01-01T09:20:42.201] SIM: faking sending message type REQUEST_BATCH_JOB_LAUNCH to localhost

[2017-01-01T09:20:42.201] backfill: Started JobId=1466 in normal on b[1-3]
[2017-01-01T09:20:42.201] SIM: faking sending message type REQUEST_BATCH_JOB_LAUNCH to localhost

[2017-01-01T09:20:42.201] backfill: Started JobId=1471 in normal on b4
[2017-01-01T09:20:42.201] SIM: faking sending message type REQUEST_BATCH_JOB_LAUNCH to localhost

[2017-01-01T09:20:42.201] backfill: Started JobId=1434 in normal on b[5,8]
[2017-01-01T09:20:42.202] SIM: faking sending message type REQUEST_BATCH_JOB_LAUNCH to localhost

[2017-01-01T09:20:42.202] backfill: Started JobId=1394 in normal on b9
[2017-01-01T09:20:42.202] SIM: faking sending message type REQUEST_BATCH_JOB_LAUNCH to localhost

[2017-01-01T09:20:42.202] backfill: Started JobId=1379 in normal on b7
[2017-01-01T09:20:42.202] SIM: faking sending message type REQUEST_BATCH_JOB_LAUNCH to localhost

[2017-01-01T09:20:42.202] backfill: Started JobId=1381 in normal on b10
[2017-01-01T09:20:42.202] SIM: faking sending message type REQUEST_BATCH_JOB_LAUNCH to localhost

[2017-01-01T09:20:42.204] backfill: Started JobId=1396 in normal on b10
[2017-01-01T09:20:42.204] SIM: faking sending message type REQUEST_BATCH_JOB_LAUNCH to localhost

[2017-01-01T09:20:42.204] backfill: Started JobId=1424 in normal on n1
[2017-01-01T09:20:42.204] SIM: faking sending message type REQUEST_BATCH_JOB_LAUNCH to localhost

[2017-01-01T09:20:42.205] backfill: Started JobId=1423 in normal on m3
[2017-01-01T09:20:42.205] SIM: faking sending message type REQUEST_BATCH_JOB_LAUNCH to localhost

[2017-01-01T09:20:50.207] job_complete: JobID=1388 State=0x1 NodeCnt=1 WEXITSTATUS 0
[2017-01-01T09:20:50.207] job_complete: JobID=1388 State=0x8003 NodeCnt=1 done
[2017-01-01T09:21:31.207] job_complete: JobID=1394 State=0x1 NodeCnt=1 WEXITSTATUS 0
[2017-01-01T09:21:31.207] job_complete: JobID=1394 State=0x8003 NodeCnt=1 done
[2017-01-01T09:21:42.207] job_complete: JobID=1453 State=0x1 NodeCnt=1 WEXITSTATUS 0
[2017-01-01T09:21:42.207] job_complete: JobID=1453 State=0x8003 NodeCnt=1 done
[2017-01-01T09:23:49.209] job_complete: JobID=1387 State=0x1 NodeCnt=1 WEXITSTATUS 0
[2017-01-01T09:23:49.209] job_complete: JobID=1387 State=0x8003 NodeCnt=1 done
[2017-01-01T09:24:33.209] job_complete: JobID=1466 State=0x1 NodeCnt=3 WEXITSTATUS 0
[2017-01-01T09:24:33.209] job_complete: JobID=1466 State=0x8003 NodeCnt=3 done
[2017-01-01T09:24:58.210] job_complete: JobID=1426 State=0x1 NodeCnt=3 WEXITSTATUS 0
[2017-01-01T09:24:58.210] job_complete: JobID=1426 State=0x8003 NodeCnt=3 done
[2017-01-01T09:24:58.210] sched: Allocate JobID=1433 NodeList=n[2-4] #CPUs=36 Partition=normal
[2017-01-01T09:24:58.210] SIM: faking sending message type REQUEST_BATCH_JOB_LAUNCH to localhost

[2017-01-01T09:25:12.210] job_complete: JobID=1424 State=0x1 NodeCnt=1 WEXITSTATUS 0
[2017-01-01T09:25:12.210] job_complete: JobID=1424 State=0x8003 NodeCnt=1 done
[2017-01-01T09:25:12.211] sched: Allocate JobID=1442 NodeList=n1 #CPUs=12 Partition=normal
[2017-01-01T09:25:12.211] SIM: faking sending message type REQUEST_BATCH_JOB_LAUNCH to localhost

[2017-01-01T09:25:31.211] job_complete: JobID=1407 State=0x1 NodeCnt=1 WEXITSTATUS 0
[2017-01-01T09:25:31.211] job_complete: JobID=1407 State=0x8003 NodeCnt=1 done
[2017-01-01T09:25:31.211] sched: Allocate JobID=1367 NodeList=g1 #CPUs=12 Partition=normal
[2017-01-01T09:25:31.212] SIM: faking sending message type REQUEST_BATCH_JOB_LAUNCH to localhost

[2017-01-01T09:26:41.212] job_complete: JobID=1423 State=0x1 NodeCnt=1 WEXITSTATUS 0
[2017-01-01T09:26:41.212] job_complete: JobID=1423 State=0x8003 NodeCnt=1 done
[2017-01-01T09:27:53.217] job_complete: JobID=1442 State=0x1 NodeCnt=1 WEXITSTATUS 0
[2017-01-01T09:27:53.218] job_complete: JobID=1442 State=0x8003 NodeCnt=1 done
[2017-01-01T09:27:53.218] job_complete: JobID=1379 State=0x1 NodeCnt=1 WEXITSTATUS 0
[2017-01-01T09:27:53.218] job_complete: JobID=1379 State=0x8003 NodeCnt=1 done
[2017-01-01T09:28:31.218] job_complete: JobID=1433 State=0x1 NodeCnt=3 WEXITSTATUS 0
[2017-01-01T09:28:31.218] job_complete: JobID=1433 State=0x8003 NodeCnt=3 done
[2017-01-01T09:29:19.218] job_complete: JobID=1471 State=0x1 NodeCnt=1 WEXITSTATUS 0
[2017-01-01T09:29:19.218] job_complete: JobID=1471 State=0x8003 NodeCnt=1 done
[2017-01-01T09:30:25.219] job_complete: JobID=1451 State=0x1 NodeCnt=1 WEXITSTATUS 0
[2017-01-01T09:30:25.219] job_complete: JobID=1451 State=0x8003 NodeCnt=1 done
[2017-01-01T09:31:15.220] job_complete: JobID=1396 State=0x1 NodeCnt=1 WEXITSTATUS 0
[2017-01-01T09:31:15.220] job_complete: JobID=1396 State=0x8003 NodeCnt=1 done
[2017-01-01T09:31:46.220] job_complete: JobID=1367 State=0x1 NodeCnt=1 WEXITSTATUS 0
[2017-01-01T09:31:46.220] job_complete: JobID=1367 State=0x8003 NodeCnt=1 done
[2017-01-01T09:31:46.220] sched: Allocate JobID=1366 NodeList=g1 #CPUs=12 Partition=normal
[2017-01-01T09:31:46.220] SIM: faking sending message type REQUEST_BATCH_JOB_LAUNCH to localhost

[2017-01-01T09:32:57.226] job_complete: JobID=1381 State=0x1 NodeCnt=1 WEXITSTATUS 0
[2017-01-01T09:32:57.226] job_complete: JobID=1381 State=0x8003 NodeCnt=1 done
[2017-01-01T09:39:42.236] job_complete: JobID=1431 State=0x1 NodeCnt=3 WEXITSTATUS 0
[2017-01-01T09:39:42.236] job_complete: JobID=1431 State=0x8003 NodeCnt=3 done
[2017-01-01T09:40:42.237] backfill: Started JobId=1354 in normal on n1
[2017-01-01T09:40:42.237] SIM: faking sending message type REQUEST_BATCH_JOB_LAUNCH to localhost

[2017-01-01T09:40:42.237] backfill: Started JobId=1359 in normal on n1
[2017-01-01T09:40:42.237] SIM: faking sending message type REQUEST_BATCH_JOB_LAUNCH to localhost

[2017-01-01T09:40:42.237] backfill: Started JobId=1469 in normal on m[1-3]
[2017-01-01T09:40:42.237] SIM: faking sending message type REQUEST_BATCH_JOB_LAUNCH to localhost

[2017-01-01T09:40:42.237] backfill: Started JobId=1448 in normal on m4
[2017-01-01T09:40:42.238] SIM: faking sending message type REQUEST_BATCH_JOB_LAUNCH to localhost

[2017-01-01T09:40:42.238] backfill: Started JobId=1454 in normal on n2
[2017-01-01T09:40:42.238] SIM: faking sending message type REQUEST_BATCH_JOB_LAUNCH to localhost

[2017-01-01T09:40:42.238] backfill: Started JobId=1480 in normal on b[1-3]
[2017-01-01T09:40:42.238] SIM: faking sending message type REQUEST_BATCH_JOB_LAUNCH to localhost

[2017-01-01T09:40:42.238] backfill: Started JobId=1491 in normal on n3
[2017-01-01T09:40:42.238] SIM: faking sending message type REQUEST_BATCH_JOB_LAUNCH to localhost

[2017-01-01T09:40:42.238] backfill: Started JobId=1419 in normal on b4
[2017-01-01T09:40:42.239] SIM: faking sending message type REQUEST_BATCH_JOB_LAUNCH to localhost

[2017-01-01T09:40:42.239] backfill: Started JobId=1450 in normal on b[6-7]
[2017-01-01T09:40:42.239] SIM: faking sending message type REQUEST_BATCH_JOB_LAUNCH to localhost

[2017-01-01T09:40:42.239] backfill: Started JobId=1420 in normal on n4
[2017-01-01T09:40:42.239] SIM: faking sending message type REQUEST_BATCH_JOB_LAUNCH to localhost

[2017-01-01T09:40:42.239] backfill: Started JobId=1406 in normal on b9
[2017-01-01T09:40:42.239] SIM: faking sending message type REQUEST_BATCH_JOB_LAUNCH to localhost

[2017-01-01T09:40:42.239] backfill: Started JobId=1427 in normal on b10
[2017-01-01T09:40:42.239] SIM: faking sending message type REQUEST_BATCH_JOB_LAUNCH to localhost

[2017-01-01T09:40:43.242] job_complete: JobID=1450 State=0x1 NodeCnt=2 WEXITSTATUS 0
[2017-01-01T09:40:43.242] job_complete: JobID=1450 State=0x8003 NodeCnt=2 done
[2017-01-01T09:40:53.242] job_complete: JobID=1427 State=0x1 NodeCnt=1 WEXITSTATUS 0
[2017-01-01T09:40:53.242] job_complete: JobID=1427 State=0x8003 NodeCnt=1 done
[2017-01-01T09:41:03.242] job_complete: JobID=1469 State=0x1 NodeCnt=3 WEXITSTATUS 0
[2017-01-01T09:41:03.242] job_complete: JobID=1469 State=0x8003 NodeCnt=3 done
[2017-01-01T09:44:38.245] job_complete: JobID=1359 State=0x1 NodeCnt=1 WEXITSTATUS 0
[2017-01-01T09:44:38.245] job_complete: JobID=1359 State=0x8003 NodeCnt=1 done
[2017-01-01T09:45:21.245] job_complete: JobID=1491 State=0x1 NodeCnt=1 WEXITSTATUS 0
[2017-01-01T09:45:21.245] job_complete: JobID=1491 State=0x8003 NodeCnt=1 done
[2017-01-01T09:45:42.246] job_complete: JobID=1434 State=0x1 NodeCnt=2 WEXITSTATUS 0
[2017-01-01T09:45:42.246] job_complete: JobID=1434 State=0x8003 NodeCnt=2 done
[2017-01-01T09:46:00.246] job_complete: JobID=1366 State=0x1 NodeCnt=1 WEXITSTATUS 0
[2017-01-01T09:46:00.246] job_complete: JobID=1366 State=0x8003 NodeCnt=1 done
[2017-01-01T09:46:00.246] sched: Allocate JobID=1457 NodeList=g1 #CPUs=12 Partition=normal
[2017-01-01T09:46:00.246] SIM: faking sending message type REQUEST_BATCH_JOB_LAUNCH to localhost

[2017-01-01T09:46:15.246] job_complete: JobID=1406 State=0x1 NodeCnt=1 WEXITSTATUS 0
[2017-01-01T09:46:15.246] job_complete: JobID=1406 State=0x8003 NodeCnt=1 done
[2017-01-01T09:46:28.246] job_complete: JobID=1457 State=0x1 NodeCnt=1 WEXITSTATUS 0
[2017-01-01T09:46:28.246] job_complete: JobID=1457 State=0x8003 NodeCnt=1 done
[2017-01-01T09:46:28.246] sched: Allocate JobID=1368 NodeList=g1 #CPUs=12 Partition=normal
[2017-01-01T09:46:28.247] SIM: faking sending message type REQUEST_BATCH_JOB_LAUNCH to localhost

[2017-01-01T09:52:28.255] job_complete: JobID=1368 State=0x1 NodeCnt=1 WEXITSTATUS 0
[2017-01-01T09:52:28.255] job_complete: JobID=1368 State=0x8003 NodeCnt=1 done
[2017-01-01T09:52:28.255] sched: Allocate JobID=1345 NodeList=g1 #CPUs=1 Partition=normal
[2017-01-01T09:52:28.255] SIM: faking sending message type REQUEST_BATCH_JOB_LAUNCH to localhost

[2017-01-01T09:52:28.255] sched: Allocate JobID=1475 NodeList=m[1-3] #CPUs=36 Partition=normal
[2017-01-01T09:52:28.255] SIM: faking sending message type REQUEST_BATCH_JOB_LAUNCH to localhost

[2017-01-01T09:55:55.263] job_complete: JobID=1354 State=0x1 NodeCnt=1 WEXITSTATUS 0
[2017-01-01T09:55:55.263] job_complete: JobID=1354 State=0x8003 NodeCnt=1 done
[2017-01-01T09:57:28.264] job_complete: JobID=1345 State=0x1 NodeCnt=1 WEXITSTATUS 0
[2017-01-01T09:57:28.264] job_complete: JobID=1345 State=0x8003 NodeCnt=1 done
[2017-01-01T09:57:47.271] job_complete: JobID=1420 State=0x1 NodeCnt=1 WEXITSTATUS 0
[2017-01-01T09:57:47.271] job_complete: JobID=1420 State=0x8003 NodeCnt=1 done
[2017-01-01T09:59:58.272] job_complete: JobID=1475 State=0x1 NodeCnt=3 WEXITSTATUS 0
[2017-01-01T09:59:58.272] job_complete: JobID=1475 State=0x8003 NodeCnt=3 done
[2017-01-01T09:59:58.272] sched: Allocate JobID=1476 NodeList=m[1-3] #CPUs=36 Partition=normal
[2017-01-01T09:59:58.272] SIM: faking sending message type REQUEST_BATCH_JOB_LAUNCH to localhost

[2017-01-01T09:59:58.272] sched: Allocate JobID=1484 NodeList=n[1,3-4] #CPUs=36 Partition=normal
[2017-01-01T09:59:58.272] SIM: faking sending message type REQUEST_BATCH_JOB_LAUNCH to localhost

[2017-01-01T09:59:58.272] sched: Allocate JobID=1490 NodeList=b5 #CPUs=6 Partition=normal
[2017-01-01T09:59:58.272] SIM: faking sending message type REQUEST_BATCH_JOB_LAUNCH to localhost

[2017-01-01T09:59:58.272] sched: Allocate JobID=1386 NodeList=g1 #CPUs=1 Partition=normal
[2017-01-01T09:59:58.273] SIM: faking sending message type REQUEST_BATCH_JOB_LAUNCH to localhost

[2017-01-01T09:59:59.273] job_complete: JobID=1476 State=0x1 NodeCnt=3 WEXITSTATUS 0
[2017-01-01T09:59:59.273] job_complete: JobID=1476 State=0x8003 NodeCnt=3 done
[2017-01-01T09:59:59.273] job_complete: JobID=1484 State=0x1 NodeCnt=3 WEXITSTATUS 0
[2017-01-01T09:59:59.273] job_complete: JobID=1484 State=0x8003 NodeCnt=3 done
[2017-01-01T10:00:01.273] sched: Allocate JobID=1467 NodeList=n[1,3] #CPUs=24 Partition=normal
[2017-01-01T10:00:01.273] SIM: faking sending message type REQUEST_BATCH_JOB_LAUNCH to localhost

[2017-01-01T10:00:01.273] sched: Allocate JobID=1470 NodeList=m[1-2] #CPUs=24 Partition=normal
[2017-01-01T10:00:01.273] SIM: faking sending message type REQUEST_BATCH_JOB_LAUNCH to localhost

[2017-01-01T10:00:02.274] job_complete: JobID=1470 State=0x1 NodeCnt=2 WEXITSTATUS 0
[2017-01-01T10:00:02.274] job_complete: JobID=1470 State=0x8003 NodeCnt=2 done
[2017-01-01T10:00:42.274] backfill: Started JobId=1472 in normal on m[1-2]
[2017-01-01T10:00:42.274] SIM: faking sending message type REQUEST_BATCH_JOB_LAUNCH to localhost

[2017-01-01T10:00:42.274] backfill: Started JobId=1397 in normal on m3
[2017-01-01T10:00:42.274] SIM: faking sending message type REQUEST_BATCH_JOB_LAUNCH to localhost

[2017-01-01T10:00:42.274] backfill: Started JobId=1401 in normal on g1
[2017-01-01T10:00:42.275] SIM: faking sending message type REQUEST_BATCH_JOB_LAUNCH to localhost

[2017-01-01T10:00:42.275] backfill: Started JobId=1429 in normal on n4
[2017-01-01T10:00:42.275] SIM: faking sending message type REQUEST_BATCH_JOB_LAUNCH to localhost

[2017-01-01T10:00:42.275] backfill: Started JobId=1437 in normal on m3
[2017-01-01T10:00:42.275] SIM: faking sending message type REQUEST_BATCH_JOB_LAUNCH to localhost

[2017-01-01T10:00:42.275] backfill: Started JobId=1455 in normal on b6
[2017-01-01T10:00:42.275] SIM: faking sending message type REQUEST_BATCH_JOB_LAUNCH to localhost

[2017-01-01T10:00:42.275] backfill: Started JobId=1495 in normal on n4
[2017-01-01T10:00:42.276] SIM: faking sending message type REQUEST_BATCH_JOB_LAUNCH to localhost

[2017-01-01T10:00:42.276] backfill: Started JobId=1460 in normal on b7
[2017-01-01T10:00:42.276] SIM: faking sending message type REQUEST_BATCH_JOB_LAUNCH to localhost

[2017-01-01T10:00:42.276] backfill: Started JobId=1461 in normal on b5
[2017-01-01T10:00:42.276] SIM: faking sending message type REQUEST_BATCH_JOB_LAUNCH to localhost

[2017-01-01T10:00:42.276] backfill: Started JobId=1447 in normal on b8
[2017-01-01T10:00:42.277] SIM: faking sending message type REQUEST_BATCH_JOB_LAUNCH to localhost

[2017-01-01T10:00:42.277] backfill: Started JobId=1444 in normal on b9
[2017-01-01T10:00:42.277] SIM: faking sending message type REQUEST_BATCH_JOB_LAUNCH to localhost

[2017-01-01T10:00:42.277] backfill: Started JobId=1481 in normal on b10
[2017-01-01T10:00:42.277] SIM: faking sending message type REQUEST_BATCH_JOB_LAUNCH to localhost

[2017-01-01T10:01:38.278] job_complete: JobID=1480 State=0x1 NodeCnt=3 WEXITSTATUS 0
[2017-01-01T10:01:38.278] job_complete: JobID=1480 State=0x8003 NodeCnt=3 done
[2017-01-01T10:01:57.278] job_complete: JobID=1419 State=0x1 NodeCnt=1 WEXITSTATUS 0
[2017-01-01T10:01:57.278] job_complete: JobID=1419 State=0x8003 NodeCnt=1 done
[2017-01-01T10:02:23.279] job_complete: JobID=1448 State=0x1 NodeCnt=1 WEXITSTATUS 0
[2017-01-01T10:02:23.279] job_complete: JobID=1448 State=0x8003 NodeCnt=1 done
[2017-01-01T10:02:49.280] job_complete: JobID=1472 State=0x1 NodeCnt=2 WEXITSTATUS 0
[2017-01-01T10:02:49.280] job_complete: JobID=1472 State=0x8003 NodeCnt=2 done
[2017-01-01T10:02:58.280] job_complete: JobID=1401 State=0x1 NodeCnt=1 WEXITSTATUS 0
[2017-01-01T10:02:58.280] job_complete: JobID=1401 State=0x8003 NodeCnt=1 done
[2017-01-01T10:04:03.280] job_complete: JobID=1429 State=0x1 NodeCnt=1 WEXITSTATUS 0
[2017-01-01T10:04:03.280] job_complete: JobID=1429 State=0x8003 NodeCnt=1 done
[2017-01-01T10:04:23.280] job_complete: JobID=1460 State=0x1 NodeCnt=1 WEXITSTATUS 0
[2017-01-01T10:04:23.281] job_complete: JobID=1460 State=0x8003 NodeCnt=1 done
[2017-01-01T10:05:08.281] job_complete: JobID=1454 State=0x1 NodeCnt=1 WEXITSTATUS 0
[2017-01-01T10:05:08.281] job_complete: JobID=1454 State=0x8003 NodeCnt=1 done
[2017-01-01T10:05:17.281] job_complete: JobID=1455 State=0x1 NodeCnt=1 WEXITSTATUS 0
[2017-01-01T10:05:17.281] job_complete: JobID=1455 State=0x8003 NodeCnt=1 done
[2017-01-01T10:08:38.289] job_complete: JobID=1437 State=0x1 NodeCnt=1 WEXITSTATUS 0
[2017-01-01T10:08:38.289] job_complete: JobID=1437 State=0x8003 NodeCnt=1 done
[2017-01-01T10:09:50.289] job_complete: JobID=1447 State=0x1 NodeCnt=1 WEXITSTATUS 0
[2017-01-01T10:09:50.289] job_complete: JobID=1447 State=0x8003 NodeCnt=1 done
[2017-01-01T10:12:11.290] job_complete: JobID=1461 State=0x1 NodeCnt=1 WEXITSTATUS 0
[2017-01-01T10:12:11.290] job_complete: JobID=1461 State=0x8003 NodeCnt=1 done
[2017-01-01T10:13:54.299] job_complete: JobID=1444 State=0x1 NodeCnt=1 WEXITSTATUS 0
[2017-01-01T10:13:54.299] job_complete: JobID=1444 State=0x8003 NodeCnt=1 done
[2017-01-01T10:14:02.299] job_complete: JobID=1495 State=0x1 NodeCnt=1 WEXITSTATUS 0
[2017-01-01T10:14:02.299] job_complete: JobID=1495 State=0x8003 NodeCnt=1 done
[2017-01-01T10:14:10.299] job_complete: JobID=1397 State=0x1 NodeCnt=1 WEXITSTATUS 0
[2017-01-01T10:14:10.299] job_complete: JobID=1397 State=0x8003 NodeCnt=1 done
[2017-01-01T10:14:33.299] job_complete: JobID=1386 State=0x1 NodeCnt=1 WEXITSTATUS 0
[2017-01-01T10:14:33.299] job_complete: JobID=1386 State=0x8003 NodeCnt=1 done
[2017-01-01T10:14:33.299] sched: Allocate JobID=1402 NodeList=g1 #CPUs=2 Partition=normal
[2017-01-01T10:14:33.299] SIM: faking sending message type REQUEST_BATCH_JOB_LAUNCH to localhost

[2017-01-01T10:15:57.300] job_complete: JobID=1481 State=0x1 NodeCnt=1 WEXITSTATUS 0
[2017-01-01T10:15:57.300] job_complete: JobID=1481 State=0x8003 NodeCnt=1 done
[2017-01-01T10:20:42.308] backfill: Started JobId=1496 in normal on m[1-2]
[2017-01-01T10:20:42.308] SIM: faking sending message type REQUEST_BATCH_JOB_LAUNCH to localhost

[2017-01-01T10:20:42.308] backfill: Started JobId=1458 in normal on n2
[2017-01-01T10:20:42.308] SIM: faking sending message type REQUEST_BATCH_JOB_LAUNCH to localhost

[2017-01-01T10:20:42.309] backfill: Started JobId=1459 in normal on m3
[2017-01-01T10:20:42.309] SIM: faking sending message type REQUEST_BATCH_JOB_LAUNCH to localhost

[2017-01-01T10:20:42.309] backfill: Started JobId=1462 in normal on m4
[2017-01-01T10:20:42.309] SIM: faking sending message type REQUEST_BATCH_JOB_LAUNCH to localhost

[2017-01-01T10:20:42.309] backfill: Started JobId=1493 in normal on n4
[2017-01-01T10:20:42.309] SIM: faking sending message type REQUEST_BATCH_JOB_LAUNCH to localhost

[2017-01-01T10:20:42.309] backfill: Started JobId=1492 in normal on m4
[2017-01-01T10:20:42.309] SIM: faking sending message type REQUEST_BATCH_JOB_LAUNCH to localhost

[2017-01-01T10:21:26.310] job_complete: JobID=1490 State=0x1 NodeCnt=1 WEXITSTATUS 0
[2017-01-01T10:21:26.310] job_complete: JobID=1490 State=0x8003 NodeCnt=1 done
[2017-01-01T10:22:47.316] job_complete: JobID=1467 State=0x1 NodeCnt=2 WEXITSTATUS 0
[2017-01-01T10:22:47.316] job_complete: JobID=1467 State=0x8003 NodeCnt=2 done
[2017-01-01T10:25:19.317] job_complete: JobID=1492 State=0x1 NodeCnt=1 WEXITSTATUS 0
[2017-01-01T10:25:19.317] job_complete: JobID=1492 State=0x8003 NodeCnt=1 done
[2017-01-01T10:26:30.317] job_complete: JobID=1493 State=0x1 NodeCnt=1 WEXITSTATUS 0
[2017-01-01T10:26:30.317] job_complete: JobID=1493 State=0x8003 NodeCnt=1 done
[2017-01-01T10:27:18.318] job_complete: JobID=1402 State=0x1 NodeCnt=1 WEXITSTATUS 0
[2017-01-01T10:27:18.318] job_complete: JobID=1402 State=0x8003 NodeCnt=1 done
[2017-01-01T10:27:18.318] sched: Allocate JobID=1414 NodeList=g1 #CPUs=2 Partition=normal
[2017-01-01T10:27:18.318] SIM: faking sending message type REQUEST_BATCH_JOB_LAUNCH to localhost

[2017-01-01T10:27:42.318] job_complete: JobID=1458 State=0x1 NodeCnt=1 WEXITSTATUS 0
[2017-01-01T10:27:42.318] job_complete: JobID=1458 State=0x8003 NodeCnt=1 done
[2017-01-01T10:28:41.325] job_complete: JobID=1462 State=0x1 NodeCnt=1 WEXITSTATUS 0
[2017-01-01T10:28:41.325] job_complete: JobID=1462 State=0x8003 NodeCnt=1 done
[2017-01-01T10:32:20.327] job_complete: JobID=1496 State=0x1 NodeCnt=2 WEXITSTATUS 0
[2017-01-01T10:32:20.327] job_complete: JobID=1496 State=0x8003 NodeCnt=2 done
[2017-01-01T10:34:27.334] job_complete: JobID=1459 State=0x1 NodeCnt=1 WEXITSTATUS 0
[2017-01-01T10:34:27.334] job_complete: JobID=1459 State=0x8003 NodeCnt=1 done
[2017-01-01T10:40:42.344] backfill: Started JobId=1474 in normal on n1
[2017-01-01T10:40:42.344] SIM: faking sending message type REQUEST_BATCH_JOB_LAUNCH to localhost

[2017-01-01T10:40:42.344] backfill: Started JobId=1485 in normal on n1
[2017-01-01T10:40:42.344] SIM: faking sending message type REQUEST_BATCH_JOB_LAUNCH to localhost

[2017-01-01T10:40:42.344] backfill: Started JobId=1498 in normal on n2
[2017-01-01T10:40:42.344] SIM: faking sending message type REQUEST_BATCH_JOB_LAUNCH to localhost

[2017-01-01T10:40:43.344] job_complete: JobID=1474 State=0x1 NodeCnt=1 WEXITSTATUS 0
[2017-01-01T10:40:43.344] job_complete: JobID=1474 State=0x8003 NodeCnt=1 done
[2017-01-01T10:44:43.352] job_complete: JobID=1498 State=0x1 NodeCnt=1 WEXITSTATUS 0
[2017-01-01T10:44:43.352] job_complete: JobID=1498 State=0x8003 NodeCnt=1 done
[2017-01-01T10:47:18.353] job_complete: JobID=1414 State=0x1 NodeCnt=1 WEXITSTATUS 0
[2017-01-01T10:47:18.353] job_complete: JobID=1414 State=0x8003 NodeCnt=1 done
[2017-01-01T10:47:18.353] sched: Allocate JobID=1478 NodeList=g1 #CPUs=1 Partition=normal
[2017-01-01T10:47:18.353] SIM: faking sending message type REQUEST_BATCH_JOB_LAUNCH to localhost

[2017-01-01T10:59:14.379] job_complete: JobID=1478 State=0x1 NodeCnt=1 WEXITSTATUS 0
[2017-01-01T10:59:14.379] job_complete: JobID=1478 State=0x8003 NodeCnt=1 done
[2017-01-01T10:59:14.379] sched: Allocate JobID=1446 NodeList=g1 #CPUs=12 Partition=normal
[2017-01-01T10:59:14.379] SIM: faking sending message type REQUEST_BATCH_JOB_LAUNCH to localhost

[2017-01-01T10:59:15.379] job_complete: JobID=1446 State=0x1 NodeCnt=1 WEXITSTATUS 0
[2017-01-01T10:59:15.379] job_complete: JobID=1446 State=0x8003 NodeCnt=1 done
[2017-01-01T10:59:17.379] sched: Allocate JobID=1425 NodeList=g1 #CPUs=2 Partition=normal
[2017-01-01T10:59:17.379] SIM: faking sending message type REQUEST_BATCH_JOB_LAUNCH to localhost

[2017-01-01T10:59:18.379] job_complete: JobID=1425 State=0x1 NodeCnt=1 WEXITSTATUS 0
[2017-01-01T10:59:18.379] job_complete: JobID=1425 State=0x8003 NodeCnt=1 done
[2017-01-01T10:59:20.380] sched: Allocate JobID=1465 NodeList=g1 #CPUs=1 Partition=normal
[2017-01-01T10:59:20.380] SIM: faking sending message type REQUEST_BATCH_JOB_LAUNCH to localhost

[2017-01-01T10:59:20.380] sched: Allocate JobID=1487 NodeList=g1 #CPUs=1 Partition=normal
[2017-01-01T10:59:20.380] SIM: faking sending message type REQUEST_BATCH_JOB_LAUNCH to localhost

[2017-01-01T10:59:33.380] job_complete: JobID=1485 State=0x1 NodeCnt=1 WEXITSTATUS 0
[2017-01-01T10:59:33.380] job_complete: JobID=1485 State=0x8003 NodeCnt=1 done
[2017-01-01T11:01:18.381] job_complete: JobID=1465 State=0x1 NodeCnt=1 WEXITSTATUS 0
[2017-01-01T11:01:18.381] job_complete: JobID=1465 State=0x8003 NodeCnt=1 done
[2017-01-01T11:04:45.388] job_complete: JobID=1487 State=0x1 NodeCnt=1 WEXITSTATUS 0
[2017-01-01T11:04:45.388] job_complete: JobID=1487 State=0x8003 NodeCnt=1 done
[2017-01-01T11:05:46.388] No more jobs to run, terminating simulation
